Workbook

Sheet HZ-ASD Tracker
A1: POOL CABIN ✈ HZ-ASD ✈ C2+6Y CHECK WORK PACKAGE TRACKER | E1: ="DAY "&(TODAY()-DATE(2026,7,18)+1)&"/38"&IF(TODAY()>DATE(2026,8,24)," ⛔ OVR +"&(TODAY()-DATE(2026,8,24))&"d"," · "&(DATE(2026,8,24)-TODAY())&"d LEFT")&" · BIS 3-SEP" -> DAY 40/38 ⛔ OVR +2d · BIS 3-SEP | H1: ="✅ "&COUNTIFS(A4:A994,"<>",E4:E994,"Closed")&" / "&COUNTIF(A4:A994,"<>")&" Closed ("&TEXT(IFERROR(COUNTIFS(A4:A994,"<>",E4:E994,"Closed")/COUNTIF(A4:A994,"<>"),0),"0%")&")" -> ✅ 311 / 465 Closed (67%)
A2: =IF(COUNT($L$4:$L$994)=0,"No dated updates yet — type todays date (e.g. 19/7) in column L when you edit a row","LAST UPDATE: "&TEXT(MAX($L$4:$L$994),"DD-MMM")&" · "&COUNTIF($L$4:$L$994,MAX($L$4:$L$994))&" row(s) updated — filter column L for details") -> LAST UPDATE: 25-Aug · 63 row(s) updated — filter column L for details | H2: ="🔴 AOG WO: "&COUNTIFS(A4:A994,"<>",F4:F994,"AOG",E4:E994,"<>Closed")&" ⚠️ Critical WO: "&COUNTIFS(A4:A994,"<>",F4:F994,"Critical",E4:E994,"<>Closed")&" 🔓 Access WO: "&COUNTIFS(A4:A994,"<>",F4:F994,"ACCESS",E4:E994,"<>Closed") -> 🔴 AOG WO: 1 ⚠️ Critical WO: 13 🔓 Access WO: 28
A3: WO / Event Number | B3: Task Description | C3: Seq. No. | D3: Category | E3: Status | F3: Priority | G3: Specialty | H3: PARTS REQ. | I3: Remarks | J3: Time EVAL? | K3: AREA | L3: Updated | M3: Closed Date | N3: Est MH | O3: ATA | P3: Booked MH | Q3: Actual Dur (h)
A4: 200125-06-1 | B4: 200125-06-1 (2) / LATERAL AVIONICS COMPT INSP | C4: 11 | D4: ACFT GENERAL T/C | E4: Closed | F4: Critical | G4: JOINT | K4: FWD | L4: 46259 | M4: 46257 | N4: 10.15 | P4: 26.5 | Q4: 49.9
A5: 200145-01-1 | B5: 200145-01-1 (2) / ZONE UNDER CABIN FLOOR CLEANING | C5: 18 | D5: ACFT GENERAL T/C | E5: Open | F5: Critical | G5: JOINT | I5: CABIN ACCESS | K5: AFT | N5: 0 | P5: 14 | Q5: 573.9
A6: 200231-03-1 | B6: 200231-03-1 (2) / FORWARD PASSENGER COMPARTMENT INSP | C6: 24 | D6: GENERAL CABIN | E6: Closed | F6: Normal | G6: JOINT | I6: C/W | J6: N/A | K6: FWD | L6: 46225 | M6: 46225 | N6: 7.15 | O6: 24-92 | P6: 13.5 | Q6: 22.17
A7: 200241-04-1 | B7: 200241-04-1 (2) / CENTER PASSENGER COMPARTMENT INSP | C7: 25 | D7: GENERAL CABIN | E7: Closed | F7: Normal | G7: JOINT | I7: CAB + INSP / REMINE CLOSE UP | J7: N/A | K7: AFT | L7: 46259 | M7: 46257 | N7: 7.15 | O7: 24-92 | P7: 17 | Q7: 795.2
A8: 200251-03-1 | B8: 200251-03-1 (2) / AFT PASSENGER COMPARTMENT INSPECTION | C8: 26 | D8: GENERAL CABIN | E8: Closed | F8: Normal | G8: JOINT | I8: CAB + INSP / REMINE CLOSE UP | J8: N/A | K8: AFT | L8: 46259 | M8: 46258 | N8: 7.15 | O8: 24-92 | P8: 25.5 | Q8: 818.7
A9: 25-11-00-18-0-SVA-001 | B9: 25-11-00-18-0-SVA-001 (04) / FOURTH OCCUPANT SEAT COVERS REPLCMNT | C9: 32 | D9: FLIGHT DECK | E9: Closed | F9: Normal | G9: CAB | H9: Requested | I9: P/S 4509031 CLOSED | J9: N/A | K9: FWD | L9: 46259 | M9: 46257 | N9: 2 | O9: 25-11 | P9: 6.5 | Q9: 6.5
A10: 25-11-00-18-0-SVA-002 | B10: 25-11-00-18-0-SVA-002 (04) / THIRD OCCUPANT SEAT COVERS R/R | C10: 33 | D10: FLIGHT DECK | E10: Closed | F10: Normal | G10: CAB | H10: Requested | I10: P/S 4509039 CLOSED | J10: N/A | K10: FWD | L10: 46252 | M10: 46246 | N10: 2 | O10: 25-11 | P10: 2 | Q10: 2
A11: 25-22-00-03-0-SVA-002 | B11: 25-22-00-03-0-SVA-002 (02) / CABIN ATTENDANT SEAT COVERS R&R | C11: 34 | D11: F/A SEAT | E11: Closed | F11: Normal | G11: CAB | H11: Requested | I11: P/S 4509037 (SOME PARTS S/D) | J11: N/A | K11: JOINT | L11: 46259 | M11: 46258 | N11: 4 | O11: 25-22 | P11: 22 | Q11: 25.6
A12: 253000-01-1 | B12: 253000-01-1 (3) / GALLEY ATTACHMENT POINTS INSPECTION | C12: 35 | D12: GALLEY | E12: Open | F12: Normal | G12: JOINT | I12: CAB + INSP / REMINE CLOSE UP | J12: N/A | K12: JOINT | N12: 0.4 | O12: 25-30 | P12: 44 | Q12: 917.4
A13: 254000-02-2 | B13: 254000-02-2 (2) / LAVATORIE’S ATTACHMENT POINTS INSP | C13: 36 | D13: LAVATORY | E13: Closed | F13: Normal | G13: JOINT | I13: CAB + INSP / REMINE CLOSE UP | J13: N/A | K13: JOINT | L13: 46259 | M13: 46257 | N13: 0.65 | O13: 25-40 | P13: 15 | Q13: 26.7
A14: 256141-01-1 | B14: 256141-01-1 (3) / CAPT AND F/O EMERGENCY DEVICE INSP | C14: 37 | D14: FLIGHT DECK | E14: Closed | F14: Normal | G14: JOINT | I14: C/W | J14: N/A | K14: FWD | L14: 46223 | M14: 46223 | N14: 0.43 | O14: 25-61 | P14: 12 | Q14: 2.78
A15: 262541-01-1 | B15: 262541-01-1 (3) / LAVATORIES FIRE EXTINGUISHERS INSP | C15: 38 | D15: LAVATORY | E15: Closed | F15: Normal | G15: INSP | I15: C/W | J15: N/A | K15: JOINT | L15: 46223 | M15: 46223 | N15: 0.22 | O15: 26-25 | P15: 0.75 | Q15: 0.75
A16: 323300-01-1 | B16: 323300-01-1 (2) / LG FREE FALL EXTN MECH&CABLE INSP | C16: 44 | D16: ACFT GENERAL T/C | E16: Open | F16: Normal | G16: INSP | H16: Requested | I16: CABIN + COCKPIT ACCESS | J16: N/A | K16: FWD | N16: 0.33 | O16: 32-33 | Q16: 390.4
A17: 323300-04-1 | B17: 323300-04-1 (3) / LG FREE FALL MECH CABLE TENTION CHK | C17: 45 | D17: ACFT GENERAL T/C | E17: Open | F17: Normal | G17: INSP | I17: CABIN + COCKPIT ACCESS | J17: N/A | K17: FWD | N17: 0.15 | O17: 32-33 | P17: 2 | Q17: 843.8
A18: 531102-01-1 | B18: 531102-01-1 (5) / LH/RH FORWARD PASSENGER DOORS INSP | C18: 51 | D18: PAX DOORS | E18: Closed | F18: Normal | G18: INSP | I18: C/W | J18: N/A | K18: FWD | L18: 46232 | M18: 46232 | N18: 0.65 | O18: 53-11 | P18: 2.52 | Q18: 74.5
A19: 531164-01-1 | B19: 531164-01-1 (02) / FUSELAGE FR 15-21 INSPECTION | C19: 52 | D19: ACFT GENERAL T/C | E19: Open | F19: Normal | G19: INSP | H19: Requested | I19: A&P / REMINE CLOSE UP | J19: N/A | K19: FWD | N19: 1.5 | O19: 53-11 | P19: 3.2 | Q19: 769.9
A20: 531166-01-2 | B20: 531166-01-2 (2) / FUSELAGE FR 16-20 INSPECTION | C20: 53 | D20: ACFT GENERAL T/C | E20: Open | F20: Critical | G20: INSP | H20: Requested | I20: FWD DOORS GIRT FITTINGS / TO DO | J20: N/A | K20: FWD | N20: 0.65 | O20: 53-11 | P20: 23.5 | Q20: 581.5
A21: 531181-01-1 | B21: 531181-01-1 (3) / FUSELAGE INTERNL STRUCT FR15-21 INSP | C21: 55 | D21: ACFT GENERAL T/C | E21: Open | F21: Critical | G21: INSP | H21: Requested | I21: FWD GALLEY + LAV A + ALL B/C SEATS + COCKPIT DOOR + FLOOR PANELS REMOVAL | J21: N/A | K21: FWD | L21: 46222 | N21: 1.75 | O21: 53-11 | P21: 22 | Q21: 1054.3
A22: 531189-01-2 | B22: 531189-01-2 (2) / CABIN FLOOR STRUCT FR12 & FR21 INSP | C22: 56 | D22: ACFT GENERAL T/C | E22: Open | F22: Critical | G22: CAB | H22: Requested | I22: FWD GALLEY + LAV A + ALL B/C SEATS + COCKPIT DOOR + FLOOR PANELS REMOVAL | J22: N/A | K22: FWD | L22: 46222 | N22: 3.67 | O22: 53-11 | P22: 127.5 | Q22: 724.7
A23: 531194-01-2 | B23: 531194-01-2 (2) / FLOOR STRUCTURE FR21 TO FR24 INSP | C23: 57 | D23: ACFT GENERAL T/C | E23: Open | F23: Critical | G23: INSP | H23: Requested | I23: G2 GALLEY + ALL SEATS REMOVAL | J23: N/A | K23: FWD | L23: 46222 | N23: 1 | O23: 53-11 | P23: 49.5 | Q23: 818.9
A24: 534132-02-1 | B24: 534132-02-1 (2) / DETAILED INSP OF AFT PASS/CREW DOOR CUTOUT, UPPER CORNERS | C24: 60 | D24: PAX DOORS | E24: Closed | F24: Normal | G24: JOINT | H24: Requested | I24: C/W | J24: N/A | K24: AFT | L24: 46233 | M24: 46233 | N24: 0.75 | O24: 53-41 | P24: 2.25 | Q24: 72.3
A25: 534135-01-4 | B25: 534135-01-4 (03) / AFT PASSENGER/CREW DOOR CUTOUT INSP | C25: 61 | D25: PAX DOORS | E25: Closed | F25: Normal | G25: JOINT | H25: Requested | I25: CAB + INSP / REMINE CLOSE UP | J25: N/A | K25: AFT | L25: 46256 | M25: 46254 | N25: 5.72 | O25: 53-41 | P25: 40.5 | Q25: 508.5
A26: 534147-01-1 | B26: 534147-01-1 (2) / CABIN FLOOR STRUC AROUND GALLEY&LAV | C26: 62 | D26: ACFT GENERAL T/C | E26: Open | F26: Critical | G26: CAB | H26: Requested | I26: REMOVE ALL GALLEYS AND LAVS + SOME ROWS OF G/C SEATS / REMINE CLOSE UP | J26: N/A | K26: JOINT | N26: 37 | O26: 53-41 | P26: 128 | Q26: 844.9
A27: 534195-01-2 | B27: 534195-01-2 (01) / CABIN FLOOR STRUCT BELOW AFT ENTERAN | C27: 66 | D27: ACFT GENERAL T/C | E27: Open | F27: Critical | G27: CAB | H27: Requested | I27: AFT AREA / REMINE CLOSE UP | J27: N/A | K27: AFT | N27: 0 | O27: 53-41 | P27: 22 | Q27: 716.5
A28: 562101-01-1 | B28: 562101-01-1 (3) / CABIN AND DOOR WINDOW PANES INSP | C28: 79 | D28: GENERAL CABIN | E28: Closed | F28: Normal | G28: JOINT | H28: Requested | I28: CAB + INSP / INTERIOR C/W REMINE EXTERIR | J28: N/A | K28: JOINT | L28: 46259 | M28: 46257 | N28: 13.2 | O28: 56-21 | P28: 212 | Q28: 678
A29: 571157-01-1 | B29: 571157-01-1 (3) / CENTER WING BOX UPPER SKIN INSP | C29: 81 | E29: Closed | F29: ACCESS | H29: Requested | L29: 46259 | M29: 46257 | N29: 7.7 | P29: 8.73 | Q29: 5.35
A30: ZL-145-01-1 | B30: ZL-145-01-1 (2) / ZONE UNDER CABIN FLOOR INSPECTION | C30: 109 | D30: ACFT GENERAL T/C | E30: Closed | F30: Critical | G30: CAB | H30: Requested | I30: CAB + INSP / FR 36 TO FR 46 / REMINE CLOSE UP | J30: N/A | K30: JOINT | L30: 46252 | M30: 46251 | N30: 11.5 | O30: 05-21 | P30: 389.8 | Q30: 517.5
A31: ZL-171-02-1 | B31: ZL-171-02-1 (2) / AFT CABIN UNDERFLOOR COMPART INSP | C31: 115 | D31: ACFT GENERAL T/C | E31: Closed | F31: Normal | G31: INSP | I31: C/W | J31: N/A | K31: AFT | L31: 46226 | M31: 46226 | N31: 77 | O31: 05-21 | P31: 2.5 | Q31: 47.7
A32: ZL-211-01-1 | B32: ZL-211-01-1 (03) / COCKPIT ZONAL INSPECTION | C32: 122 | D32: FLIGHT DECK | E32: Closed | F32: Normal | G32: INSP | I32: C/W | J32: N/A | K32: FWD | L32: 46226 | M32: 46226 | N32: 0.43 | O32: 05-22 | P32: 21 | Q32: 30.4
A33: ZL-833-02-1 | B33: ZL-833-02-1 (04) / FWD AND AFT EMERGENCY EXITS INSP | C33: 157 | D33: PAX DOORS | E33: Closed | F33: Normal | G33: AP | I33: AP | J33: N/A | K33: JOINT | L33: 46252 | M33: 46239 | N33: 1.97 | O33: 05-28 | P33: 6.83 | Q33: 323.4
A34: 05-SVA-01 | B34: 05-SVA-01 (00) / EMERGENCY EQUIPMENTS EXPIRY CHECK | C34: 159 | D34: GENERAL CABIN | E34: Closed | F34: Normal | G34: CAB | I34: ALL INFORMATIONS FILLED TO BE CLOSE BEFORE ACFT RELASE | J34: N/A | K34: JOINT | L34: 46259 | M34: 46257 | N34: 2.17 | O34: 05 | P34: 8 | Q34: 4
A35: 11-11-00-01-0-SVA | B35: 11-11-00-01-0-SVA (02) / INTERIOR PLACARDS CHECK | C35: 160 | D35: GENERAL CABIN | E35: Open | F35: Normal | G35: PAINT | I35: PAINT | J35: N/A | K35: JOINT | N35: 1 | O35: 11-11 | Q35: 0
A36: 212300-02-1 | B36: 212300-02-1 (4) / LAVATORY AIR EXTRACTION FLTR R/R | C36: 162 | D36: LAVATORY | E36: Closed | F36: Normal | G36: CAB | H36: Requested | I36: C/W | J36: N/A | K36: JOINT | L36: 46223 | M36: 46223 | N36: 0.43 | O36: 21-23 | P36: 2 | Q36: 1
A37: 25-10-00-00-SVA | B37: 25-10-00-00-SVA (00) / COCKPIT CHECK | C37: 168 | D37: FLIGHT DECK | E37: Closed | F37: Normal | G37: CAB | I37: CAB ONLY / CHECK C/W | J37: N/A | K37: FWD | L37: 46259 | M37: 46257 | N37: 6.83 | O37: 25-10 | P37: 53 | Q37: 803.5
A38: 25-20-00-00-SVA | B38: 25-20-00-00-SVA (01) / GENERAL CABIN DEEP INSP | C38: 169 | D38: GENERAL CABIN | E38: Closed | F38: Normal | G38: JOINT | H38: Requested | I38: CAB + INSP / CHECK C/W | J38: N/A | K38: JOINT | L38: 46260 | N38: 10.83 | O38: 25-10 | P38: 51 | Q38: 841.6
A39: 25-21-00-00-SVA | B39: 25-21-00-00-SVA (01) / B/C SEAT DEEP INSP | C39: 170 | D39: PAX SEAT | E39: Open | F39: Normal | G39: SEAT | I39: SEAT SHOP | J39: N/A | K39: JOINT | N39: 2.33 | O39: 25-10 | P39: 7.5 | Q39: 866
A40: 25-21-01-00-SVA | B40: 25-21-01-00-SVA (01) / G/C SEAT DEEP INSP | C40: 171 | D40: PAX SEAT | E40: Open | F40: Normal | G40: SEAT | I40: STEP 8 (CAB POOL SPLTY) / TO DO AFTER SEAT INATALLAITON | J40: N/A | K40: JOINT | N40: 1.5 | O40: 25-10 | P40: 6 | Q40: 866.1
...

Sheet DASHBOARD
A1: 📊 HZ-ASD C2+6Y — WORK PACKAGE DASHBOARD | F1: ="DAY "&MAX(MIN(TODAY()-DASHBOARD!$M$1+1,DASHBOARD!$M$2-DASHBOARD!$M$1+1),0)&"/"&(DASHBOARD!$M$2-DASHBOARD!$M$1+1) -> DAY 38/38 | L1: START → | M1: 46221
A2: =IF(AND(DASHBOARD!$M$1="",DASHBOARD!$M$2=""),"⚙️ Set CHECK START (M1) and CHECK END (M2) dates → schedule alert activates automatically",IF(OR(NOT(ISNUMBER(DASHBOARD!$M$1)),NOT(ISNUMBER(DASHBOARD!$M$2))),"⚠️ Date not recognized — clear M1/M2 and re-type as 2026-07-01 (year-month-day)",IF(DASHBOARD!$M$2<=DASHBOARD!$M$1,"⚠️ CHECK END must be after CHECK START — please review M1/M2",IF(AND(TODAY()>DASHBOARD!$M$2,(COUNTIFS('HZ-ASD Tracker'!$A$5:$A$994,"<>",'HZ-ASD Tracker'!$E$5:$E$994,"Closed")/COUNTIF('HZ-ASD Tracker'!$A$5:$A$994,"<>"))<1),"❌ CHECK PERIOD ENDED — Completion "&TEXT((COUNTIFS('HZ-ASD Tracker'!$A$5:$A$994,"<>",'HZ-ASD Tracker'!$E$5:$E$994,"Closed")/COUNTIF('HZ-ASD Tracker'!$A$5:$A$994,"<>")),"0%")&" · Overdue by "&(TODAY()-DASHBOARD!$M$2)&" days",IF((COUNTIFS('HZ-ASD Tracker'!$A$5:$A$994,"<>",'HZ-ASD Tracker'!$E$5:$E$994,"Closed")/COUNTIF('HZ-ASD Tracker'!$A$5:$A$994,"<>"))>=((TODAY()-DASHBOARD!$M$1)/(DASHBOARD!$M$2-DASHBOARD!$M$1))-0.05,"✅ ON TRACK — "&"Completed "&TEXT((COUNTIFS('HZ-ASD Tracker'!$A$5:$A$994,"<>",'HZ-ASD Tracker'!$E$5:$E$994,"Closed")/COUNTIF('HZ-ASD Tracker'!$A$5:$A$994,"<>")),"0%")&" vs Time "&TEXT(MAX(MIN(((TODAY()-DASHBOARD!$M$1)/(DASHBOARD!$M$2-DASHBOARD!$M$1)),1),0),"0%")&" · Days Left: "&MAX(DASHBOARD!$M$2-TODAY(),0)&" · Pace needed: "&TEXT((COUNTIF('HZ-ASD Tracker'!$A$5:$A$994,"<>")-COUNTIFS('HZ-ASD Tracker'!$A$5:$A$994,"<>",'HZ-ASD Tracker'!$E$5:$E$994,"Closed"))/MAX(DASHBOARD!$M$2-TODAY(),1),"0.0")&"/day vs avg "&TEXT(COUNTIFS('HZ-ASD Tracker'!$A$5:$A$994,"<>",'HZ-ASD Tracker'!$E$5:$E$994,"Closed")/MAX(TODAY()-DASHBOARD!$M$1,1),"0.0")&"/day",IF((COUNTIFS('HZ-ASD Tracker'!$A$5:$A$994,"<>",'HZ-ASD Tracker'!$E$5:$E$994,"Closed")/COUNTIF('HZ-ASD Tracker'!$A$5:$A$994,"<>"))>=((TODAY()-DASHBOARD!$M$1)/(DASHBOARD!$M$2-DASHBOARD!$M$1))-0.15,"⚠️ WARNING — "&"Completed "&TEXT((COUNTIFS('HZ-ASD Tracker'!$A$5:$A$994,"<>",'HZ-ASD Tracker'!$E$5:$E$994,"Closed")/COUNTIF('HZ-ASD Tracker'!$A$5:$A$994,"<>")),"0%")&" vs Time "&TEXT(MAX(MIN(((TODAY()-DASHBOARD!$M$1)/(DASHBOARD!$M$2-DASHBOARD!$M$1)),1),0),"0%")&" · Days Left: "&MAX(DASHBOARD!$M$2-TODAY(),0)&" · Pace needed: "&TEXT((COUNTIF('HZ-ASD Tracker'!$A$5:$A$994,"<>")-COUNTIFS('HZ-ASD Tracker'!$A$5:$A$994,"<>",'HZ-ASD Tracker'!$E$5:$E$994,"Closed"))/MAX(DASHBOARD!$M$2-TODAY(),1),"0.0")&"/day vs avg "&TEXT(COUNTIFS('HZ-ASD Tracker'!$A$5:$A$994,"<>",'HZ-ASD Tracker'!$E$5:$E$994,"Closed")/MAX(TODAY()-DASHBOARD!$M$1,1),"0.0")&"/day","🔴 CRITICAL — "&"Completed "&TEXT((COUNTIFS('HZ-ASD Tracker'!$A$5:$A$994,"<>",'HZ-ASD Tracker'!$E$5:$E$994,"Closed")/COUNTIF('HZ-ASD Tracker'!$A$5:$A$994,"<>")),"0%")&" vs Time "&TEXT(MAX(MIN(((TODAY()-DASHBOARD!$M$1)/(DASHBOARD!$M$2-DASHBOARD!$M$1)),1),0),"0%")&" · Days Left: "&MAX(DASHBOARD!$M$2-TODAY(),0)&" · Pace needed: "&TEXT((COUNTIF('HZ-ASD Tracker'!$A$5:$A$994,"<>")-COUNTIFS('HZ-ASD Tracker'!$A$5:$A$994,"<>",'HZ-ASD Tracker'!$E$5:$E$994,"Closed"))/MAX(DASHBOARD!$M$2-TODAY(),1),"0.0")&"/day vs avg "&TEXT(COUNTIFS('HZ-ASD Tracker'!$A$5:$A$994,"<>",'HZ-ASD Tracker'!$E$5:$E$994,"Closed")/MAX(TODAY()-DASHBOARD!$M$1,1),"0.0")&"/day")))))) -> ❌ CHECK PERIOD ENDED — Completion 67% · Overdue by 2 days | L2: END → | M2: 46258
A3: ⛔ OVERRUN — B.I.S REVISED → 03 SEP 2026 (EXTENSION +10 DAYS)
A4: TOTAL WOs | B4: CLOSED | C4: OPEN | D4: HPC ⏳ | E4: 🔴 AOG WO | F4: ⚠️ CRITICAL WO | G4: DONE
A5: =COUNTIF('HZ-ASD Tracker'!$A$5:$A$994,"<>") -> 464 | B5: =COUNTIFS('HZ-ASD Tracker'!$A$5:$A$994,"<>",'HZ-ASD Tracker'!$E$5:$E$994,"Closed") -> 310 | C5: =COUNTIFS('HZ-ASD Tracker'!$A$5:$A$994,"<>",'HZ-ASD Tracker'!$E$5:$E$994,"Open") -> 152 | D5: =COUNTIFS('HZ-ASD Tracker'!$A$5:$A$994,"<>",'HZ-ASD Tracker'!$E$5:$E$994,"HPC") -> 0 | E5: =COUNTIFS('HZ-ASD Tracker'!$A$5:$A$994,"<>",'HZ-ASD Tracker'!$F$5:$F$994,"AOG",'HZ-ASD Tracker'!$E$5:$E$994,"<>Closed") -> 1 | F5: =COUNTIFS('HZ-ASD Tracker'!$A$5:$A$994,"<>",'HZ-ASD Tracker'!$F$5:$F$994,"Critical",'HZ-ASD Tracker'!$E$5:$E$994,"<>Closed") -> 13 | G5: =IFERROR(COUNTIFS('HZ-ASD Tracker'!$A$5:$A$994,"<>",'HZ-ASD Tracker'!$E$5:$E$994,"Closed")/COUNTIF('HZ-ASD Tracker'!$A$5:$A$994,"<>"),0) -> 0.66810345
A7: TIMELINE — linked to LAYOVER sheet
A8: ="🛬 O.O.S "&TEXT(DASHBOARD!$M$1-1,"DD-MMM")&" 🛫 B.I.S "&TEXT(DASHBOARD!$M$2,"DD-MMM")&" GROUND TIME "&(DASHBOARD!$M$2-DASHBOARD!$M$1+1)&" days"&" · DAY "&MAX(MIN(TODAY()-DASHBOARD!$M$1+1,DASHBOARD!$M$2-DASHBOARD!$M$1+1),0)&"/"&(DASHBOARD!$M$2-DASHBOARD!$M$1+1) -> 🛬 O.O.S 17-Jul 🛫 B.I.S 24-Aug GROUND TIME 38 days · DAY 38/38
A9: =IF(NOT(ISNUMBER(LAYOVER!$B$7)),"📍 Phase: awaiting official schedule","📍 Now: "&IF(AND(ISNUMBER(LAYOVER!$B$37),TODAY()>=LAYOVER!$B$37),"PHASE 5 — Release",IF(AND(ISNUMBER(LAYOVER!$B$27),TODAY()>=LAYOVER!$B$27),"PHASE 4 — Close Up & Final",IF(AND(ISNUMBER(LAYOVER!$B$21),TODAY()>=LAYOVER!$B$21),"PHASE 3 — Mod & Rectification",IF(AND(ISNUMBER(LAYOVER!$B$14),TODAY()>=LAYOVER!$B$14),"PHASE 2 — Inspection","PHASE 1 — Pre Hangar"))))) -> 📍 Now: PHASE 5 — Release
A10: =IF(NOT(ISNUMBER(LAYOVER!$B$19)),"⏳ set findings cutoff (LAYOVER)",IF(TODAY()>LAYOVER!$B$19,"🔒 FINDINGS WINDOW CLOSED","⏳ Findings window closes in: "&(LAYOVER!$B$19-TODAY())&" day(s)")) -> 🔒 FINDINGS WINDOW CLOSED
A11: =IF(MIN(LAYOVER!$D$41:$D$48)=9^9,"📅 No upcoming milestone","📅 Next: "&INDEX(LAYOVER!$A$41:$A$48,MATCH(MIN(LAYOVER!$D$41:$D$48),LAYOVER!$D$41:$D$48,0))&" — "&TEXT(MIN(LAYOVER!$D$41:$D$48),"DD-MMM")&IF(MIN(LAYOVER!$D$41:$D$48)=TODAY()," (TODAY!)"," (in "&(MIN(LAYOVER!$D$41:$D$48)-TODAY())&"d)")) -> 📅 No upcoming milestone
A12: =IF(NOT(ISNUMBER(LAYOVER!$C$28)),"🔒 Cabin close-up: date TBD",IF(TODAY()>LAYOVER!$C$28,"🔒 Close-up date passed — "&COUNTIFS('HZ-ASD Tracker'!$A$5:$A$996,"<>",'HZ-ASD Tracker'!$F$5:$F$996,"ACCESS",'HZ-ASD Tracker'!$E$5:$E$996,"<>Closed")&" ACCESS still open","🔒 Close-up in "&(LAYOVER!$C$28-TODAY())&" day(s) · "&COUNTIFS('HZ-ASD Tracker'!$A$5:$A$996,"<>",'HZ-ASD Tracker'!$F$5:$F$996,"ACCESS",'HZ-ASD Tracker'!$E$5:$E$996,"<>Closed")&" ACCESS still open")) -> 🔒 Close-up date passed — 28 ACCESS still open
A13: BY SOURCE
B14: Closed | C14: Total | D14: % | E14: Window ⏱ | F14: Left
A15: ROUTINE TASKS (WP) | B15: =(COUNTIFS('HZ-ASD Tracker'!$A$5:$A$994,"<>",'HZ-ASD Tracker'!$E$5:$E$994,"Closed")-SUMPRODUCT(('HZ-ASD Tracker'!$A$5:$A$994<>"")*(LEN('HZ-ASD Tracker'!$A$5:$A$994)=8)*ISNUMBER(--'HZ-ASD Tracker'!$A$5:$A$994)*('HZ-ASD Tracker'!$E$5:$E$994="Closed"))+SUMPRODUCT(('HZ-ASD Tracker'!$A$5:$A$994<>"")*(LEN('HZ-ASD Tracker'!$A$5:$A$994)=8)*ISNUMBER(--'HZ-ASD Tracker'!$A$5:$A$994)*(((LEFT('HZ-ASD Tracker'!$B$5:$B$994,3)="6Y_")+(LEFT('HZ-ASD Tracker'!$B$5:$B$994,4)="A_N ")+(LEFT('HZ-ASD Tracker'!$B$5:$B$994,4)="C_N ")+(LEFT('HZ-ASD Tracker'!$B$5:$B$994,4)="DCC-")+(LEFT('HZ-ASD Tracker'!$B$5:$B$994,4)="CCC-")+(LEFT('HZ-ASD Tracker'!$B$5:$B$994,4)="ISC-")+(LEFT('HZ-ASD Tracker'!$B$5:$B$994,7)="WEEKLY-"))>0)*('HZ-ASD Tracker'!$E$5:$E$994="Closed"))) -> 103 | C15: =(COUNTIF('HZ-ASD Tracker'!$A$5:$A$994,"<>")-SUMPRODUCT(('HZ-ASD Tracker'!$A$5:$A$994<>"")*(LEN('HZ-ASD Tracker'!$A$5:$A$994)=8)*ISNUMBER(--'HZ-ASD Tracker'!$A$5:$A$994))+SUMPRODUCT(('HZ-ASD Tracker'!$A$5:$A$994<>"")*(LEN('HZ-ASD Tracker'!$A$5:$A$994)=8)*ISNUMBER(--'HZ-ASD Tracker'!$A$5:$A$994)*(((LEFT('HZ-ASD Tracker'!$B$5:$B$994,3)="6Y_")+(LEFT('HZ-ASD Tracker'!$B$5:$B$994,4)="A_N ")+(LEFT('HZ-ASD Tracker'!$B$5:$B$994,4)="C_N ")+(LEFT('HZ-ASD Tracker'!$B$5:$B$994,4)="DCC-")+(LEFT('HZ-ASD Tracker'!$B$5:$B$994,4)="CCC-")+(LEFT('HZ-ASD Tracker'!$B$5:$B$994,4)="ISC-")+(LEFT('HZ-ASD Tracker'!$B$5:$B$994,7)="WEEKLY-"))>0))) -> 165 | D15: =IFERROR(B15/C15,0) -> 0.62424242 | E15: =MIN(MAX((TODAY()-DASHBOARD!$M$1)/(DASHBOARD!$M$2-DASHBOARD!$M$1),0),1) -> 1 | F15: =C15-B15 -> 62 | G15: =IF(D15=0,"",D15) -> 0.62424242
A16: ENG ORDERS (EOD/AD/EO) | B16: =SUMPRODUCT(('HZ-ASD Tracker'!$A$5:$A$994<>"")*(LEN('HZ-ASD Tracker'!$A$5:$A$994)=8)*ISNUMBER(--'HZ-ASD Tracker'!$A$5:$A$994)*(((LEFT('HZ-ASD Tracker'!$B$5:$B$994,4)="EOD-")+(LEFT('HZ-ASD Tracker'!$B$5:$B$994,3)="EO-")+(LEFT('HZ-ASD Tracker'!$B$5:$B$994,3)="ER-")+(LEFT('HZ-ASD Tracker'!$B$5:$B$994,5)="FRSEO")+(LEFT('HZ-ASD Tracker'!$B$5:$B$994,1)="S")*ISNUMBER(--MID('HZ-ASD Tracker'!$B$5:$B$994,2,2))*(MID('HZ-ASD Tracker'!$B$5:$B$994,4,2)="-R")+(LEFT('HZ-ASD Tracker'!$B$5:$B$994,8)="REPLACE ")+ISNUMBER(SEARCH("/AD-",'HZ-ASD Tracker'!$B$5:$B$994)))>0)*('HZ-ASD Tracker'!$E$5:$E$994="Closed")) -> 10 | C16: =SUMPRODUCT(('HZ-ASD Tracker'!$A$5:$A$994<>"")*(LEN('HZ-ASD Tracker'!$A$5:$A$994)=8)*ISNUMBER(--'HZ-ASD Tracker'!$A$5:$A$994)*(((LEFT('HZ-ASD Tracker'!$B$5:$B$994,4)="EOD-")+(LEFT('HZ-ASD Tracker'!$B$5:$B$994,3)="EO-")+(LEFT('HZ-ASD Tracker'!$B$5:$B$994,3)="ER-")+(LEFT('HZ-ASD Tracker'!$B$5:$B$994,5)="FRSEO")+(LEFT('HZ-ASD Tracker'!$B$5:$B$994,1)="S")*ISNUMBER(--MID('HZ-ASD Tracker'!$B$5:$B$994,2,2))*(MID('HZ-ASD Tracker'!$B$5:$B$994,4,2)="-R")+(LEFT('HZ-ASD Tracker'!$B$5:$B$994,8)="REPLACE ")+ISNUMBER(SEARCH("/AD-",'HZ-ASD Tracker'!$B$5:$B$994)))>0)) -> 19 | D16: =IFERROR(B16/C16,0) -> 0.52631579 | E16: =IF(AND(ISNUMBER(LAYOVER!$B$22),ISNUMBER(LAYOVER!$C$22)),MIN(MAX((TODAY()-LAYOVER!$B$22)/(LAYOVER!$C$22-LAYOVER!$B$22),0),1),"") -> 1 | F16: =C16-B16 -> 9 | G16: =IF(D16=0,"",D16) -> 0.52631579
A17: FINDINGS (AMOS) | B17: =(SUMPRODUCT(('HZ-ASD Tracker'!$A$5:$A$994<>"")*(LEN('HZ-ASD Tracker'!$A$5:$A$994)=8)*ISNUMBER(--'HZ-ASD Tracker'!$A$5:$A$994)*('HZ-ASD Tracker'!$E$5:$E$994="Closed"))-SUMPRODUCT(('HZ-ASD Tracker'!$A$5:$A$994<>"")*(LEN('HZ-ASD Tracker'!$A$5:$A$994)=8)*ISNUMBER(--'HZ-ASD Tracker'!$A$5:$A$994)*(((LEFT('HZ-ASD Tracker'!$B$5:$B$994,4)="EOD-")+(LEFT('HZ-ASD Tracker'!$B$5:$B$994,3)="EO-")+(LEFT('HZ-ASD Tracker'!$B$5:$B$994,3)="ER-")+(LEFT('HZ-ASD Tracker'!$B$5:$B$994,5)="FRSEO")+(LEFT('HZ-ASD Tracker'!$B$5:$B$994,1)="S")*ISNUMBER(--MID('HZ-ASD Tracker'!$B$5:$B$994,2,2))*(MID('HZ-ASD Tracker'!$B$5:$B$994,4,2)="-R")+(LEFT('HZ-ASD Tracker'!$B$5:$B$994,8)="REPLACE ")+ISNUMBER(SEARCH("/AD-",'HZ-ASD Tracker'!$B$5:$B$994)))>0)*('HZ-ASD Tracker'!$E$5:$E$994="Closed"))-SUMPRODUCT(('HZ-ASD Tracker'!$A$5:$A$994<>"")*(LEN('HZ-ASD Tracker'!$A$5:$A$994)=8)*ISNUMBER(--'HZ-ASD Tracker'!$A$5:$A$994)*(((LEFT('HZ-ASD Tracker'!$B$5:$B$994,3)="6Y_")+(LEFT('HZ-ASD Tracker'!$B$5:$B$994,4)="A_N ")+(LEFT('HZ-ASD Tracker'!$B$5:$B$994,4)="C_N ")+(LEFT('HZ-ASD Tracker'!$B$5:$B$994,4)="DCC-")+(LEFT('HZ-ASD Tracker'!$B$5:$B$994,4)="CCC-")+(LEFT('HZ-ASD Tracker'!$B$5:$B$994,4)="ISC-")+(LEFT('HZ-ASD Tracker'!$B$5:$B$994,7)="WEEKLY-"))>0)*('HZ-ASD Tracker'!$E$5:$E$994="Closed"))) -> 197 | C17: =(SUMPRODUCT(('HZ-ASD Tracker'!$A$5:$A$994<>"")*(LEN('HZ-ASD Tracker'!$A$5:$A$994)=8)*ISNUMBER(--'HZ-ASD Tracker'!$A$5:$A$994))-SUMPRODUCT(('HZ-ASD Tracker'!$A$5:$A$994<>"")*(LEN('HZ-ASD Tracker'!$A$5:$A$994)=8)*ISNUMBER(--'HZ-ASD Tracker'!$A$5:$A$994)*(((LEFT('HZ-ASD Tracker'!$B$5:$B$994,4)="EOD-")+(LEFT('HZ-ASD Tracker'!$B$5:$B$994,3)="EO-")+(LEFT('HZ-ASD Tracker'!$B$5:$B$994,3)="ER-")+(LEFT('HZ-ASD Tracker'!$B$5:$B$994,5)="FRSEO")+(LEFT('HZ-ASD Tracker'!$B$5:$B$994,1)="S")*ISNUMBER(--MID('HZ-ASD Tracker'!$B$5:$B$994,2,2))*(MID('HZ-ASD Tracker'!$B$5:$B$994,4,2)="-R")+(LEFT('HZ-ASD Tracker'!$B$5:$B$994,8)="REPLACE ")+ISNUMBER(SEARCH("/AD-",'HZ-ASD Tracker'!$B$5:$B$994)))>0))-SUMPRODUCT(('HZ-ASD Tracker'!$A$5:$A$994<>"")*(LEN('HZ-ASD Tracker'!$A$5:$A$994)=8)*ISNUMBER(--'HZ-ASD Tracker'!$A$5:$A$994)*(((LEFT('HZ-ASD Tracker'!$B$5:$B$994,3)="6Y_")+(LEFT('HZ-ASD Tracker'!$B$5:$B$994,4)="A_N ")+(LEFT('HZ-ASD Tracker'!$B$5:$B$994,4)="C_N ")+(LEFT('HZ-ASD Tracker'!$B$5:$B$994,4)="DCC-")+(LEFT('HZ-ASD Tracker'!$B$5:$B$994,4)="CCC-")+(LEFT('HZ-ASD Tracker'!$B$5:$B$994,4)="ISC-")+(LEFT('HZ-ASD Tracker'!$B$5:$B$994,7)="WEEKLY-"))>0))) -> 280 | D17: =IFERROR(B17/C17,0) -> 0.70357143 | E17: =IF(AND(ISNUMBER(LAYOVER!$B$21),ISNUMBER(LAYOVER!$C$21)),MIN(MAX((TODAY()-LAYOVER!$B$21)/(LAYOVER!$C$21-LAYOVER!$B$21),0),1),"") -> 1 | F17: =C17-B17 -> 83 | G17: =IF(D17=0,"",D17) -> 0.70357143
A19: BY CATEGORY
B20: Closed | C20: Total | D20: % | E20: Share | F20: Left
A21: GENERAL CABIN | B21: =COUNTIFS('HZ-ASD Tracker'!$A$5:$A$994,"<>",'HZ-ASD Tracker'!$D$5:$D$994,"GENERAL CABIN",'HZ-ASD Tracker'!$E$5:$E$994,"Closed") -> 43 | C21: =COUNTIFS('HZ-ASD Tracker'!$A$5:$A$994,"<>",'HZ-ASD Tracker'!$D$5:$D$994,"GENERAL CABIN") -> 73 | D21: =IFERROR(B21/C21,0) -> 0.5890411 | E21: =IFERROR(C21/COUNTIF('HZ-ASD Tracker'!$A$5:$A$994,"<>"),0) -> 0.15732759 | F21: =C21-B21 -> 30 | G21: =IF(D21=0,"",D21) -> 0.5890411
A22: GALLEY | B22: =COUNTIFS('HZ-ASD Tracker'!$A$5:$A$994,"<>",'HZ-ASD Tracker'!$D$5:$D$994,"GALLEY",'HZ-ASD Tracker'!$E$5:$E$994,"Closed") -> 36 | C22: =COUNTIFS('HZ-ASD Tracker'!$A$5:$A$994,"<>",'HZ-ASD Tracker'!$D$5:$D$994,"GALLEY") -> 53 | D22: =IFERROR(B22/C22,0) -> 0.67924528 | E22: =IFERROR(C22/COUNTIF('HZ-ASD Tracker'!$A$5:$A$994,"<>"),0) -> 0.11422414 | F22: =C22-B22 -> 17 | G22: =IF(D22=0,"",D22) -> 0.67924528
A23: LAVATORY | B23: =COUNTIFS('HZ-ASD Tracker'!$A$5:$A$994,"<>",'HZ-ASD Tracker'!$D$5:$D$994,"LAVATORY",'HZ-ASD Tracker'!$E$5:$E$994,"Closed") -> 33 | C23: =COUNTIFS('HZ-ASD Tracker'!$A$5:$A$994,"<>",'HZ-ASD Tracker'!$D$5:$D$994,"LAVATORY") -> 43 | D23: =IFERROR(B23/C23,0) -> 0.76744186 | E23: =IFERROR(C23/COUNTIF('HZ-ASD Tracker'!$A$5:$A$994,"<>"),0) -> 0.092672414 | F23: =C23-B23 -> 10 | G23: =IF(D23=0,"",D23) -> 0.76744186
A24: PAX DOORS | B24: =COUNTIFS('HZ-ASD Tracker'!$A$5:$A$994,"<>",'HZ-ASD Tracker'!$D$5:$D$994,"PAX DOORS",'HZ-ASD Tracker'!$E$5:$E$994,"Closed") -> 45 | C24: =COUNTIFS('HZ-ASD Tracker'!$A$5:$A$994,"<>",'HZ-ASD Tracker'!$D$5:$D$994,"PAX DOORS") -> 63 | D24: =IFERROR(B24/C24,0) -> 0.71428571 | E24: =IFERROR(C24/COUNTIF('HZ-ASD Tracker'!$A$5:$A$994,"<>"),0) -> 0.13577586 | F24: =C24-B24 -> 18 | G24: =IF(D24=0,"",D24) -> 0.71428571
A25: F/A SEAT | B25: =COUNTIFS('HZ-ASD Tracker'!$A$5:$A$994,"<>",'HZ-ASD Tracker'!$D$5:$D$994,"F/A SEAT",'HZ-ASD Tracker'!$E$5:$E$994,"Closed") -> 24 | C25: =COUNTIFS('HZ-ASD Tracker'!$A$5:$A$994,"<>",'HZ-ASD Tracker'!$D$5:$D$994,"F/A SEAT") -> 41 | D25: =IFERROR(B25/C25,0) -> 0.58536585 | E25: =IFERROR(C25/COUNTIF('HZ-ASD Tracker'!$A$5:$A$994,"<>"),0) -> 0.088362069 | F25: =C25-B25 -> 17 | G25: =IF(D25=0,"",D25) -> 0.58536585
A26: PAX SEAT | B26: =COUNTIFS('HZ-ASD Tracker'!$A$5:$A$994,"<>",'HZ-ASD Tracker'!$D$5:$D$994,"PAX SEAT",'HZ-ASD Tracker'!$E$5:$E$994,"Closed") -> 45 | C26: =COUNTIFS('HZ-ASD Tracker'!$A$5:$A$994,"<>",'HZ-ASD Tracker'!$D$5:$D$994,"PAX SEAT") -> 68 | D26: =IFERROR(B26/C26,0) -> 0.66176471 | E26: =IFERROR(C26/COUNTIF('HZ-ASD Tracker'!$A$5:$A$994,"<>"),0) -> 0.14655172 | F26: =C26-B26 -> 23 | G26: =IF(D26=0,"",D26) -> 0.66176471
A27: FLIGHT DECK | B27: =COUNTIFS('HZ-ASD Tracker'!$A$5:$A$994,"<>",'HZ-ASD Tracker'!$D$5:$D$994,"FLIGHT DECK",'HZ-ASD Tracker'!$E$5:$E$994,"Closed") -> 56 | C27: =COUNTIFS('HZ-ASD Tracker'!$A$5:$A$994,"<>",'HZ-ASD Tracker'!$D$5:$D$994,"FLIGHT DECK") -> 60 | D27: =IFERROR(B27/C27,0) -> 0.93333333 | E27: =IFERROR(C27/COUNTIF('HZ-ASD Tracker'!$A$5:$A$994,"<>"),0) -> 0.12931034 | F27: =C27-B27 -> 4 | G27: =IF(D27=0,"",D27) -> 0.93333333
A28: TEDLAR/SIDEWALL | B28: =COUNTIFS('HZ-ASD Tracker'!$A$5:$A$994,"<>",'HZ-ASD Tracker'!$D$5:$D$994,"TEDLAR/SIDEWALL",'HZ-ASD Tracker'!$E$5:$E$994,"Closed") -> 14 | C28: =COUNTIFS('HZ-ASD Tracker'!$A$5:$A$994,"<>",'HZ-ASD Tracker'!$D$5:$D$994,"TEDLAR/SIDEWALL") -> 15 | D28: =IFERROR(B28/C28,0) -> 0.93333333 | E28: =IFERROR(C28/COUNTIF('HZ-ASD Tracker'!$A$5:$A$994,"<>"),0) -> 0.032327586 | F28: =C28-B28 -> 1 | G28: =IF(D28=0,"",D28) -> 0.93333333
A29: ACCESS | B29: =COUNTIFS('HZ-ASD Tracker'!$A$5:$A$994,"<>",'HZ-ASD Tracker'!$F$5:$F$994,"ACCESS",'HZ-ASD Tracker'!$E$5:$E$994,"Closed") -> 3 | C29: =COUNTIFS('HZ-ASD Tracker'!$A$5:$A$994,"<>",'HZ-ASD Tracker'!$F$5:$F$994,"ACCESS") -> 31 | D29: =IFERROR(B29/C29,0) -> 0.096774194 | E29: =IFERROR(C29/COUNTIF('HZ-ASD Tracker'!$A$5:$A$994,"<>"),0) -> 0.066810345 | F29: =C29-B29 -> 28 | G29: =IF(D29=0,"",D29) -> 0.096774194
A30: ACFT GENERAL T/C | B30: =COUNTIFS('HZ-ASD Tracker'!$A$5:$A$994,"<>",'HZ-ASD Tracker'!$D$5:$D$994,"ACFT GENERAL T/C",'HZ-ASD Tracker'!$E$5:$E$994,"Closed") -> 13 | C30: =COUNTIFS('HZ-ASD Tracker'!$A$5:$A$994,"<>",'HZ-ASD Tracker'!$D$5:$D$994,"ACFT GENERAL T/C") -> 47 | D30: =IFERROR(B30/C30,0) -> 0.27659574 | E30: =IFERROR(C30/COUNTIF('HZ-ASD Tracker'!$A$5:$A$994,"<>"),0) -> 0.1012931 | F30: =C30-B30 -> 34 | G30: =IF(D30=0,"",D30) -> 0.27659574
A32: SPECIALTY
B33: Closed | C33: Total | D33: % | E33: Share | F33: Left
A34: CAB | B34: =COUNTIFS('HZ-ASD Tracker'!$A$5:$A$994,"<>",'HZ-ASD Tracker'!$G$5:$G$994,"CAB",'HZ-ASD Tracker'!$E$5:$E$994,"Closed") -> 131 | C34: =COUNTIFS('HZ-ASD Tracker'!$A$5:$A$994,"<>",'HZ-ASD Tracker'!$G$5:$G$994,"CAB") -> 216 | D34: =IFERROR(B34/C34,0) -> 0.60648148 | E34: =IFERROR(C34/COUNTIF('HZ-ASD Tracker'!$A$5:$A$994,"<>"),0) -> 0.46551724 | F34: =C34-B34 -> 85 | G34: =IF(D34=0,"",D34) -> 0.60648148
A35: SEAT | B35: =COUNTIFS('HZ-ASD Tracker'!$A$5:$A$994,"<>",'HZ-ASD Tracker'!$G$5:$G$994,"SEAT",'HZ-ASD Tracker'!$E$5:$E$994,"Closed") -> 39 | C35: =COUNTIFS('HZ-ASD Tracker'!$A$5:$A$994,"<>",'HZ-ASD Tracker'!$G$5:$G$994,"SEAT") -> 54 | D35: =IFERROR(B35/C35,0) -> 0.72222222 | E35: =IFERROR(C35/COUNTIF('HZ-ASD Tracker'!$A$5:$A$994,"<>"),0) -> 0.11637931 | F35: =C35-B35 -> 15 | G35: =IF(D35=0,"",D35) -> 0.72222222
A36: AV | B36: =COUNTIFS('HZ-ASD Tracker'!$A$5:$A$994,"<>",'HZ-ASD Tracker'!$G$5:$G$994,"AV",'HZ-ASD Tracker'!$E$5:$E$994,"Closed") -> 30 | C36: =COUNTIFS('HZ-ASD Tracker'!$A$5:$A$994,"<>",'HZ-ASD Tracker'!$G$5:$G$994,"AV") -> 37 | D36: =IFERROR(B36/C36,0) -> 0.81081081 | E36: =IFERROR(C36/COUNTIF('HZ-ASD Tracker'!$A$5:$A$994,"<>"),0) -> 0.079741379 | F36: =C36-B36 -> 7 | G36: =IF(D36=0,"",D36) -> 0.81081081
A37: WALL | B37: =COUNTIFS('HZ-ASD Tracker'!$A$5:$A$994,"<>",'HZ-ASD Tracker'!$G$5:$G$994,"WALL",'HZ-ASD Tracker'!$E$5:$E$994,"Closed") -> 22 | C37: =COUNTIFS('HZ-ASD Tracker'!$A$5:$A$994,"<>",'HZ-ASD Tracker'!$G$5:$G$994,"WALL") -> 22 | D37: =IFERROR(B37/C37,0) -> 1 | E37: =IFERROR(C37/COUNTIF('HZ-ASD Tracker'!$A$5:$A$994,"<>"),0) -> 0.047413793 | F37: =C37-B37 -> 0 | G37: =IF(D37=0,"",D37) -> 1
A38: S/M | B38: =COUNTIFS('HZ-ASD Tracker'!$A$5:$A$994,"<>",'HZ-ASD Tracker'!$G$5:$G$994,"S/M",'HZ-ASD Tracker'!$E$5:$E$994,"Closed") -> 10 | C38: =COUNTIFS('HZ-ASD Tracker'!$A$5:$A$994,"<>",'HZ-ASD Tracker'!$G$5:$G$994,"S/M") -> 14 | D38: =IFERROR(B38/C38,0) -> 0.71428571 | E38: =IFERROR(C38/COUNTIF('HZ-ASD Tracker'!$A$5:$A$994,"<>"),0) -> 0.030172414 | F38: =C38-B38 -> 4 | G38: =IF(D38=0,"",D38) -> 0.71428571
A39: PAINT | B39: =COUNTIFS('HZ-ASD Tracker'!$A$5:$A$994,"<>",'HZ-ASD Tracker'!$G$5:$G$994,"PAINT",'HZ-ASD Tracker'!$E$5:$E$994,"Closed") -> 33 | C39: =COUNTIFS('HZ-ASD Tracker'!$A$5:$A$994,"<>",'HZ-ASD Tracker'!$G$5:$G$994,"PAINT") -> 41 | D39: =IFERROR(B39/C39,0) -> 0.80487805 | E39: =IFERROR(C39/COUNTIF('HZ-ASD Tracker'!$A$5:$A$994,"<>"),0) -> 0.088362069 | F39: =C39-B39 -> 8 | G39: =IF(D39=0,"",D39) -> 0.80487805
A40: JOINT | B40: =COUNTIFS('HZ-ASD Tracker'!$A$5:$A$994,"<>",'HZ-ASD Tracker'!$G$5:$G$994,"JOINT",'HZ-ASD Tracker'!$E$5:$E$994,"Closed") -> 22 | C40: =COUNTIFS('HZ-ASD Tracker'!$A$5:$A$994,"<>",'HZ-ASD Tracker'!$G$5:$G$994,"JOINT") -> 36 | D40: =IFERROR(B40/C40,0) -> 0.61111111 | E40: =IFERROR(C40/COUNTIF('HZ-ASD Tracker'!$A$5:$A$994,"<>"),0) -> 0.077586207 | F40: =C40-B40 -> 14 | G40: =IF(D40=0,"",D40) -> 0.61111111
A41: INSP | B41: =COUNTIFS('HZ-ASD Tracker'!$A$5:$A$994,"<>",'HZ-ASD Tracker'!$G$5:$G$994,"INSP",'HZ-ASD Tracker'!$E$5:$E$994,"Closed") -> 11 | C41: =COUNTIFS('HZ-ASD Tracker'!$A$5:$A$994,"<>",'HZ-ASD Tracker'!$G$5:$G$994,"INSP") -> 18 | D41: =IFERROR(B41/C41,0) -> 0.61111111 | E41: =IFERROR(C41/COUNTIF('HZ-ASD Tracker'!$A$5:$A$994,"<>"),0) -> 0.038793103 | F41: =C41-B41 -> 7 | G41: =IF(D41=0,"",D41) -> 0.61111111
A42: AP | B42: =COUNTIFS('HZ-ASD Tracker'!$A$5:$A$994,"<>",'HZ-ASD Tracker'!$G$5:$G$994,"AP",'HZ-ASD Tracker'!$E$5:$E$994,"Closed") -> 9 | C42: =COUNTIFS('HZ-ASD Tracker'!$A$5:$A$994,"<>",'HZ-ASD Tracker'!$G$5:$G$994,"AP") -> 18 | D42: =IFERROR(B42/C42,0) -> 0.5 | E42: =IFERROR(C42/COUNTIF('HZ-ASD Tracker'!$A$5:$A$994,"<>"),0) -> 0.038793103 | F42: =C42-B42 -> 9 | G42: =IF(D42=0,"",D42) -> 0.5
A44: DAILY CLOSURES — last 10 days | C44: Σ Closed | D44: Left | E44: Cum % | F44: =IF(COUNTIFS('HZ-ASD Tracker'!$A$5:$A$995,"<>",'HZ-ASD Tracker'!$E$5:$E$995,"Closed")>=ROUND(COUNTIF('HZ-ASD Tracker'!$A$5:$A$995,"<>")*VLOOKUP(MAX(MIN(TODAY()-DASHBOARD!$M$1+1,38),1),'FULL PKG'!$L$2:$M$39,2,0),0),"📈 S-curve: +"&(COUNTIFS('HZ-ASD Tracker'!$A$5:$A$995,"<>",'HZ-ASD Tracker'!$E$5:$E$995,"Closed")-ROUND(COUNTIF('HZ-ASD Tracker'!$A$5:$A$995,"<>")*VLOOKUP(MAX(MIN(TODAY()-DASHBOARD!$M$1+1,38),1),'FULL PKG'!$L$2:$M$39,2,0),0))&" ahead 🟢","📉 S-curve: "&(COUNTIFS('HZ-ASD Tracker'!$A$5:$A$995,"<>",'HZ-ASD Tracker'!$E$5:$E$995,"Closed")-ROUND(COUNTIF('HZ-ASD Tracker'!$A$5:$A$995,"<>")*VLOOKUP(MAX(MIN(TODAY()-DASHBOARD!$M$1+1,38),1),'FULL PKG'!$L$2:$M$39,2,0),0))&" behind 🔴") -> #N/A
...

Sheet AOG
A1: AOG / MATERIAL — CABIN CARDS · HZ-ASD C2+6Y · 19-Aug-2026
A2: ="Part lines: "&COUNTIF($B$4:$B$185,"<>")&" · 🔴 NOT AVAILABLE: "&COUNTIF($I$4:$I$185,"NOT AVAILABLE")&" · 🟢 AVAILABLE: "&COUNTIF($I$4:$I$185,"AVAILABLE") -> Part lines: 12 · 🔴 NOT AVAILABLE: 10 · 🟢 AVAILABLE: 0
A3: # | B3: WO | C3: Seq | D3: Card Description | E3: Part No. | F3: Part Description | G3: Qty | H3: Unit | I3: Availability | J3: Transfer | K3: Created | L3: Note | M3: Delivery
A4: =IF($B4="","",COUNTA($B$4:$B4)) -> 1 | B4: 32984848 | C4: 1012 | D4: SM - NO CALLBACK - GALLEY G2 G2 GALLEY COMP. 205, 202, AND 209 MISSING STRIKER. | E4: SP0614 | F4: STRIKER PLATE U/O PN 330SVA4RGA00 | G4: 3 | H4: EA | I4: NOT AVAILABLE | J4: TRANSFER_NEEDED | K4: 20.Jul.2026 | L4: — | M4: —
A5: =IF($B5="","",COUNTA($B$4:$B5)) -> 2 | B5: 32985332 | C5: 1038 | D5: CAB - NO CALL BACK L1 DOOR INBOARD F/A SEAT BELT DIRTY | E5: 4115-1-131-8110 | F5: RESTRNT-SYSTEM | G5: 2 | H5: EA | I5: NOT AVAILABLE | J5: — | K5: 20.Jul.2026 | L5: P26081726, 60 EA, EDD 10AUG26 | M5: —
A6: =IF($B6="","",COUNTA($B$4:$B6)) -> 3 | B6: 32985343 | C6: 1045 | D6: CAB - NO CALLBACK L1 DOOR OUTBOARD F/A SEAT BELT DIRTY | E6: 4115-1-131-8110 | F6: RESTRNT-SYSTEM | G6: 2 | H6: EA | I6: NOT AVAILABLE | J6: — | K6: 20.Jul.2026 | L6: P26081726, 60 EA, EDD 10AUG26 | M6: —
A7: =IF($B7="","",COUNTA($B$4:$B7)) -> 4 | B7: 32991511 | C7: 1202 | D7: CAB - RII - LAV E LAV E ACCESS DOOR WASTE COMPARTMENT WITH SMALL CRACK NEXT TO LATCH. | E7: A225400429-750 | F7: DOOR ASSY-WASHBASIN | G7: 1 | H7: EA | I7: NOT AVAILABLE | J7: — | K7: 23.Jul.2026 | L7: — | M7: —
A8: =IF($B8="","",COUNTA($B$4:$B8)) -> 5 | B8: 32988850 | C8: 1121 | D8: CAB - NO CALLBACK - FWD GALLEY FWD GALLEY 8 EA AIR FLAP SEAL DETERIORATED. | E8: SP1395 | F8: VALVE ASSY-FLAP | G8: 6 | H8: EA | I8: NOT AVAILABLE | J8: — | K8: 27.Jul.2026 | L8: 02 EA ISSUED TO ACFT, PO P26712626, 03 EA, NEW PO, U/APPROVAL. | M8: —
A9: =IF($B9="","",COUNTA($B$4:$B9)) -> 6 | B9: 33022670 | C9: 1342 | D9: CAB - NO CALL BACK - GALLEY G2 GALLEY FOOT STEP LEVER MISSING | E9: 3212MU01SA41 | F9: FOOTSTEP ASSY | G9: 1 | H9: EA | I9: NOT AVAILABLE | J9: — | K9: 28.Jul.2026 | L9: — | M9: —
A10: =IF($B10="","",COUNTA($B$4:$B10)) -> 7 | B10: 32985350 | C10: 1049 | D10: CAB - NO CALLBACK L1 DOOR OUTBOARD F/A SEAT LOWER BACK CUSHION WORN OUT | E10: 2E7003-1 | F10: CUSHION-BACK | G10: 2 | H10: EA | I10: NOT AVAILABLE | J10: TRANSFER_NEEDED | K10: 30.Jul.2026 | L10: AVBL (JED=1,RUH=5). | M10: —
A11: =IF($B11="","",COUNTA($B$4:$B11)) -> 8 | B11: 32985304 | C11: 1036 | D11: CAB - NO CALLBACK L1 DOOR INBOARD F/A SEAT LOWER BACK CUSHION WORN OUT | E11: 2E7003-1 | F11: CUSHION-BACK | G11: 1 | H11: EA | I11: NOT AVAILABLE | J11: TRANSFER_NEEDED | K11: 30.Jul.2026 | L11: AVBL (JED=1,RUH=5). | M11: —
A12: =IF($B12="","",COUNTA($B$4:$B12)) -> 9 | B12: 32985832 | C12: 1061 | D12: CAB -RII DURING OXYGEN GENERATOR CHECK FOUND GREEN LANYARD MISSING AND BRIDLE ASSY AT SEAT# 1 AC,2AC ,4AC,5AC,30ABC,31ABC,32ABC,34ABC,35ABC,36ABC,37ABC,38ABC,40ABC,41ABC,42ABC,43ABC,44ABC, | E12: E60614-00-0240 | F12: LANYARD, GENERATOR RELEASE (GREEN) | G12: 72 | H12: EA | I12: ORDERED | J12: — | K12: 04.Aug.2026 | L12: — | M12: 15.Aug.2026
A13: =IF($B13="","",COUNTA($B$4:$B13)) -> 10 | B13: 32985833 | C13: 1062 | D13: CAB -RII DURING OXYGEN GENERATOR CHECK FOUND GREEN LANYARD MISSING AND BRIDLE ASSY AT SEAT# 2JL,4JL,30JKL,31JKL32JKL,34JKL,36JKL,37JKL,38JKL,39JKL,40JKL,41JKL,42JKL,43JKL,44JKL. | E13: E60614-00-0240 | F13: LANYARD, GENERATOR RELEASE (GREEN) | G13: 72 | H13: EA | I13: ORDERED | J13: — | K13: 04.Aug.2026 | L13: — | M13: 05.Aug.2026
A14: =IF($B14="","",COUNTA($B$4:$B14)) -> 11 | B14: 32984848 | C14: 1012 | D14: SM - NO CALLBACK - GALLEY G2 G2 GALLEY COMP. 205, 202, AND 209 MISSING STRIKER. | E14: SP0614 | F14: STRIKER PLATE U/O PN 330SVA4RGA00 | G14: 3 | H14: EA | I14: NOT AVAILABLE | J14: TRANSFER_NEEDED | K14: 06.Aug.2026 | L14: — | M14: —
A15: =IF($B15="","",COUNTA($B$4:$B15)) -> 12 | B15: 33069524 | C15: 1431 | D15: CAB - NO CALLBACK -AFT GALLEY AFT GALLEY 1 EA AIR FLAP SEALTORN. | E15: SP1395 | F15: VALVE ASSY-FLAP | G15: 1 | H15: EA | I15: NOT AVAILABLE | J15: — | K15: 06.Aug.2026 | L15: — | M15: —

Sheet LAYOVER
D1: HZ-ASD C2+6Y-CHK + WIFI — LAYOVER SCHEDULE | AQ1: ="O.O.S "&TEXT(DASHBOARD!$M$1-1,"DD-MMM")&" B.I.S "&TEXT(DASHBOARD!$M$2,"DD-MMM")&" GROUND TIME "&(DASHBOARD!$M$2-DASHBOARD!$M$1+1)&" DAYS" -> O.O.S 17-Jul B.I.S 24-Aug GROUND TIME 38 DAYS
A3: TASK | B3: Start | C3: Finish | D3: =IF(DASHBOARD!$M$2-DASHBOARD!$M$1>=0,"Day "&1,"") -> Day 1 | G3: =IF(DASHBOARD!$M$2-DASHBOARD!$M$1>=1,"Day "&2,"") -> Day 2 | J3: =IF(DASHBOARD!$M$2-DASHBOARD!$M$1>=2,"Day "&3,"") -> Day 3 | M3: =IF(DASHBOARD!$M$2-DASHBOARD!$M$1>=3,"Day "&4,"") -> Day 4 | P3: =IF(DASHBOARD!$M$2-DASHBOARD!$M$1>=4,"Day "&5,"") -> Day 5 | S3: =IF(DASHBOARD!$M$2-DASHBOARD!$M$1>=5,"Day "&6,"") -> Day 6 | V3: =IF(DASHBOARD!$M$2-DASHBOARD!$M$1>=6,"Day "&7,"") -> Day 7 | Y3: =IF(DASHBOARD!$M$2-DASHBOARD!$M$1>=7,"Day "&8,"") -> Day 8 | AB3: =IF(DASHBOARD!$M$2-DASHBOARD!$M$1>=8,"Day "&9,"") -> Day 9 | AE3: =IF(DASHBOARD!$M$2-DASHBOARD!$M$1>=9,"Day "&10,"") -> Day 10 | AH3: =IF(DASHBOARD!$M$2-DASHBOARD!$M$1>=10,"Day "&11,"") -> Day 11 | AK3: =IF(DASHBOARD!$M$2-DASHBOARD!$M$1>=11,"Day "&12,"") -> Day 12 | AN3: =IF(DASHBOARD!$M$2-DASHBOARD!$M$1>=12,"Day "&13,"") -> Day 13 | AQ3: =IF(DASHBOARD!$M$2-DASHBOARD!$M$1>=13,"Day "&14,"") -> Day 14 | AT3: =IF(DASHBOARD!$M$2-DASHBOARD!$M$1>=14,"Day "&15,"") -> Day 15 | AW3: =IF(DASHBOARD!$M$2-DASHBOARD!$M$1>=15,"Day "&16,"") -> Day 16 | AZ3: =IF(DASHBOARD!$M$2-DASHBOARD!$M$1>=16,"Day "&17,"") -> Day 17 | BC3: =IF(DASHBOARD!$M$2-DASHBOARD!$M$1>=17,"Day "&18,"") -> Day 18 | BF3: =IF(DASHBOARD!$M$2-DASHBOARD!$M$1>=18,"Day "&19,"") -> Day 19 | BI3: =IF(DASHBOARD!$M$2-DASHBOARD!$M$1>=19,"Day "&20,"") -> Day 20 | BL3: =IF(DASHBOARD!$M$2-DASHBOARD!$M$1>=20,"Day "&21,"") -> Day 21 | BO3: =IF(DASHBOARD!$M$2-DASHBOARD!$M$1>=21,"Day "&22,"") -> Day 22 | BR3: =IF(DASHBOARD!$M$2-DASHBOARD!$M$1>=22,"Day "&23,"") -> Day 23 | BU3: =IF(DASHBOARD!$M$2-DASHBOARD!$M$1>=23,"Day "&24,"") -> Day 24 | BX3: =IF(DASHBOARD!$M$2-DASHBOARD!$M$1>=24,"Day "&25,"") -> Day 25 | CA3: =IF(DASHBOARD!$M$2-DASHBOARD!$M$1>=25,"Day "&26,"") -> Day 26 | CD3: =IF(DASHBOARD!$M$2-DASHBOARD!$M$1>=26,"Day "&27,"") -> Day 27 | CG3: =IF(DASHBOARD!$M$2-DASHBOARD!$M$1>=27,"Day "&28,"") -> Day 28 | CJ3: =IF(DASHBOARD!$M$2-DASHBOARD!$M$1>=28,"Day "&29,"") -> Day 29 | CM3: =IF(DASHBOARD!$M$2-DASHBOARD!$M$1>=29,"Day "&30,"") -> Day 30 | CP3: =IF(DASHBOARD!$M$2-DASHBOARD!$M$1>=30,"Day "&31,"") -> Day 31 | CS3: =IF(DASHBOARD!$M$2-DASHBOARD!$M$1>=31,"Day "&32,"") -> Day 32 | CV3: =IF(DASHBOARD!$M$2-DASHBOARD!$M$1>=32,"Day "&33,"") -> Day 33 | CY3: =IF(DASHBOARD!$M$2-DASHBOARD!$M$1>=33,"Day "&34,"") -> Day 34 | DB3: =IF(DASHBOARD!$M$2-DASHBOARD!$M$1>=34,"Day "&35,"") -> Day 35 | DE3: =IF(DASHBOARD!$M$2-DASHBOARD!$M$1>=35,"Day "&36,"") -> Day 36 | DH3: =IF(DASHBOARD!$M$2-DASHBOARD!$M$1>=36,"Day "&37,"") -> Day 37 | DK3: =IF(DASHBOARD!$M$2-DASHBOARD!$M$1>=37,"Day "&38,"") -> Day 38 | DN3: =IF(DASHBOARD!$M$2-DASHBOARD!$M$1>=38,"Day "&39,"") | DQ3: =IF(DASHBOARD!$M$2-DASHBOARD!$M$1>=39,"Day "&40,"") | DT3: =IF(DASHBOARD!$M$2-DASHBOARD!$M$1>=40,"Day "&41,"") | DW3: =IF(DASHBOARD!$M$2-DASHBOARD!$M$1>=41,"Day "&42,"") | DZ3: =IF(DASHBOARD!$M$2-DASHBOARD!$M$1>=42,"Day "&43,"") | EC3: =IF(DASHBOARD!$M$2-DASHBOARD!$M$1>=43,"Day "&44,"") | EF3: =IF(DASHBOARD!$M$2-DASHBOARD!$M$1>=44,"Day "&45,"") | EI3: =IF(DASHBOARD!$M$2-DASHBOARD!$M$1>=45,"Day "&46,"") | EL3: =IF(DASHBOARD!$M$2-DASHBOARD!$M$1>=46,"Day "&47,"") | EO3: =IF(DASHBOARD!$M$2-DASHBOARD!$M$1>=47,"Day "&48,"") | ER3: =IF(DASHBOARD!$M$2-DASHBOARD!$M$1>=48,"Day "&49,"") | EU3: =IF(DASHBOARD!$M$2-DASHBOARD!$M$1>=49,"Day "&50,"")
D4: =IF(DASHBOARD!$M$2-DASHBOARD!$M$1>=0,DASHBOARD!$M$1+0,"") -> 46221 | G4: =IF(DASHBOARD!$M$2-DASHBOARD!$M$1>=1,DASHBOARD!$M$1+1,"") -> 46222 | J4: =IF(DASHBOARD!$M$2-DASHBOARD!$M$1>=2,DASHBOARD!$M$1+2,"") -> 46223 | M4: =IF(DASHBOARD!$M$2-DASHBOARD!$M$1>=3,DASHBOARD!$M$1+3,"") -> 46224 | P4: =IF(DASHBOARD!$M$2-DASHBOARD!$M$1>=4,DASHBOARD!$M$1+4,"") -> 46225 | S4: =IF(DASHBOARD!$M$2-DASHBOARD!$M$1>=5,DASHBOARD!$M$1+5,"") -> 46226 | V4: =IF(DASHBOARD!$M$2-DASHBOARD!$M$1>=6,DASHBOARD!$M$1+6,"") -> 46227 | Y4: =IF(DASHBOARD!$M$2-DASHBOARD!$M$1>=7,DASHBOARD!$M$1+7,"") -> 46228 | AB4: =IF(DASHBOARD!$M$2-DASHBOARD!$M$1>=8,DASHBOARD!$M$1+8,"") -> 46229 | AE4: =IF(DASHBOARD!$M$2-DASHBOARD!$M$1>=9,DASHBOARD!$M$1+9,"") -> 46230 | AH4: =IF(DASHBOARD!$M$2-DASHBOARD!$M$1>=10,DASHBOARD!$M$1+10,"") -> 46231 | AK4: =IF(DASHBOARD!$M$2-DASHBOARD!$M$1>=11,DASHBOARD!$M$1+11,"") -> 46232 | AN4: =IF(DASHBOARD!$M$2-DASHBOARD!$M$1>=12,DASHBOARD!$M$1+12,"") -> 46233 | AQ4: =IF(DASHBOARD!$M$2-DASHBOARD!$M$1>=13,DASHBOARD!$M$1+13,"") -> 46234 | AT4: =IF(DASHBOARD!$M$2-DASHBOARD!$M$1>=14,DASHBOARD!$M$1+14,"") -> 46235 | AW4: =IF(DASHBOARD!$M$2-DASHBOARD!$M$1>=15,DASHBOARD!$M$1+15,"") -> 46236 | AZ4: =IF(DASHBOARD!$M$2-DASHBOARD!$M$1>=16,DASHBOARD!$M$1+16,"") -> 46237 | BC4: =IF(DASHBOARD!$M$2-DASHBOARD!$M$1>=17,DASHBOARD!$M$1+17,"") -> 46238 | BF4: =IF(DASHBOARD!$M$2-DASHBOARD!$M$1>=18,DASHBOARD!$M$1+18,"") -> 46239 | BI4: =IF(DASHBOARD!$M$2-DASHBOARD!$M$1>=19,DASHBOARD!$M$1+19,"") -> 46240 | BL4: =IF(DASHBOARD!$M$2-DASHBOARD!$M$1>=20,DASHBOARD!$M$1+20,"") -> 46241 | BO4: =IF(DASHBOARD!$M$2-DASHBOARD!$M$1>=21,DASHBOARD!$M$1+21,"") -> 46242 | BR4: =IF(DASHBOARD!$M$2-DASHBOARD!$M$1>=22,DASHBOARD!$M$1+22,"") -> 46243 | BU4: =IF(DASHBOARD!$M$2-DASHBOARD!$M$1>=23,DASHBOARD!$M$1+23,"") -> 46244 | BX4: =IF(DASHBOARD!$M$2-DASHBOARD!$M$1>=24,DASHBOARD!$M$1+24,"") -> 46245 | CA4: =IF(DASHBOARD!$M$2-DASHBOARD!$M$1>=25,DASHBOARD!$M$1+25,"") -> 46246 | CD4: =IF(DASHBOARD!$M$2-DASHBOARD!$M$1>=26,DASHBOARD!$M$1+26,"") -> 46247 | CG4: =IF(DASHBOARD!$M$2-DASHBOARD!$M$1>=27,DASHBOARD!$M$1+27,"") -> 46248 | CJ4: =IF(DASHBOARD!$M$2-DASHBOARD!$M$1>=28,DASHBOARD!$M$1+28,"") -> 46249 | CM4: =IF(DASHBOARD!$M$2-DASHBOARD!$M$1>=29,DASHBOARD!$M$1+29,"") -> 46250 | CP4: =IF(DASHBOARD!$M$2-DASHBOARD!$M$1>=30,DASHBOARD!$M$1+30,"") -> 46251 | CS4: =IF(DASHBOARD!$M$2-DASHBOARD!$M$1>=31,DASHBOARD!$M$1+31,"") -> 46252 | CV4: =IF(DASHBOARD!$M$2-DASHBOARD!$M$1>=32,DASHBOARD!$M$1+32,"") -> 46253 | CY4: =IF(DASHBOARD!$M$2-DASHBOARD!$M$1>=33,DASHBOARD!$M$1+33,"") -> 46254 | DB4: =IF(DASHBOARD!$M$2-DASHBOARD!$M$1>=34,DASHBOARD!$M$1+34,"") -> 46255 | DE4: =IF(DASHBOARD!$M$2-DASHBOARD!$M$1>=35,DASHBOARD!$M$1+35,"") -> 46256 | DH4: =IF(DASHBOARD!$M$2-DASHBOARD!$M$1>=36,DASHBOARD!$M$1+36,"") -> 46257 | DK4: =IF(DASHBOARD!$M$2-DASHBOARD!$M$1>=37,DASHBOARD!$M$1+37,"") -> 46258 | DN4: =IF(DASHBOARD!$M$2-DASHBOARD!$M$1>=38,DASHBOARD!$M$1+38,"") | DQ4: =IF(DASHBOARD!$M$2-DASHBOARD!$M$1>=39,DASHBOARD!$M$1+39,"") | DT4: =IF(DASHBOARD!$M$2-DASHBOARD!$M$1>=40,DASHBOARD!$M$1+40,"") | DW4: =IF(DASHBOARD!$M$2-DASHBOARD!$M$1>=41,DASHBOARD!$M$1+41,"") | DZ4: =IF(DASHBOARD!$M$2-DASHBOARD!$M$1>=42,DASHBOARD!$M$1+42,"") | EC4: =IF(DASHBOARD!$M$2-DASHBOARD!$M$1>=43,DASHBOARD!$M$1+43,"") | EF4: =IF(DASHBOARD!$M$2-DASHBOARD!$M$1>=44,DASHBOARD!$M$1+44,"") | EI4: =IF(DASHBOARD!$M$2-DASHBOARD!$M$1>=45,DASHBOARD!$M$1+45,"") | EL4: =IF(DASHBOARD!$M$2-DASHBOARD!$M$1>=46,DASHBOARD!$M$1+46,"") | EO4: =IF(DASHBOARD!$M$2-DASHBOARD!$M$1>=47,DASHBOARD!$M$1+47,"") | ER4: =IF(DASHBOARD!$M$2-DASHBOARD!$M$1>=48,DASHBOARD!$M$1+48,"") | EU4: =IF(DASHBOARD!$M$2-DASHBOARD!$M$1>=49,DASHBOARD!$M$1+49,"")
D5: =IF(DASHBOARD!$M$2-DASHBOARD!$M$1>=0,"D","") -> D | E5: =IF(DASHBOARD!$M$2-DASHBOARD!$M$1>=0,"T","") -> T | F5: =IF(DASHBOARD!$M$2-DASHBOARD!$M$1>=0,"G","") -> G | G5: =IF(DASHBOARD!$M$2-DASHBOARD!$M$1>=1,"D","") -> D | H5: =IF(DASHBOARD!$M$2-DASHBOARD!$M$1>=1,"T","") -> T | I5: =IF(DASHBOARD!$M$2-DASHBOARD!$M$1>=1,"G","") -> G | J5: =IF(DASHBOARD!$M$2-DASHBOARD!$M$1>=2,"D","") -> D | K5: =IF(DASHBOARD!$M$2-DASHBOARD!$M$1>=2,"T","") -> T | L5: =IF(DASHBOARD!$M$2-DASHBOARD!$M$1>=2,"G","") -> G | M5: =IF(DASHBOARD!$M$2-DASHBOARD!$M$1>=3,"D","") -> D | N5: =IF(DASHBOARD!$M$2-DASHBOARD!$M$1>=3,"T","") -> T | O5: =IF(DASHBOARD!$M$2-DASHBOARD!$M$1>=3,"G","") -> G | P5: =IF(DASHBOARD!$M$2-DASHBOARD!$M$1>=4,"D","") -> D | Q5: =IF(DASHBOARD!$M$2-DASHBOARD!$M$1>=4,"T","") -> T | R5: =IF(DASHBOARD!$M$2-DASHBOARD!$M$1>=4,"G","") -> G | S5: =IF(DASHBOARD!$M$2-DASHBOARD!$M$1>=5,"D","") -> D | T5: =IF(DASHBOARD!$M$2-DASHBOARD!$M$1>=5,"T","") -> T | U5: =IF(DASHBOARD!$M$2-DASHBOARD!$M$1>=5,"G","") -> G | V5: =IF(DASHBOARD!$M$2-DASHBOARD!$M$1>=6,"D","") -> D | W5: =IF(DASHBOARD!$M$2-DASHBOARD!$M$1>=6,"T","") -> T | X5: =IF(DASHBOARD!$M$2-DASHBOARD!$M$1>=6,"G","") -> G | Y5: =IF(DASHBOARD!$M$2-DASHBOARD!$M$1>=7,"D","") -> D | Z5: =IF(DASHBOARD!$M$2-DASHBOARD!$M$1>=7,"T","") -> T | AA5: =IF(DASHBOARD!$M$2-DASHBOARD!$M$1>=7,"G","") -> G | AB5: =IF(DASHBOARD!$M$2-DASHBOARD!$M$1>=8,"D","") -> D | AC5: =IF(DASHBOARD!$M$2-DASHBOARD!$M$1>=8,"T","") -> T | AD5: =IF(DASHBOARD!$M$2-DASHBOARD!$M$1>=8,"G","") -> G | AE5: =IF(DASHBOARD!$M$2-DASHBOARD!$M$1>=9,"D","") -> D | AF5: =IF(DASHBOARD!$M$2-DASHBOARD!$M$1>=9,"T","") -> T | AG5: =IF(DASHBOARD!$M$2-DASHBOARD!$M$1>=9,"G","") -> G | AH5: =IF(DASHBOARD!$M$2-DASHBOARD!$M$1>=10,"D","") -> D | AI5: =IF(DASHBOARD!$M$2-DASHBOARD!$M$1>=10,"T","") -> T | AJ5: =IF(DASHBOARD!$M$2-DASHBOARD!$M$1>=10,"G","") -> G | AK5: =IF(DASHBOARD!$M$2-DASHBOARD!$M$1>=11,"D","") -> D | AL5: =IF(DASHBOARD!$M$2-DASHBOARD!$M$1>=11,"T","") -> T | AM5: =IF(DASHBOARD!$M$2-DASHBOARD!$M$1>=11,"G","") -> G | AN5: =IF(DASHBOARD!$M$2-DASHBOARD!$M$1>=12,"D","") -> D | AO5: =IF(DASHBOARD!$M$2-DASHBOARD!$M$1>=12,"T","") -> T | AP5: =IF(DASHBOARD!$M$2-DASHBOARD!$M$1>=12,"G","") -> G | AQ5: =IF(DASHBOARD!$M$2-DASHBOARD!$M$1>=13,"D","") -> D | AR5: =IF(DASHBOARD!$M$2-DASHBOARD!$M$1>=13,"T","") -> T | AS5: =IF(DASHBOARD!$M$2-DASHBOARD!$M$1>=13,"G","") -> G | AT5: =IF(DASHBOARD!$M$2-DASHBOARD!$M$1>=14,"D","") -> D | AU5: =IF(DASHBOARD!$M$2-DASHBOARD!$M$1>=14,"T","") -> T | AV5: =IF(DASHBOARD!$M$2-DASHBOARD!$M$1>=14,"G","") -> G | AW5: =IF(DASHBOARD!$M$2-DASHBOARD!$M$1>=15,"D","") -> D | AX5: =IF(DASHBOARD!$M$2-DASHBOARD!$M$1>=15,"T","") -> T | AY5: =IF(DASHBOARD!$M$2-DASHBOARD!$M$1>=15,"G","") -> G | AZ5: =IF(DASHBOARD!$M$2-DASHBOARD!$M$1>=16,"D","") -> D | BA5: =IF(DASHBOARD!$M$2-DASHBOARD!$M$1>=16,"T","") -> T | BB5: =IF(DASHBOARD!$M$2-DASHBOARD!$M$1>=16,"G","") -> G | BC5: =IF(DASHBOARD!$M$2-DASHBOARD!$M$1>=17,"D","") -> D | BD5: =IF(DASHBOARD!$M$2-DASHBOARD!$M$1>=17,"T","") -> T | BE5: =IF(DASHBOARD!$M$2-DASHBOARD!$M$1>=17,"G","") -> G | BF5: =IF(DASHBOARD!$M$2-DASHBOARD!$M$1>=18,"D","") -> D | BG5: =IF(DASHBOARD!$M$2-DASHBOARD!$M$1>=18,"T","") -> T | BH5: =IF(DASHBOARD!$M$2-DASHBOARD!$M$1>=18,"G","") -> G | BI5: =IF(DASHBOARD!$M$2-DASHBOARD!$M$1>=19,"D","") -> D | BJ5: =IF(DASHBOARD!$M$2-DASHBOARD!$M$1>=19,"T","") -> T | BK5: =IF(DASHBOARD!$M$2-DASHBOARD!$M$1>=19,"G","") -> G | BL5: =IF(DASHBOARD!$M$2-DASHBOARD!$M$1>=20,"D","") -> D | BM5: =IF(DASHBOARD!$M$2-DASHBOARD!$M$1>=20,"T","") -> T | BN5: =IF(DASHBOARD!$M$2-DASHBOARD!$M$1>=20,"G","") -> G | BO5: =IF(DASHBOARD!$M$2-DASHBOARD!$M$1>=21,"D","") -> D | BP5: =IF(DASHBOARD!$M$2-DASHBOARD!$M$1>=21,"T","") -> T | BQ5: =IF(DASHBOARD!$M$2-DASHBOARD!$M$1>=21,"G","") -> G | BR5: =IF(DASHBOARD!$M$2-DASHBOARD!$M$1>=22,"D","") -> D | BS5: =IF(DASHBOARD!$M$2-DASHBOARD!$M$1>=22,"T","") -> T | BT5: =IF(DASHBOARD!$M$2-DASHBOARD!$M$1>=22,"G","") -> G | BU5: =IF(DASHBOARD!$M$2-DASHBOARD!$M$1>=23,"D","") -> D | BV5: =IF(DASHBOARD!$M$2-DASHBOARD!$M$1>=23,"T","") -> T | BW5: =IF(DASHBOARD!$M$2-DASHBOARD!$M$1>=23,"G","") -> G | BX5: =IF(DASHBOARD!$M$2-DASHBOARD!$M$1>=24,"D","") -> D | BY5: =IF(DASHBOARD!$M$2-DASHBOARD!$M$1>=24,"T","") -> T | BZ5: =IF(DASHBOARD!$M$2-DASHBOARD!$M$1>=24,"G","") -> G | CA5: =IF(DASHBOARD!$M$2-DASHBOARD!$M$1>=25,"D","") -> D | CB5: =IF(DASHBOARD!$M$2-DASHBOARD!$M$1>=25,"T","") -> T | CC5: =IF(DASHBOARD!$M$2-DASHBOARD!$M$1>=25,"G","") -> G | CD5: =IF(DASHBOARD!$M$2-DASHBOARD!$M$1>=26,"D","") -> D | CE5: =IF(DASHBOARD!$M$2-DASHBOARD!$M$1>=26,"T","") -> T | CF5: =IF(DASHBOARD!$M$2-DASHBOARD!$M$1>=26,"G","") -> G | CG5: =IF(DASHBOARD!$M$2-DASHBOARD!$M$1>=27,"D","") -> D | CH5: =IF(DASHBOARD!$M$2-DASHBOARD!$M$1>=27,"T","") -> T | CI5: =IF(DASHBOARD!$M$2-DASHBOARD!$M$1>=27,"G","") -> G | CJ5: =IF(DASHBOARD!$M$2-DASHBOARD!$M$1>=28,"D","") -> D | CK5: =IF(DASHBOARD!$M$2-DASHBOARD!$M$1>=28,"T","") -> T | CL5: =IF(DASHBOARD!$M$2-DASHBOARD!$M$1>=28,"G","") -> G | CM5: =IF(DASHBOARD!$M$2-DASHBOARD!$M$1>=29,"D","") -> D | CN5: =IF(DASHBOARD!$M$2-DASHBOARD!$M$1>=29,"T","") -> T | CO5: =IF(DASHBOARD!$M$2-DASHBOARD!$M$1>=29,"G","") -> G | CP5: =IF(DASHBOARD!$M$2-DASHBOARD!$M$1>=30,"D","") -> D | CQ5: =IF(DASHBOARD!$M$2-DASHBOARD!$M$1>=30,"T","") -> T | CR5: =IF(DASHBOARD!$M$2-DASHBOARD!$M$1>=30,"G","") -> G | CS5: =IF(DASHBOARD!$M$2-DASHBOARD!$M$1>=31,"D","") -> D | CT5: =IF(DASHBOARD!$M$2-DASHBOARD!$M$1>=31,"T","") -> T | CU5: =IF(DASHBOARD!$M$2-DASHBOARD!$M$1>=31,"G","") -> G | CV5: =IF(DASHBOARD!$M$2-DASHBOARD!$M$1>=32,"D","") -> D | CW5: =IF(DASHBOARD!$M$2-DASHBOARD!$M$1>=32,"T","") -> T | CX5: =IF(DASHBOARD!$M$2-DASHBOARD!$M$1>=32,"G","") -> G | CY5: =IF(DASHBOARD!$M$2-DASHBOARD!$M$1>=33,"D","") -> D | CZ5: =IF(DASHBOARD!$M$2-DASHBOARD!$M$1>=33,"T","") -> T | DA5: =IF(DASHBOARD!$M$2-DASHBOARD!$M$1>=33,"G","") -> G | DB5: =IF(DASHBOARD!$M$2-DASHBOARD!$M$1>=34,"D","") -> D | DC5: =IF(DASHBOARD!$M$2-DASHBOARD!$M$1>=34,"T","") -> T | DD5: =IF(DASHBOARD!$M$2-DASHBOARD!$M$1>=34,"G","") -> G | DE5: =IF(DASHBOARD!$M$2-DASHBOARD!$M$1>=35,"D","") -> D | DF5: =IF(DASHBOARD!$M$2-DASHBOARD!$M$1>=35,"T","") -> T | DG5: =IF(DASHBOARD!$M$2-DASHBOARD!$M$1>=35,"G","") -> G | DH5: =IF(DASHBOARD!$M$2-DASHBOARD!$M$1>=36,"D","") -> D | DI5: =IF(DASHBOARD!$M$2-DASHBOARD!$M$1>=36,"T","") -> T | DJ5: =IF(DASHBOARD!$M$2-DASHBOARD!$M$1>=36,"G","") -> G | DK5: =IF(DASHBOARD!$M$2-DASHBOARD!$M$1>=37,"D","") -> D | DL5: =IF(DASHBOARD!$M$2-DASHBOARD!$M$1>=37,"T","") -> T | DM5: =IF(DASHBOARD!$M$2-DASHBOARD!$M$1>=37,"G","") -> G | DN5: =IF(DASHBOARD!$M$2-DASHBOARD!$M$1>=38,"D","") | DO5: =IF(DASHBOARD!$M$2-DASHBOARD!$M$1>=38,"T","") | DP5: =IF(DASHBOARD!$M$2-DASHBOARD!$M$1>=38,"G","") | DQ5: =IF(DASHBOARD!$M$2-DASHBOARD!$M$1>=39,"D","") | DR5: =IF(DASHBOARD!$M$2-DASHBOARD!$M$1>=39,"T","") | DS5: =IF(DASHBOARD!$M$2-DASHBOARD!$M$1>=39,"G","") | DT5: =IF(DASHBOARD!$M$2-DASHBOARD!$M$1>=40,"D","") | DU5: =IF(DASHBOARD!$M$2-DASHBOARD!$M$1>=40,"T","") | DV5: =IF(DASHBOARD!$M$2-DASHBOARD!$M$1>=40,"G","") | DW5: =IF(DASHBOARD!$M$2-DASHBOARD!$M$1>=41,"D","") | DX5: =IF(DASHBOARD!$M$2-DASHBOARD!$M$1>=41,"T","") | DY5: =IF(DASHBOARD!$M$2-DASHBOARD!$M$1>=41,"G","") | DZ5: =IF(DASHBOARD!$M$2-DASHBOARD!$M$1>=42,"D","") | EA5: =IF(DASHBOARD!$M$2-DASHBOARD!$M$1>=42,"T","") | EB5: =IF(DASHBOARD!$M$2-DASHBOARD!$M$1>=42,"G","") | EC5: =IF(DASHBOARD!$M$2-DASHBOARD!$M$1>=43,"D","") | ED5: =IF(DASHBOARD!$M$2-DASHBOARD!$M$1>=43,"T","") | EE5: =IF(DASHBOARD!$M$2-DASHBOARD!$M$1>=43,"G","") | EF5: =IF(DASHBOARD!$M$2-DASHBOARD!$M$1>=44,"D","") | EG5: =IF(DASHBOARD!$M$2-DASHBOARD!$M$1>=44,"T","") | EH5: =IF(DASHBOARD!$M$2-DASHBOARD!$M$1>=44,"G","") | EI5: =IF(DASHBOARD!$M$2-DASHBOARD!$M$1>=45,"D","") | EJ5: =IF(DASHBOARD!$M$2-DASHBOARD!$M$1>=45,"T","") | EK5: =IF(DASHBOARD!$M$2-DASHBOARD!$M$1>=45,"G","") | EL5: =IF(DASHBOARD!$M$2-DASHBOARD!$M$1>=46,"D","") | EM5: =IF(DASHBOARD!$M$2-DASHBOARD!$M$1>=46,"T","") | EN5: =IF(DASHBOARD!$M$2-DASHBOARD!$M$1>=46,"G","") | EO5: =IF(DASHBOARD!$M$2-DASHBOARD!$M$1>=47,"D","") | EP5: =IF(DASHBOARD!$M$2-DASHBOARD!$M$1>=47,"T","") | EQ5: =IF(DASHBOARD!$M$2-DASHBOARD!$M$1>=47,"G","") | ER5: =IF(DASHBOARD!$M$2-DASHBOARD!$M$1>=48,"D","") | ES5: =IF(DASHBOARD!$M$2-DASHBOARD!$M$1>=48,"T","") | ET5: =IF(DASHBOARD!$M$2-DASHBOARD!$M$1>=48,"G","") | EU5: =IF(DASHBOARD!$M$2-DASHBOARD!$M$1>=49,"D","") | EV5: =IF(DASHBOARD!$M$2-DASHBOARD!$M$1>=49,"T","") | EW5: =IF(DASHBOARD!$M$2-DASHBOARD!$M$1>=49,"G","")
A6: PHASE 1 (Pre Hangar)
A7: Aircraft Arrival | B7: 46221.958
A8: Heavy Wash | B8: 46222.25
A9: Both ENG Preservation | B9: 46221.583
A10: Pre HGR | B10: 46222.583 | C10: 46224 | M10: 21-Jul
A11: Pre Insp | B11: 46222.583 | C11: 46224 | M11: 21-Jul
A12: Defuel | B12: 46225 | P12: 22-Jul
A13: PHASE 2 (Inspection)
A14: Nose Jacking – Prox Sensor Check | B14: 46239 | BF14: 46239
A15: Open-Up | B15: 46224 | C15: 46229 | AB15: 26-Jul
A16: Joint Cards Insp | B16: 46224 | C16: 46237 | AZ16: 3-Aug
A17: Jacking – Free Fall Func Chk & NLG | B17: 46239 | C17: 46239 | BF17: 5-Aug
A18: Power Off | B18: 46229 | C18: 46236 | AW18: 2-Aug
A19: FINDING CUT-OFF | B19: 46238 | D19: =IF((DASHBOARD!$M$1+INT((COLUMN()-4)/3))=INT($B$19),"◆ "&TEXT($B$19,"D-MMM"),"") | G19: =IF((DASHBOARD!$M$1+INT((COLUMN()-4)/3))=INT($B$19),"◆ "&TEXT($B$19,"D-MMM"),"") | J19: =IF((DASHBOARD!$M$1+INT((COLUMN()-4)/3))=INT($B$19),"◆ "&TEXT($B$19,"D-MMM"),"") | M19: =IF((DASHBOARD!$M$1+INT((COLUMN()-4)/3))=INT($B$19),"◆ "&TEXT($B$19,"D-MMM"),"") | P19: =IF((DASHBOARD!$M$1+INT((COLUMN()-4)/3))=INT($B$19),"◆ "&TEXT($B$19,"D-MMM"),"") | S19: =IF((DASHBOARD!$M$1+INT((COLUMN()-4)/3))=INT($B$19),"◆ "&TEXT($B$19,"D-MMM"),"") | V19: =IF((DASHBOARD!$M$1+INT((COLUMN()-4)/3))=INT($B$19),"◆ "&TEXT($B$19,"D-MMM"),"") | Y19: =IF((DASHBOARD!$M$1+INT((COLUMN()-4)/3))=INT($B$19),"◆ "&TEXT($B$19,"D-MMM"),"") | AB19: =IF((DASHBOARD!$M$1+INT((COLUMN()-4)/3))=INT($B$19),"◆ "&TEXT($B$19,"D-MMM"),"") | AE19: =IF((DASHBOARD!$M$1+INT((COLUMN()-4)/3))=INT($B$19),"◆ "&TEXT($B$19,"D-MMM"),"") | AH19: =IF((DASHBOARD!$M$1+INT((COLUMN()-4)/3))=INT($B$19),"◆ "&TEXT($B$19,"D-MMM"),"") | AK19: =IF((DASHBOARD!$M$1+INT((COLUMN()-4)/3))=INT($B$19),"◆ "&TEXT($B$19,"D-MMM"),"") | AN19: =IF((DASHBOARD!$M$1+INT((COLUMN()-4)/3))=INT($B$19),"◆ "&TEXT($B$19,"D-MMM"),"") | AQ19: =IF((DASHBOARD!$M$1+INT((COLUMN()-4)/3))=INT($B$19),"◆ "&TEXT($B$19,"D-MMM"),"") | AT19: =IF((DASHBOARD!$M$1+INT((COLUMN()-4)/3))=INT($B$19),"◆ "&TEXT($B$19,"D-MMM"),"") | AW19: =IF((DASHBOARD!$M$1+INT((COLUMN()-4)/3))=INT($B$19),"◆ "&TEXT($B$19,"D-MMM"),"") | AZ19: =IF((DASHBOARD!$M$1+INT((COLUMN()-4)/3))=INT($B$19),"◆ "&TEXT($B$19,"D-MMM"),"") | BC19: =IF((DASHBOARD!$M$1+INT((COLUMN()-4)/3))=INT($B$19),"◆ "&TEXT($B$19,"D-MMM"),"") -> ◆ 4-Aug | BF19: =IF((DASHBOARD!$M$1+INT((COLUMN()-4)/3))=INT($B$19),"◆ "&TEXT($B$19,"D-MMM"),"") | BI19: =IF((DASHBOARD!$M$1+INT((COLUMN()-4)/3))=INT($B$19),"◆ "&TEXT($B$19,"D-MMM"),"") | BL19: =IF((DASHBOARD!$M$1+INT((COLUMN()-4)/3))=INT($B$19),"◆ "&TEXT($B$19,"D-MMM"),"") | BO19: =IF((DASHBOARD!$M$1+INT((COLUMN()-4)/3))=INT($B$19),"◆ "&TEXT($B$19,"D-MMM"),"") | BR19: =IF((DASHBOARD!$M$1+INT((COLUMN()-4)/3))=INT($B$19),"◆ "&TEXT($B$19,"D-MMM"),"") | BU19: =IF((DASHBOARD!$M$1+INT((COLUMN()-4)/3))=INT($B$19),"◆ "&TEXT($B$19,"D-MMM"),"") | BX19: =IF((DASHBOARD!$M$1+INT((COLUMN()-4)/3))=INT($B$19),"◆ "&TEXT($B$19,"D-MMM"),"") | CA19: =IF((DASHBOARD!$M$1+INT((COLUMN()-4)/3))=INT($B$19),"◆ "&TEXT($B$19,"D-MMM"),"") | CD19: =IF((DASHBOARD!$M$1+INT((COLUMN()-4)/3))=INT($B$19),"◆ "&TEXT($B$19,"D-MMM"),"") | CG19: =IF((DASHBOARD!$M$1+INT((COLUMN()-4)/3))=INT($B$19),"◆ "&TEXT($B$19,"D-MMM"),"") | CJ19: =IF((DASHBOARD!$M$1+INT((COLUMN()-4)/3))=INT($B$19),"◆ "&TEXT($B$19,"D-MMM"),"") | CM19: =IF((DASHBOARD!$M$1+INT((COLUMN()-4)/3))=INT($B$19),"◆ "&TEXT($B$19,"D-MMM"),"") | CP19: =IF((DASHBOARD!$M$1+INT((COLUMN()-4)/3))=INT($B$19),"◆ "&TEXT($B$19,"D-MMM"),"") | CS19: =IF((DASHBOARD!$M$1+INT((COLUMN()-4)/3))=INT($B$19),"◆ "&TEXT($B$19,"D-MMM"),"") | CV19: =IF((DASHBOARD!$M$1+INT((COLUMN()-4)/3))=INT($B$19),"◆ "&TEXT($B$19,"D-MMM"),"") | CY19: =IF((DASHBOARD!$M$1+INT((COLUMN()-4)/3))=INT($B$19),"◆ "&TEXT($B$19,"D-MMM"),"") | DB19: =IF((DASHBOARD!$M$1+INT((COLUMN()-4)/3))=INT($B$19),"◆ "&TEXT($B$19,"D-MMM"),"") | DE19: =IF((DASHBOARD!$M$1+INT((COLUMN()-4)/3))=INT($B$19),"◆ "&TEXT($B$19,"D-MMM"),"") | DH19: =IF((DASHBOARD!$M$1+INT((COLUMN()-4)/3))=INT($B$19),"◆ "&TEXT($B$19,"D-MMM"),"") | DK19: =IF((DASHBOARD!$M$1+INT((COLUMN()-4)/3))=INT($B$19),"◆ "&TEXT($B$19,"D-MMM"),"") | DN19: =IF((DASHBOARD!$M$1+INT((COLUMN()-4)/3))=INT($B$19),"◆ "&TEXT($B$19,"D-MMM"),"") | DQ19: =IF((DASHBOARD!$M$1+INT((COLUMN()-4)/3))=INT($B$19),"◆ "&TEXT($B$19,"D-MMM"),"") | DT19: =IF((DASHBOARD!$M$1+INT((COLUMN()-4)/3))=INT($B$19),"◆ "&TEXT($B$19,"D-MMM"),"") | DW19: =IF((DASHBOARD!$M$1+INT((COLUMN()-4)/3))=INT($B$19),"◆ "&TEXT($B$19,"D-MMM"),"") | DZ19: =IF((DASHBOARD!$M$1+INT((COLUMN()-4)/3))=INT($B$19),"◆ "&TEXT($B$19,"D-MMM"),"") | EC19: =IF((DASHBOARD!$M$1+INT((COLUMN()-4)/3))=INT($B$19),"◆ "&TEXT($B$19,"D-MMM"),"") | EF19: =IF((DASHBOARD!$M$1+INT((COLUMN()-4)/3))=INT($B$19),"◆ "&TEXT($B$19,"D-MMM"),"") | EI19: =IF((DASHBOARD!$M$1+INT((COLUMN()-4)/3))=INT($B$19),"◆ "&TEXT($B$19,"D-MMM"),"") | EL19: =IF((DASHBOARD!$M$1+INT((COLUMN()-4)/3))=INT($B$19),"◆ "&TEXT($B$19,"D-MMM"),"") | EO19: =IF((DASHBOARD!$M$1+INT((COLUMN()-4)/3))=INT($B$19),"◆ "&TEXT($B$19,"D-MMM"),"") | ER19: =IF((DASHBOARD!$M$1+INT((COLUMN()-4)/3))=INT($B$19),"◆ "&TEXT($B$19,"D-MMM"),"") | EU19: =IF((DASHBOARD!$M$1+INT((COLUMN()-4)/3))=INT($B$19),"◆ "&TEXT($B$19,"D-MMM"),"")
A20: PHASE 3 (Modification & Rectification)
A21: Findings & Rectification | B21: 46221.958 | C21: 46253 | CV21: 19-Aug
A22: Engineering Orders Doc (EOD's / ER's) | B22: 46228 | C22: 46242 | BO22: 8-Aug
A23: FOMAX & Eclipse Connectivity Mods | B23: 46229 | C23: 46239 | BF23: 5-Aug
