Workbook

Sheet ASF Tracker
A1: POOL CABIN ✈ HZ-ASF ✈ C7-CHECK WORK PACKAGE TRACKER | E1: ="Day "&TEXT(MAX(1,MIN(TODAY()-DATE(2026,6,8)+1,36)),"0")&"/36" -> Day 24/36 | G1: ="✅ "&COUNTIFS(B4:B1002,"<>",E4:E1002,"Closed")&" / "&COUNTIF(B4:B1002,"<>")&" Closed ("&TEXT(IFERROR(COUNTIFS(B4:B1002,"<>",E4:E1002,"Closed")/COUNTIF(B4:B1002,"<>"),0),"0%")&")" -> ✅ 192 / 376 Closed (51%)
A2: UPDATED: 30 MAY -- DAY SHIFT | G2: ="AOG/Critical: "&COUNTIFS(B4:B1002,"<>",F4:F1002,"AOG")+COUNTIFS(B4:B1002,"<>",F4:F1002,"Critical") -> AOG/Critical: 4
A3: Seq. No. | B3: WO / Event Number | C3: Task Description | D3: Category | E3: Status | F3: Priority | G3: Specialty | H3: PARTS REQ. | I3: Remarks | J3: Time EVAL? | K3: AREA
A4: 1 | B4: 31956294 | C4: C_N (C_N07)/C-CHECK | D4: TASK CARD | E4: Open | F4: Normal | G4: AP | J4: N/A | K4: N/A
A5: 2 | B5: 05-00-00-05-SVA | C5: 05-00-00-05-SVA (03) / FINAL PRODUCT QUALITY INSPECTION | D5: TASK CARD | E5: Open | F5: Normal | G5: INSP | J5: N/A | K5: N/A
A6: 3 | B6: 08-10-00-01-0-A | C6: 08-10-00-01-0-A (01) / WIGHT & BALANCE | D6: TASK CARD | E6: Open | F6: Normal | G6: AP | J6: N/A | K6: N/A
A7: 24 | B7: 25-11-00-03-0-SVA-001 | C7: 25-11-00-03-0-SVA-001 (02) / THIRD OCCUPANT SEAT BOTTOM CUSHION REPLACMENT | D7: TASK CARD | E7: Open | F7: Normal | G7: CAB | H7: Requested | I7: AFTER COCKPIT CLOSE UP | J7: N/A | K7: FWD
A8: 25 | B8: 25-11-00-08-0-SVA | C8: 25-11-00-08-0-SVA (02) / CAPTAIN AND F/O SEATS BOTTOM REPLACMENT | D8: TASK CARD | E8: Open | F8: Normal | G8: CAB | H8: Requested | I8: AFTER COCKPIT CLOSE UP | J8: N/A | K8: FWD
A9: 26 | B9: 25-11-00-09-0-SVA | C9: 25-11-00-09-0-SVA (03) / CAPTAIN & F/O SEATS COVERS REPLACMENT | D9: TASK CARD | E9: Open | F9: Normal | G9: CAB | H9: Requested | I9: AFTER COCKPIT CLOSE UP | J9: N/A | K9: FWD
A10: 27 | B10: 25-11-00-17-0-SVA-002 | C10: 25-11-00-17-0-SVA-002 (02) / FOURTH OCCUPANT SEAT BOTTOM CUSHION REPLACMENT | D10: TASK CARD | E10: Open | F10: Normal | G10: CAB | H10: Requested | I10: AFTER COCKPIT CLOSE UP | J10: N/A | K10: FWD
A11: 28 | B11: 25-28-00-04-0-SVA-001 | C11: 25-28-00-04-0-SVA-001 (03) / A320(HZ-ASA TO ASG) CARPETS&MATS R/R | D11: TASK CARD | E11: Open | F11: Normal | G11: CAB | H11: Requested | I11: P/S 4467509 | J11: N/A | K11: JOINT
A12: 29 | B12: 25-28-00-04-0-SVA-002 | C12: 25-28-00-04-0-SVA-002 (03) / COCKPIT COMPARTMENT CARPETS REPLCMNT | D12: TASK CARD | E12: Open | F12: Normal | G12: CAB | H12: Requested | I12: P/S 4467511 | J12: N/A | K12: FWD
A13: 30 | B13: 25-SVA-01 | C13: 25-SVA-01 (00) / COCKPIT CHECK | D13: TASK CARD | E13: Open | F13: Normal | G13: CAB | J13: N/A | K13: FWD
A14: 31 | B14: 25-SVA-02 | C14: 25-SVA-02 (00) / GENERAL CABIN ITEMS C-CHK | D14: TASK CARD | E14: Closed | F14: Normal | G14: CAB | J14: N/A | K14: JOINT
A15: 32 | B15: 25-SVA-05 | C15: 25-SVA-05 (00) / G/C SEAT REFRESH | D15: TASK CARD | E15: Open | F15: Normal | G15: SEAT | J15: N/A
A16: 33 | B16: 25-SVA-06 | C16: 25-SVA-06 (00) / GALLEY REFRESH | D16: TASK CARD | E16: Closed | F16: Normal | G16: CAB | J16: N/A | K16: JOINT
A17: 34 | B17: 25-SVA-07 | C17: 25-SVA-07 (00) / LAV REFRESH | D17: TASK CARD | E17: Closed | F17: Normal | G17: CAB | J17: N/A | K17: JOINT
A18: 39 | B18: 254000-04-2 | C18: 254000-04-2 (03) / LAVATORIES FLOOR PANELS INSPECTION | D18: TASK CARD | E18: Closed | F18: Normal | G18: JOINT | J18: N/A
A19: 42 | B19: 256652-01-1-SVA | C19: 256652-01-1-SVA (01) / LIFE VEST RESTORATION PERIODIC CHECK FOR EXPIRATION | D19: TASK CARD | E19: Open | F19: Normal | G19: JOINT | I19: F/A seat to be installed | J19: N/A
A20: 47 | B20: 262541-04-1 | C20: 262541-04-1 (02) / LAVATORY FIRE EXTG PRESS READING CHK | D20: TASK CARD | E20: Closed | F20: Normal | G20: JOINT | J20: N/A
A21: 112 | B21: 351000-01-1 | C21: 351000-01-1 (02) / FULL FACE/QUICK OXYGEN MASKS OPC | D21: TASK CARD | E21: Closed | F21: Normal | G21: JOINT | J21: N/A
A22: 113 | B22: 351241-01-1 | C22: 351241-01-1 (02) / CREW OXYGEN MASKS INSPECTION | D22: TASK CARD | E22: Closed | F22: Normal | G22: JOINT | J22: N/A
A23: 114 | B23: 352142-01-1-SVA | C23: 352142-01-1-SVA (01) / VALIDITY CHECK OF CHEMICAL OXYGEN GENERATORS | D23: TASK CARD | E23: Open | F23: Normal | G23: JOINT | I23: AFTER OXY CLOSE UP | J23: N/A
A24: 115 | B24: 353000-06-1-SVA | C24: 353000-06-1-SVA (03) / COCKPIT (PBE) INSPECTION | D24: TASK CARD | E24: Closed | F24: Normal | G24: JOINT | J24: N/A
A25: 116 | B25: 353000-07-1 | C25: 353000-07-1 (03) / PORTABLE OXYGEN MASKS INSPECTION | D25: TASK CARD | E25: Closed | F25: Normal | G25: JOINT | J25: N/A
A26: 123 | B26: 383100-07-1 | C26: 383100-07-1 (06) / VACUUM TOILET SYSTEM CLEANING | D26: TASK CARD | E26: Closed | F26: Normal | G26: AP | J26: N/A
A27: 127 | B27: 521000-01-SVA | C27: 521000-01-SVA (01) / FWD LH PASSENGER/CREW DOOR DAMPER AND EMERGENCY OPERATION CYLINDER DIAPHRAGM REPLACEMENT | D27: TASK CARD | E27: Closed | F27: Normal | G27: CAB | J27: N/A | K27: FWD
A28: 128 | B28: 521000-02-1 | C28: 521000-02-1 (02) / PASSENGER/CREW DOOR SUSPENSION CHK | D28: TASK CARD | E28: Closed | F28: Normal | G28: JOINT | J28: N/A | K28: JOINT
A29: 129 | B29: 521000-02-SVA | C29: 521000-02-SVA (01) / FWD RH PASSENGER/CREW DOOR DAMPER AND EMERGENCY OPERATION CYLINDER DIAPHRAGM REPLACEMENT | D29: TASK CARD | E29: Closed | F29: Normal | G29: CAB | J29: N/A | K29: FWD
A30: 130 | B30: 521000-03-SVA | C30: 521000-03-SVA (01) / AFT LH PASSENGER/CREW DOOR DAMPER AND EMERGENCY OPERATION CYLINDER DIAPHRAGM REPLACEMENT | D30: TASK CARD | E30: Closed | F30: Normal | G30: CAB | J30: N/A | K30: AFT
A31: 131 | B31: 521000-04-1-001 | C31: 521000-04-1-001 (02) / L/H FWD PAX/CREW DOOR INTEGRITY CHK | D31: TASK CARD | E31: Closed | F31: Normal | G31: JOINT | J31: N/A | K31: FWD
A32: 132 | B32: 521000-04-1-002 | C32: 521000-04-1-002 (02) / R/H FWD PAX/CREW DOOR INTEGRITY CHK | D32: TASK CARD | E32: Closed | F32: Normal | G32: JOINT | J32: N/A | K32: FWD
A33: 133 | B33: 521000-04-1-003 | C33: 521000-04-1-003 (02) / L/H AFT PAX/CREW DOOR INTEGRITY CHK | D33: TASK CARD | E33: Closed | F33: Normal | G33: JOINT | J33: N/A | K33: AFT
A34: 134 | B34: 521000-04-1-004 | C34: 521000-04-1-004 (02) / R/H AFT PAX/CREW DOOR INTEGRITY CHK | D34: TASK CARD | E34: Closed | F34: Normal | G34: JOINT | J34: N/A | K34: AFT
A35: 135 | B35: 521000-04-SVA | C35: 521000-04-SVA (01) / AFT RH PASSENGER/CREW DOOR DAMPER AND EMERGENCY OPERATION CYLINDER DIAPHRAGM REPLACEMENT | D35: TASK CARD | E35: Closed | F35: Normal | G35: CAB | J35: N/A | K35: AFT
A36: 136 | B36: 521121-02-1 | C36: 521121-02-1 (03) / PASSENGER/CREW DOORS LUBRICATION | D36: TASK CARD | E36: Closed | F36: Normal | G36: CAB | J36: N/A | K36: JOINT
A37: 139 | B37: 527100-01-1 | C37: 527100-01-1 (5) / DOOR WARNING SYSTEM OPERATIONAL TEST | D37: TASK CARD | E37: Open | F37: Normal | G37: AV | J37: N/A
A38: 140 | B38: 527300-01-1 | C38: 527300-01-1 (03) / EMERGENCY ESCAPE SLIDE WARNING SYS | D38: TASK CARD | E38: Closed | F38: Normal | G38: AV | J38: N/A
A39: 141 | B39: 531151-02-1 | C39: 531151-02-1 (00) / DETAILED INSPECTION OF DOOR STOP FITTINGS PROTRUDING PART NOT COVERED BY THE LINING ON FRAME 16 AND FRAME 20, LH/RH. | D39: TASK CARD | E39: Closed | F39: Normal | G39: JOINT | J39: N/A
A40: 162 | B40: 561200-02-1 | C40: 561200-02-1 (01) / COCKPIT SLIDING WINDOW LUBRICATION | D40: TASK CARD | E40: Closed | F40: Normal | G40: CAB | J40: N/A | K40: FWD
...

Sheet DASHBOARD
A1: 📊 ASF C3-CHECK — WORK PACKAGE DASHBOARD | I1: ="Day "&TEXT(MAX(1,MIN(TODAY()-DATE(2026,6,8)+1,36)),"0")&"/36" -> Day 24/36
A2: All figures update automatically from ASF Tracker
A3: STATUS OVERVIEW
B5: Total Items/WOs | C5: =COUNTIF('ASF Tracker'!B4:B1002,"<>") -> 376 | E5: Closed | F5: =COUNTIFS('ASF Tracker'!B4:B1002,"<>",'ASF Tracker'!E4:E1002,"Closed") -> 192 | H5: Completion | I5: =TEXT(IFERROR(COUNTIFS('ASF Tracker'!B4:B1002,"<>",'ASF Tracker'!E4:E1002,"Closed")/COUNTIF('ASF Tracker'!B4:B1002,"<>"),0),"0%") -> 51%
B7: Open | C7: =COUNTIFS('ASF Tracker'!B4:B1002,"<>",'ASF Tracker'!E4:E1002,"Open") -> 156 | E7: In Progress | F7: =COUNTIFS('ASF Tracker'!B4:B1002,"<>",'ASF Tracker'!E4:E1002,"In Progress") -> 28 | H7: Deferred / Hold | I7: =COUNTIFS('ASF Tracker'!B4:B1002,"<>",'ASF Tracker'!E4:E1002,"Deferred")+COUNTIFS('ASF Tracker'!B4:B1002,"<>",'ASF Tracker'!E4:E1002,"On Hold") -> 0
A9: PRIORITY ALERTS
B11: AOG | C11: =COUNTIFS('ASF Tracker'!B4:B1002,"<>",'ASF Tracker'!F4:F1002,"AOG") -> 4 | E11: Critical | F11: =COUNTIFS('ASF Tracker'!B4:B1002,"<>",'ASF Tracker'!F4:F1002,"Critical") -> 0 | H11: High | I11: =COUNTIFS('ASF Tracker'!B4:B1002,"<>",'ASF Tracker'!F4:F1002,"High") -> 0
A13: PARTS REQUIREMENTS (count of WOs with each status)
B15: Requested | C15: =COUNTIFS('ASF Tracker'!B4:B1002,"<>",'ASF Tracker'!H4:H1002,"Requested") -> 111 | E15: Requested – CR | F15: =COUNTIFS('ASF Tracker'!B4:B1002,"<>",'ASF Tracker'!H4:H1002,"Requested - CR") -> 3 | H15: Requested – R | I15: =COUNTIFS('ASF Tracker'!B4:B1002,"<>",'ASF Tracker'!H4:H1002,"Requested - R") -> 30
B17: Pending - Require Evaluation | C17: =COUNTIFS('ASF Tracker'!B4:B1002,"<>",'ASF Tracker'!H4:H1002,"Pending EVAL") -> 0 | E17: N/R (not required) | F17: =COUNTIFS('ASF Tracker'!B4:B1002,"<>",'ASF Tracker'!H4:H1002,"N/R") -> 15 | H17: N/A (Not available) | I17: =COUNTIFS('ASF Tracker'!B4:B1002,"<>",'ASF Tracker'!H4:H1002,"N/A") -> 0
A19: BY CATEGORY
B21: TASK CARD | C21: =IFERROR(COUNTIFS('ASF Tracker'!$B$4:$B$1002,"<>",'ASF Tracker'!$D$4:$D$1002,"TASK CARD",'ASF Tracker'!$E$4:$E$1002,"Closed")&" / "&COUNTIFS('ASF Tracker'!$B$4:$B$1002,"<>",'ASF Tracker'!$D$4:$D$1002,"TASK CARD"),"-") -> 60 / 126 | E21: LAVATORY | F21: =IFERROR(COUNTIFS('ASF Tracker'!$B$4:$B$1002,"<>",'ASF Tracker'!$D$4:$D$1002,"LAVATORY",'ASF Tracker'!$E$4:$E$1002,"Closed")&" / "&COUNTIFS('ASF Tracker'!$B$4:$B$1002,"<>",'ASF Tracker'!$D$4:$D$1002,"LAVATORY"),"-") -> 20 / 35 | H21: GALLEY | I21: =IFERROR(COUNTIFS('ASF Tracker'!$B$4:$B$1002,"<>",'ASF Tracker'!$D$4:$D$1002,"GALLEY",'ASF Tracker'!$E$4:$E$1002,"Closed")&" / "&COUNTIFS('ASF Tracker'!$B$4:$B$1002,"<>",'ASF Tracker'!$D$4:$D$1002,"GALLEY"),"-") -> 31 / 39
B22: =IFERROR("Completion: "&TEXT(COUNTIFS('ASF Tracker'!$B$4:$B$1002,"<>",'ASF Tracker'!$D$4:$D$1002,"TASK CARD",'ASF Tracker'!$E$4:$E$1002,"Closed")/COUNTIFS('ASF Tracker'!$B$4:$B$1002,"<>",'ASF Tracker'!$D$4:$D$1002,"TASK CARD"),"0%"),"-") -> Completion: 48% | E22: =IFERROR("Completion: "&TEXT(COUNTIFS('ASF Tracker'!$B$4:$B$1002,"<>",'ASF Tracker'!$D$4:$D$1002,"LAVATORY",'ASF Tracker'!$E$4:$E$1002,"Closed")/COUNTIFS('ASF Tracker'!$B$4:$B$1002,"<>",'ASF Tracker'!$D$4:$D$1002,"LAVATORY"),"0%"),"-") -> Completion: 57% | H22: =IFERROR("Completion: "&TEXT(COUNTIFS('ASF Tracker'!$B$4:$B$1002,"<>",'ASF Tracker'!$D$4:$D$1002,"GALLEY",'ASF Tracker'!$E$4:$E$1002,"Closed")/COUNTIFS('ASF Tracker'!$B$4:$B$1002,"<>",'ASF Tracker'!$D$4:$D$1002,"GALLEY"),"0%"),"-") -> Completion: 79%
B24: GENERAL CABIN | C24: =IFERROR(COUNTIFS('ASF Tracker'!$D$4:$D$1002,"GENERAL CABIN",'ASF Tracker'!$E$4:$E$1002,"Closed",'ASF Tracker'!$B$4:$B$1002,"<>")&" / "&COUNTIFS('ASF Tracker'!$D$4:$D$1002,"GENERAL CABIN",'ASF Tracker'!$B$4:$B$1002,"<>"),"-") -> 34 / 72 | E24: TEDLAR/SIDEWALL | F24: =IFERROR(COUNTIFS('ASF Tracker'!$B$4:$B$1002,"<>",'ASF Tracker'!$D$4:$D$1002,"TEDLAR/SIDEWALL",'ASF Tracker'!$E$4:$E$1002,"Closed")&" / "&COUNTIFS('ASF Tracker'!$B$4:$B$1002,"<>",'ASF Tracker'!$D$4:$D$1002,"TEDLAR/SIDEWALL"),"-") -> 7 / 12 | H24: PAX SEAT | I24: =IFERROR(COUNTIFS('ASF Tracker'!$B$4:$B$1002,"<>",'ASF Tracker'!$D$4:$D$1002,"PAX SEAT",'ASF Tracker'!$E$4:$E$1002,"Closed")&" / "&COUNTIFS('ASF Tracker'!$B$4:$B$1002,"<>",'ASF Tracker'!$D$4:$D$1002,"PAX SEAT"),"-") -> 1 / 27
B25: =IFERROR("Completion: "&TEXT(COUNTIFS('ASF Tracker'!$D$4:$D$1002,"GENERAL CABIN",'ASF Tracker'!$E$4:$E$1002,"Closed",'ASF Tracker'!$B$4:$B$1002,"<>")/COUNTIFS('ASF Tracker'!$D$4:$D$1002,"GENERAL CABIN",'ASF Tracker'!$B$4:$B$1002,"<>"),"0%"),"-") -> Completion: 47% | E25: =IFERROR("Completion: "&TEXT(COUNTIFS('ASF Tracker'!$B$4:$B$1002,"<>",'ASF Tracker'!$D$4:$D$1002,"TEDLAR/SIDEWALL",'ASF Tracker'!$E$4:$E$1002,"Closed")/COUNTIFS('ASF Tracker'!$B$4:$B$1002,"<>",'ASF Tracker'!$D$4:$D$1002,"TEDLAR/SIDEWALL"),"0%"),"-") -> Completion: 58% | H25: =IFERROR("Completion: "&TEXT(COUNTIFS('ASF Tracker'!$B$4:$B$1002,"<>",'ASF Tracker'!$D$4:$D$1002,"PAX SEAT",'ASF Tracker'!$E$4:$E$1002,"Closed")/COUNTIFS('ASF Tracker'!$B$4:$B$1002,"<>",'ASF Tracker'!$D$4:$D$1002,"PAX SEAT"),"0%"),"-") -> Completion: 4%
B27: PAX DOORS | C27: =IFERROR(COUNTIFS('ASF Tracker'!$B$4:$B$1002,"<>",'ASF Tracker'!$D$4:$D$1002,"PAX DOORS",'ASF Tracker'!$E$4:$E$1002,"Closed")&" / "&COUNTIFS('ASF Tracker'!$B$4:$B$1002,"<>",'ASF Tracker'!$D$4:$D$1002,"PAX DOORS"),"-") -> 3 / 13 | E27: F/A SEAT | F27: =IFERROR(COUNTIFS('ASF Tracker'!$B$4:$B$1002,"<>",'ASF Tracker'!$D$4:$D$1002,"F/A SEAT",'ASF Tracker'!$E$4:$E$1002,"Closed")&" / "&COUNTIFS('ASF Tracker'!$B$4:$B$1002,"<>",'ASF Tracker'!$D$4:$D$1002,"F/A SEAT"),"-") -> 17 / 27 | H27: OTHERS | I27: =IFERROR((COUNTIFS('ASF Tracker'!$B$4:$B$1002,"<>",'ASF Tracker'!$E$4:$E$1002,"Closed")-(COUNTIFS('ASF Tracker'!$B$4:$B$1002,"<>",'ASF Tracker'!$D$4:$D$1002,"TASK CARD",'ASF Tracker'!$E$4:$E$1002,"Closed")+COUNTIFS('ASF Tracker'!$B$4:$B$1002,"<>",'ASF Tracker'!$D$4:$D$1002,"LAVATORY",'ASF Tracker'!$E$4:$E$1002,"Closed")+COUNTIFS('ASF Tracker'!$B$4:$B$1002,"<>",'ASF Tracker'!$D$4:$D$1002,"GALLEY",'ASF Tracker'!$E$4:$E$1002,"Closed")+COUNTIFS('ASF Tracker'!$B$4:$B$1002,"<>",'ASF Tracker'!$D$4:$D$1002,"GENERAL CABIN",'ASF Tracker'!$E$4:$E$1002,"Closed")+COUNTIFS('ASF Tracker'!$B$4:$B$1002,"<>",'ASF Tracker'!$D$4:$D$1002,"TEDLAR/SIDEWALL",'ASF Tracker'!$E$4:$E$1002,"Closed")+COUNTIFS('ASF Tracker'!$B$4:$B$1002,"<>",'ASF Tracker'!$D$4:$D$1002,"PAX SEAT",'ASF Tracker'!$E$4:$E$1002,"Closed")+COUNTIFS('ASF Tracker'!$B$4:$B$1002,"<>",'ASF Tracker'!$D$4:$D$1002,"PAX DOORS",'ASF Tracker'!$E$4:$E$1002,"Closed")+COUNTIFS('ASF Tracker'!$B$4:$B$1002,"<>",'ASF Tracker'!$D$4:$D$1002,"F/A SEAT",'ASF Tracker'!$E$4:$E$1002,"Closed")+COUNTIFS('ASF Tracker'!$B$4:$B$1002,"<>",'ASF Tracker'!$D$4:$D$1002,"OFAR/OFCR",'ASF Tracker'!$E$4:$E$1002,"Closed")+COUNTIFS('ASF Tracker'!$B$4:$B$1002,"<>",'ASF Tracker'!$D$4:$D$1002,"FLIGHT DECK",'ASF Tracker'!$E$4:$E$1002,"Closed")))&" / "&(COUNTIFS('ASF Tracker'!$B$4:$B$1002,"<>")-(COUNTIFS('ASF Tracker'!$B$4:$B$1002,"<>",'ASF Tracker'!$D$4:$D$1002,"TASK CARD")+COUNTIFS('ASF Tracker'!$B$4:$B$1002,"<>",'ASF Tracker'!$D$4:$D$1002,"LAVATORY")+COUNTIFS('ASF Tracker'!$B$4:$B$1002,"<>",'ASF Tracker'!$D$4:$D$1002,"GALLEY")+COUNTIFS('ASF Tracker'!$B$4:$B$1002,"<>",'ASF Tracker'!$D$4:$D$1002,"GENERAL CABIN")+COUNTIFS('ASF Tracker'!$B$4:$B$1002,"<>",'ASF Tracker'!$D$4:$D$1002,"TEDLAR/SIDEWALL")+COUNTIFS('ASF Tracker'!$B$4:$B$1002,"<>",'ASF Tracker'!$D$4:$D$1002,"PAX SEAT")+COUNTIFS('ASF Tracker'!$B$4:$B$1002,"<>",'ASF Tracker'!$D$4:$D$1002,"PAX DOORS")+COUNTIFS('ASF Tracker'!$B$4:$B$1002,"<>",'ASF Tracker'!$D$4:$D$1002,"F/A SEAT")+COUNTIFS('ASF Tracker'!$B$4:$B$1002,"<>",'ASF Tracker'!$D$4:$D$1002,"OFAR/OFCR")+COUNTIFS('ASF Tracker'!$B$4:$B$1002,"<>",'ASF Tracker'!$D$4:$D$1002,"FLIGHT DECK"))),"-") -> 0 / 0
B28: =IFERROR("Completion: "&TEXT(COUNTIFS('ASF Tracker'!$B$4:$B$1002,"<>",'ASF Tracker'!$D$4:$D$1002,"PAX DOORS",'ASF Tracker'!$E$4:$E$1002,"Closed")/COUNTIFS('ASF Tracker'!$B$4:$B$1002,"<>",'ASF Tracker'!$D$4:$D$1002,"PAX DOORS"),"0%"),"-") -> Completion: 23% | E28: =IFERROR("Completion: "&TEXT(COUNTIFS('ASF Tracker'!$B$4:$B$1002,"<>",'ASF Tracker'!$D$4:$D$1002,"F/A SEAT",'ASF Tracker'!$E$4:$E$1002,"Closed")/COUNTIFS('ASF Tracker'!$B$4:$B$1002,"<>",'ASF Tracker'!$D$4:$D$1002,"F/A SEAT"),"0%"),"-") -> Completion: 63% | H28: =IFERROR("Completion: "&TEXT(((COUNTIFS('ASF Tracker'!$B$4:$B$1002,"<>",'ASF Tracker'!$E$4:$E$1002,"Closed")-(COUNTIFS('ASF Tracker'!$B$4:$B$1002,"<>",'ASF Tracker'!$D$4:$D$1002,"TASK CARD",'ASF Tracker'!$E$4:$E$1002,"Closed")+COUNTIFS('ASF Tracker'!$B$4:$B$1002,"<>",'ASF Tracker'!$D$4:$D$1002,"LAVATORY",'ASF Tracker'!$E$4:$E$1002,"Closed")+COUNTIFS('ASF Tracker'!$B$4:$B$1002,"<>",'ASF Tracker'!$D$4:$D$1002,"GALLEY",'ASF Tracker'!$E$4:$E$1002,"Closed")+COUNTIFS('ASF Tracker'!$B$4:$B$1002,"<>",'ASF Tracker'!$D$4:$D$1002,"GENERAL CABIN",'ASF Tracker'!$E$4:$E$1002,"Closed")+COUNTIFS('ASF Tracker'!$B$4:$B$1002,"<>",'ASF Tracker'!$D$4:$D$1002,"TEDLAR/SIDEWALL",'ASF Tracker'!$E$4:$E$1002,"Closed")+COUNTIFS('ASF Tracker'!$B$4:$B$1002,"<>",'ASF Tracker'!$D$4:$D$1002,"PAX SEAT",'ASF Tracker'!$E$4:$E$1002,"Closed")+COUNTIFS('ASF Tracker'!$B$4:$B$1002,"<>",'ASF Tracker'!$D$4:$D$1002,"PAX DOORS",'ASF Tracker'!$E$4:$E$1002,"Closed")+COUNTIFS('ASF Tracker'!$B$4:$B$1002,"<>",'ASF Tracker'!$D$4:$D$1002,"F/A SEAT",'ASF Tracker'!$E$4:$E$1002,"Closed")+COUNTIFS('ASF Tracker'!$B$4:$B$1002,"<>",'ASF Tracker'!$D$4:$D$1002,"OFAR/OFCR",'ASF Tracker'!$E$4:$E$1002,"Closed")+COUNTIFS('ASF Tracker'!$B$4:$B$1002,"<>",'ASF Tracker'!$D$4:$D$1002,"FLIGHT DECK",'ASF Tracker'!$E$4:$E$1002,"Closed"))))/((COUNTIFS('ASF Tracker'!$B$4:$B$1002,"<>")-(COUNTIFS('ASF Tracker'!$B$4:$B$1002,"<>",'ASF Tracker'!$D$4:$D$1002,"TASK CARD")+COUNTIFS('ASF Tracker'!$B$4:$B$1002,"<>",'ASF Tracker'!$D$4:$D$1002,"LAVATORY")+COUNTIFS('ASF Tracker'!$B$4:$B$1002,"<>",'ASF Tracker'!$D$4:$D$1002,"GALLEY")+COUNTIFS('ASF Tracker'!$B$4:$B$1002,"<>",'ASF Tracker'!$D$4:$D$1002,"GENERAL CABIN")+COUNTIFS('ASF Tracker'!$B$4:$B$1002,"<>",'ASF Tracker'!$D$4:$D$1002,"TEDLAR/SIDEWALL")+COUNTIFS('ASF Tracker'!$B$4:$B$1002,"<>",'ASF Tracker'!$D$4:$D$1002,"PAX SEAT")+COUNTIFS('ASF Tracker'!$B$4:$B$1002,"<>",'ASF Tracker'!$D$4:$D$1002,"PAX DOORS")+COUNTIFS('ASF Tracker'!$B$4:$B$1002,"<>",'ASF Tracker'!$D$4:$D$1002,"F/A SEAT")+COUNTIFS('ASF Tracker'!$B$4:$B$1002,"<>",'ASF Tracker'!$D$4:$D$1002,"OFAR/OFCR")+COUNTIFS('ASF Tracker'!$B$4:$B$1002,"<>",'ASF Tracker'!$D$4:$D$1002,"FLIGHT DECK")))),"0%"),"-") -> -
B30: FLIGHT DECK | C30: =IFERROR(COUNTIFS('ASF Tracker'!$B$4:$B$1002,"<>",'ASF Tracker'!$D$4:$D$1002,"FLIGHT DECK",'ASF Tracker'!$E$4:$E$1002,"Closed")&" / "&COUNTIFS('ASF Tracker'!$B$4:$B$1002,"<>",'ASF Tracker'!$D$4:$D$1002,"FLIGHT DECK"),"-") -> 19 / 25
B31: =IFERROR("Completion: "&TEXT(COUNTIFS('ASF Tracker'!$B$4:$B$1002,"<>",'ASF Tracker'!$D$4:$D$1002,"FLIGHT DECK",'ASF Tracker'!$E$4:$E$1002,"Closed")/COUNTIFS('ASF Tracker'!$B$4:$B$1002,"<>",'ASF Tracker'!$D$4:$D$1002,"FLIGHT DECK"),"0%"),"-") -> Completion: 76%
A33: SPECIALTY
B35: CABIN | C35: =IFERROR(COUNTIFS('ASF Tracker'!$B$4:$B$1002,"<>",'ASF Tracker'!$G$4:$G$1002,"CAB",'ASF Tracker'!$E$4:$E$1002,"Closed")&" / "&COUNTIFS('ASF Tracker'!$B$4:$B$1002,"<>",'ASF Tracker'!$G$4:$G$1002,"CAB"),"-") -> 143 / 222 | E35: SEAT SHOP | F35: =IFERROR(COUNTIFS('ASF Tracker'!$B$4:$B$1002,"<>",'ASF Tracker'!$G$4:$G$1002,"SEAT",'ASF Tracker'!$E$4:$E$1002,"Closed")&" / "&COUNTIFS('ASF Tracker'!$B$4:$B$1002,"<>",'ASF Tracker'!$G$4:$G$1002,"SEAT"),"-") -> 0 / 26 | H35: AV/FOMAX | I35: =IFERROR(COUNTIFS('ASF Tracker'!$B$4:$B$1002,"<>",'ASF Tracker'!$G$4:$G$1002,"AV",'ASF Tracker'!$E$4:$E$1002,"Closed")&" / "&COUNTIFS('ASF Tracker'!$B$4:$B$1002,"<>",'ASF Tracker'!$G$4:$G$1002,"AV"),"-") -> 14 / 33
B36: =IFERROR("Completion: "&TEXT(COUNTIFS('ASF Tracker'!$B$4:$B$1002,"<>",'ASF Tracker'!$G$4:$G$1002,"CAB",'ASF Tracker'!$E$4:$E$1002,"Closed")/COUNTIFS('ASF Tracker'!$B$4:$B$1002,"<>",'ASF Tracker'!$G$4:$G$1002,"CAB"),"0%"),"-") -> Completion: 64% | E36: =IFERROR("Completion: "&TEXT(COUNTIFS('ASF Tracker'!$B$4:$B$1002,"<>",'ASF Tracker'!$G$4:$G$1002,"SEAT",'ASF Tracker'!$E$4:$E$1002,"Closed")/COUNTIFS('ASF Tracker'!$B$4:$B$1002,"<>",'ASF Tracker'!$G$4:$G$1002,"SEAT"),"0%"),"-") -> Completion: 0% | H36: =IFERROR("Completion: "&TEXT(COUNTIFS('ASF Tracker'!$B$4:$B$1002,"<>",'ASF Tracker'!$G$4:$G$1002,"AV",'ASF Tracker'!$E$4:$E$1002,"Closed")/COUNTIFS('ASF Tracker'!$B$4:$B$1002,"<>",'ASF Tracker'!$G$4:$G$1002,"AV"),"0%"),"-") -> Completion: 42%
B38: SIDEWALL | C38: =IFERROR(COUNTIFS('ASF Tracker'!$B$4:$B$1002,"<>",'ASF Tracker'!$G$4:$G$1002,"S/W",'ASF Tracker'!$E$4:$E$1002,"Closed")&" / "&COUNTIFS('ASF Tracker'!$B$4:$B$1002,"<>",'ASF Tracker'!$G$4:$G$1002,"S/W"),"-") -> 4 / 10 | E38: S/M | F38: =IFERROR(COUNTIFS('ASF Tracker'!$B$4:$B$1002,"<>",'ASF Tracker'!$G$4:$G$1002,"S/M",'ASF Tracker'!$E$4:$E$1002,"Closed")&" / "&COUNTIFS('ASF Tracker'!$B$4:$B$1002,"<>",'ASF Tracker'!$G$4:$G$1002,"S/M"),"-") -> 2 / 6 | H38: PAINT | I38: =IFERROR(COUNTIFS('ASF Tracker'!$B$4:$B$1002,"<>",'ASF Tracker'!$G$4:$G$1002,"PAINT",'ASF Tracker'!$E$4:$E$1002,"Closed")&" / "&COUNTIFS('ASF Tracker'!$B$4:$B$1002,"<>",'ASF Tracker'!$G$4:$G$1002,"PAINT"),"-") -> 5 / 25
B39: =IFERROR("Completion: "&TEXT(COUNTIFS('ASF Tracker'!$B$4:$B$1002,"<>",'ASF Tracker'!$G$4:$G$1002,"S/W",'ASF Tracker'!$E$4:$E$1002,"Closed")/COUNTIFS('ASF Tracker'!$B$4:$B$1002,"<>",'ASF Tracker'!$G$4:$G$1002,"S/W"),"0%"),"-") -> Completion: 40% | E39: =IFERROR("Completion: "&TEXT(COUNTIFS('ASF Tracker'!$B$4:$B$1002,"<>",'ASF Tracker'!$G$4:$G$1002,"S/M",'ASF Tracker'!$E$4:$E$1002,"Closed")/COUNTIFS('ASF Tracker'!$B$4:$B$1002,"<>",'ASF Tracker'!$G$4:$G$1002,"S/M"),"0%"),"-") -> Completion: 33% | H39: =IFERROR("Completion: "&TEXT(COUNTIFS('ASF Tracker'!$B$4:$B$1002,"<>",'ASF Tracker'!$G$4:$G$1002,"PAINT",'ASF Tracker'!$E$4:$E$1002,"Closed")/COUNTIFS('ASF Tracker'!$B$4:$B$1002,"<>",'ASF Tracker'!$G$4:$G$1002,"PAINT"),"0%"),"-") -> Completion: 20%
B41: JOINT | C41: =IFERROR(COUNTIFS('ASF Tracker'!$B$4:$B$1002,"<>",'ASF Tracker'!$G$4:$G$1002,"JOINT",'ASF Tracker'!$E$4:$E$1002,"Closed")&" / "&COUNTIFS('ASF Tracker'!$B$4:$B$1002,"<>",'ASF Tracker'!$G$4:$G$1002,"JOINT"),"-") -> 12 / 20 | E41: INSP | F41: =IFERROR(COUNTIFS('ASF Tracker'!$B$4:$B$1002,"<>",'ASF Tracker'!$G$4:$G$1002,"INSP",'ASF Tracker'!$E$4:$E$1002,"Closed")&" / "&COUNTIFS('ASF Tracker'!$B$4:$B$1002,"<>",'ASF Tracker'!$G$4:$G$1002,"INSP"),"-") -> 8 / 14 | H41: A/P | I41: =IFERROR(COUNTIFS('ASF Tracker'!$B$4:$B$1002,"<>",'ASF Tracker'!$G$4:$G$1002,"AP",'ASF Tracker'!$E$4:$E$1002,"Closed")&" / "&COUNTIFS('ASF Tracker'!$B$4:$B$1002,"<>",'ASF Tracker'!$G$4:$G$1002,"AP"),"-") -> 4 / 19
B42: =IFERROR("Completion: "&TEXT(COUNTIFS('ASF Tracker'!$B$4:$B$1002,"<>",'ASF Tracker'!$G$4:$G$1002,"JOINT",'ASF Tracker'!$E$4:$E$1002,"Closed")/COUNTIFS('ASF Tracker'!$B$4:$B$1002,"<>",'ASF Tracker'!$G$4:$G$1002,"JOINT"),"0%"),"-") -> Completion: 60% | E42: =IFERROR("Completion: "&TEXT(COUNTIFS('ASF Tracker'!$B$4:$B$1002,"<>",'ASF Tracker'!$G$4:$G$1002,"INSP",'ASF Tracker'!$E$4:$E$1002,"Closed")/COUNTIFS('ASF Tracker'!$B$4:$B$1002,"<>",'ASF Tracker'!$G$4:$G$1002,"INSP"),"0%"),"-") -> Completion: 57% | H42: =IFERROR("Completion: "&TEXT(COUNTIFS('ASF Tracker'!$B$4:$B$1002,"<>",'ASF Tracker'!$G$4:$G$1002,"AP",'ASF Tracker'!$E$4:$E$1002,"Closed")/COUNTIFS('ASF Tracker'!$B$4:$B$1002,"<>",'ASF Tracker'!$G$4:$G$1002,"AP"),"0%"),"-") -> Completion: 21%

Sheet Findings Draft
A1: 📋 FINDINGS DRAFT — Pre-AMOS
A2: Findings sourced from ACFT Finding Report App · Review & assign P/N before raising on AMOS
A3: # | B3: By | C3: Category | D3: Sub-Category | E3: Finding Description | F3: Remarks | G3: Photo URL | H3: AMOS Status | I3: WO No. | J3: P/N Required | K3: Qty
A4: 1 | B4: BAY 4 CREW | C4: LAVATORY | D4: LAV A | E4: LAVATORY A NURSING TABLE WITH MISSING BUMPER. | H4: Raised
A5: 2 | B5: BAY 4 CREW | C5: LAVATORY | E5: LAVATORY A NURSING TABLE DISCOLORED. | F5: PAINT | H5: Not Raised
A6: 3 | B6: BAY 4 CREW | C6: LAVATORY | E6: LAVATORY A SERVICE CABINET STORAGE DRAWER RUBBER SEAL NOT SECURED. | H6: Raised
A7: 4 | B7: BAY 4 CREW | C7: LAVATORY | E7: LAVATORY A TOILET SHROUD WITH MISSING 2 EA SCREWS. | H7: Raised
A8: 5 | B8: BAY 4 CREW | C8: LAVATORY | E8: LAVATORY A TOILET PAPER DISPENSER COVER COLOR FADED. | H8: Raised
A9: 6 | B9: BAY 4 CREW | C9: LAVATORY | E9: LAVATORY A FAUCET LEAKING | H9: Raised
A10: 7 | B10: BAY 4 CREW | C10: LAVATORY | D10: LAV E | E10: LAVATORY E TOILET SHROUD NOT SECURED. | H10: Raised
A11: 8 | B11: BAY 4 CREW | C11: LAVATORY | E11: LAVATORY E TOILET SHROUD SCREW CORRODED | H11: Not Raised
A12: 9 | B12: BAY 4 CREW | C12: LAVATORY | E12: LAVATORY E TOILET SHROUD COVER DISCOLORED. | F12: PAINT | H12: Raised
A13: 10 | B13: BAY 4 CREW | C13: LAVATORY | E13: LAVATORY E NURSING TABLE WITH MISSING BUMPER. | H13: Raised
A14: 11 | B14: BAY 4 CREW | C14: LAVATORY | E14: LAVATORY E FAUCET LEAKING. | H14: Raised
A15: 12 | B15: BAY 4 CREW | C15: LAVATORY | E15: LAVATORY E WATER HEATER INOP. | H15: Raised
A16: 13 | B16: BAY 4 CREW | C16: LAVATORY | E16: LAVATORY E AIR VENTILATION COVER BROKEN. | H16: Raised
A17: 14 | B17: BAY 4 CREW | C17: LAVATORY | D17: LAV D | E17: LAVATORY D TOILET SHROUD COVER NOT SECURED. | H17: Raised
A18: 15 | B18: BAY 4 CREW | C18: LAVATORY | E18: LAVATORY D WASHBASIN ACCESS DOOR REQ PAINT. | H18: Not Raised
A19: 16 | B19: BAY 4 CREW | C19: LAVATORY | E19: LAVATORY D TOILET PAPER ROLLER IS MISSING. | H19: Raised
A20: 17 | B20: BAY 4 CREW | C20: LAVATORY | E20: LAVATORY D FAUCET IS LEAKING. | H20: Not Raised
A21: 18 | B21: BAY 4 CREW | C21: LAVATORY | E21: LAVATORY D SINK SIEVE NOT SECURED. | H21: Raised
A22: 19 | B22: BAY 4 CREW | C22: LAVATORY | E22: LAVATORY D WASHBASIN SINK DRAINING SLOWLY. | H22: Raised
A23: 20 | B23: BAY 4 CREW | C23: LAVATORY | E23: LAVATORY D DOOR HANDLE LOOSE. | H23: Raised
A24: 21 | B24: BAY 4 CREW | C24: LAVATORY | E24: LAVATORY D TEDLAR DAMAGED. | F24: OUTERBOARD TEDLAR | H24: Not Raised
A25: 22 | B25: BAY 4 CREW | C25: GALLEY | E25: G1 GALLEY CART TURN CATCH AT 109 AND 111 FOUND LOOSE. | H25: Raised
A26: 23 | B26: BAY 4 CREW | C26: GALLEY | E26: FWD GALLEY CART COMPT. 109 MID LATCH LEVER IS MISSING. | H26: Raised
A27: 24 | B27: BAY 4 CREW | C27: GALLEY | E27: FWD GALLEY COUNTERTOP SEALANT DETERIORATED. | F27: REQ REWORK | H27: Raised
A28: 25 | B28: BAY 4 CREW | C28: GALLEY | E28: G1 GALLEY COMPT. 101 DOOR HINGE LOOSE. | H28: Not Raised
A29: 26 | B29: BAY 4 CREW | C29: GALLEY | E29: G2 GALLEY ICE BOX LOWER TRIM WITH CORROSION | F29: REQ EVAL DONT RAISE NOW | H29: Not Raised
A30: 27 | B30: BAY 4 CREW | C30: GALLEY | E30: G2 GALLEY COMPT. 211 LOWER BUMPER IS MISSING. | H30: Raised
A31: 28 | B31: BAY 4 CREW | C31: GALLEY | E31: G2 GALLEY COMPT. 210 DOOR TEDLAR CHIPPED OFF. | H31: Not Raised
A32: 29 | B32: BAY 4 CREW | C32: GALLEY | E32: G2 GALLEY COUNTERTOP BULGED. | F32: REQ EVAL DONT RAISE NOW | H32: Not Raised
A33: 30 | B33: BAY 4 CREW | C33: GALLEY | E33: G2 GALLEY FOOTSTEP INOP. | H33: Raised
A34: 31 | B34: BAY 4 CREW | C34: GALLEY | E34: G2 GALLEY COMPT. 210 DOOR LOCK LOOSE. | H34: Raised
A35: 32 | B35: BAY 4 CREW | C35: GALLEY | E35: AFT GALLEY COMPT. 501 DOOR HINGE BROKEN. | H35: Raised
A36: 33 | B36: BAY 4 CREW | C36: GALLEY | E36: AFT GALLEY COMPT. 501, 503 AND 504 STC DIVIDER KNOB BROKEN (WITHOUT LOCK). | F36: REQ EVAL | H36: Not Raised
A37: 34 | B37: BAY 4 CREW | C37: GALLEY | E37: AFT GALLEY 3 LONG CART CATCH AND 2 SHORT CART TURN CATCH REQ REPLACEMENT. | H37: Not Raised
A38: 35 | B38: BAY 4 CREW | C38: GALLEY | E38: AFT GALLEY ALL OVENS REQ PAITN. | H38: Raised
A39: 36 | B39: BAY 4 CREW | C39: GALLEY | E39: AFT GALLEY CART COMPARTMENT AT 517 T-DIVIDER WITH MISSING BUMPER. | H39: Not Raised
A40: 37 | B40: BAY 4 CREW | C40: GALLEY | E40: AFT GALLEY CART COMPARTMENT AT 519 T-DIVIDER WITH BROKEN BUMPER. | H40: Not Raised
...
