Workbook

Sheet HZ-ASD Tracker
A1: POOL CABIN ✈ HZ-ASD ✈ C2+6Y CHECK WORK PACKAGE TRACKER | E1: =IF(OR(NOT(ISNUMBER(DASHBOARD!$M$1)),NOT(ISNUMBER(DASHBOARD!$M$2))),"PENDING","DAY "&MAX(MIN(TODAY()-DASHBOARD!$M$1+1,DASHBOARD!$M$2-DASHBOARD!$M$1+1),0)&"/"&(DASHBOARD!$M$2-DASHBOARD!$M$1+1)) -> DAY 2/38 | H1: ="✅ "&COUNTIFS(A4:A1004,"<>",E4:E1004,"Closed")&" / "&COUNTIF(A4:A1004,"<>")&" Closed ("&TEXT(IFERROR(COUNTIFS(A4:A1004,"<>",E4:E1004,"Closed")/COUNTIF(A4:A1004,"<>"),0),"0%")&")" -> ✅ 0 / 192 Closed (0%)
A2: =IF(COUNT($L$4:$L$1004)=0,"No dated updates yet — type todays date (e.g. 19/7) in column L when you edit a row","LAST UPDATE: "&TEXT(MAX($L$4:$L$1004),"DD-MMM")&" · "&COUNTIF($L$4:$L$1004,MAX($L$4:$L$1004))&" row(s) updated — filter column L for details") -> LAST UPDATE: 19-Jul · 13 row(s) updated — filter column L for details | H2: ="AOG/Critical: "&COUNTIFS(A4:A1004,"<>",F4:F1004,"AOG")+COUNTIFS(A4:A1004,"<>",F4:F1004,"Critical") -> AOG/Critical: 1
A3: WO / Event Number | B3: Task Description | C3: Seq. No. | D3: Category | E3: Status | F3: Priority | G3: Specialty | H3: PARTS REQ. | I3: Remarks | J3: Time EVAL? | K3: AREA | L3: Updated | M3: Closed Date | N3: Est MH | O3: ATA | P3: Booked MH | Q3: Actual Dur (h)
A4: 32797253 | B4: 6Y_N/6Y_N YEARS STRUCTURE | C4: 1 | D4: ACFT GENERAL T/C | E4: Open | F4: Normal | G4: AP | J4: N/A | K4: JOINT | N4: 0 | O4: 05
A5: 200231-03-1 | B5: 200231-03-1 (2) / FORWARD PASSENGER COMPARTMENT INSP | C5: 24 | D5: GENERAL CABIN | E5: Open | F5: Normal | G5: JOINT | I5: CAB + INSP | J5: N/A | K5: FWD | N5: 7.15 | O5: 24-92
A6: 200241-04-1 | B6: 200241-04-1 (2) / CENTER PASSENGER COMPARTMENT INSP | C6: 25 | D6: GENERAL CABIN | E6: Open | F6: Normal | G6: JOINT | I6: CAB + INSP | J6: N/A | N6: 7.15 | O6: 24-92
A7: 200251-03-1 | B7: 200251-03-1 (2) / AFT PASSENGER COMPARTMENT INSPECTION | C7: 26 | D7: GENERAL CABIN | E7: Open | F7: Normal | G7: JOINT | I7: CAB + INSP | J7: N/A | K7: AFT | N7: 7.15 | O7: 24-92
A8: 25-11-00-18-0-SVA-001 | B8: 25-11-00-18-0-SVA-001 (04) / FOURTH OCCUPANT SEAT COVERS REPLCMNT | C8: 32 | D8: FLIGHT DECK | E8: Open | F8: Normal | G8: CAB | H8: Requested | I8: P/S 4509031 | J8: N/A | K8: FWD | L8: 46222 | N8: 2 | O8: 25-11
A9: 25-11-00-18-0-SVA-002 | B9: 25-11-00-18-0-SVA-002 (04) / THIRD OCCUPANT SEAT COVERS R/R | C9: 33 | D9: FLIGHT DECK | E9: Open | F9: Normal | G9: CAB | H9: Requested | I9: P/S 4509039 | J9: N/A | K9: FWD | L9: 46222 | N9: 2 | O9: 25-11
A10: 25-22-00-03-0-SVA-002 | B10: 25-22-00-03-0-SVA-002 (02) / CABIN ATTENDANT SEAT COVERS R&R | C10: 34 | D10: F/A SEAT | E10: Open | F10: AOG | G10: CAB | H10: Requested | I10: P/S 4509037 (SOME PARTS S/D) | J10: N/A | K10: JOINT | L10: 46222 | N10: 4 | O10: 25-22
A11: 253000-01-1 | B11: 253000-01-1 (3) / GALLEY ATTACHMENT POINTS INSPECTION | C11: 35 | D11: GALLEY | E11: Open | F11: Normal | G11: JOINT | I11: CAB + INSP | J11: N/A | K11: JOINT | N11: 0.75 | O11: 25-30
A12: 254000-02-2 | B12: 254000-02-2 (2) / LAVATORIE’S ATTACHMENT POINTS INSP | C12: 36 | D12: LAVATORY | E12: Open | F12: Normal | G12: JOINT | I12: CAB + INSP | J12: N/A | K12: JOINT | N12: 0.65 | O12: 25-40
A13: 256141-01-1 | B13: 256141-01-1 (3) / CAPT AND F/O EMERGENCY DEVICE INSP | C13: 37 | D13: FLIGHT DECK | E13: Open | F13: Normal | G13: JOINT | I13: CAB + INSP | J13: N/A | K13: FWD | N13: 0.43 | O13: 25-61
A14: 262541-01-1 | B14: 262541-01-1 (3) / LAVATORIES FIRE EXTINGUISHERS INSP | C14: 38 | D14: LAVATORY | E14: Open | F14: Normal | G14: INSP | I14: INSP | J14: N/A | K14: JOINT | N14: 0.22 | O14: 26-25
A15: 323300-01-1 | B15: 323300-01-1 (2) / LG FREE FALL EXTN MECH&CABLE INSP | C15: 44 | D15: ACFT GENERAL T/C | E15: Open | F15: Normal | I15: CABIN + COCKPIT ACCESS | J15: N/A | N15: 2.2 | O15: 32-33
A16: 323300-04-1 | B16: 323300-04-1 (3) / LG FREE FALL MECH CABLE TENTION CHK | C16: 45 | D16: ACFT GENERAL T/C | E16: Open | F16: Normal | I16: CABIN + COCKPIT ACCESS | J16: N/A | N16: 0.55 | O16: 32-33
A17: 531102-01-1 | B17: 531102-01-1 (5) / LH/RH FORWARD PASSENGER DOORS INSP | C17: 51 | D17: PAX DOORS | E17: Open | F17: Normal | I17: EXTERNAL | J17: N/A | K17: FWD | N17: 0.65 | O17: 53-11
A18: 531164-01-1 | B18: 531164-01-1 (02) / FUSELAGE FR 15-21 INSPECTION | C18: 52 | D18: ACFT GENERAL T/C | E18: Open | F18: Normal | I18: A&P | J18: N/A | K18: FWD | N18: 2.85 | O18: 53-11
A19: 531166-01-2 | B19: 531166-01-2 (2) / FUSELAGE FR 16-20 INSPECTION | C19: 53 | D19: ACFT GENERAL T/C | E19: Open | F19: Normal | I19: FWD DOORS GIRT FITTINGS | J19: N/A | K19: FWD | N19: 3.52 | O19: 53-11
A20: 531181-01-1 | B20: 531181-01-1 (3) / FUSELAGE INTERNL STRUCT FR15-21 INSP | C20: 55 | D20: ACFT GENERAL T/C | E20: Open | F20: Normal | G20: INSP | I20: FWD GALLEY + LAV A + SOME B/C SEATS + COCKPIT DOOR + FLOOR PANELS REMOVAL | J20: N/A | K20: FWD | N20: 4.88 | O20: 53-11
A21: 531189-01-2 | B21: 531189-01-2 (2) / CABIN FLOOR STRUCT FR12 & FR21 INSP | C21: 56 | D21: ACFT GENERAL T/C | E21: Open | F21: Normal | G21: INSP | I21: FWD GALLEY + LAV A + SOME B/C SEATS + COCKPIT DOOR + FLOOR PANELS REMOVAL | J21: N/A | K21: FWD | N21: 21.87 | O21: 53-11
A22: 531194-01-2 | B22: 531194-01-2 (2) / FLOOR STRUCTURE FR21 TO FR24 INSP | C22: 57 | D22: ACFT GENERAL T/C | E22: Open | F22: Normal | G22: INSP | I22: G2 GALLEY + SOME B/C SEATS REMOVAL | J22: N/A | K22: FWD | N22: 39.8 | O22: 53-11
A23: 534132-02-1 | B23: 534132-02-1 (2) / DETAILED INSP OF AFT PASS/CREW DOOR CUTOUT, UPPER CORNERS | C23: 60 | D23: ACFT GENERAL T/C | E23: Open | F23: Normal | G23: JOINT | I23: CAB + INSP | J23: N/A | K23: AFT | N23: 0.75 | O23: 53-41
A24: 534135-01-4 | B24: 534135-01-4 (03) / AFT PASSENGER/CREW DOOR CUTOUT INSP | C24: 61 | D24: ACFT GENERAL T/C | E24: Open | F24: Normal | G24: JOINT | I24: CAB + INSP | J24: N/A | K24: AFT | N24: 5.72 | O24: 53-41
A25: 534147-01-1 | B25: 534147-01-1 (2) / CABIN FLOOR STRUC AROUND GALLEY&LAV | C25: 62 | D25: ACFT GENERAL T/C | E25: Open | F25: Normal | I25: REMOVE ALL GALLEYS AND LAVS + SOME ROWS OF G/C SEATS | J25: N/A | K25: JOINT | N25: 89 | O25: 53-41
A26: 534195-01-2 | B26: 534195-01-2 (01) / CABIN FLOOR STRUCT BELOW AFT ENTERAN | C26: 66 | D26: ACFT GENERAL T/C | E26: Open | F26: Normal | I26: AFT AREA / OPEN UP | J26: N/A | K26: AFT | N26: 8 | O26: 53-41
A27: 562101-01-1 | B27: 562101-01-1 (3) / CABIN AND DOOR WINDOW PANES INSP | C27: 79 | D27: GENERAL CABIN | E27: Open | F27: Normal | G27: JOINT | I27: CAB + INSP | J27: N/A | K27: JOINT | N27: 13.2 | O27: 56-21
A28: ZL-145-01-1 | B28: ZL-145-01-1 (2) / ZONE UNDER CABIN FLOOR INSPECTION | C28: 109 | D28: ACFT GENERAL T/C | E28: Open | F28: Normal | I28: CAB + INSP / FR 36 TO FR 46 | J28: N/A | K28: JOINT | N28: 11.5 | O28: 05-21
A29: ZL-171-02-1 | B29: ZL-171-02-1 (2) / AFT CABIN UNDERFLOOR COMPART INSP | C29: 115 | D29: ACFT GENERAL T/C | E29: Open | F29: Normal | G29: INSP | I29: ISNP | J29: N/A | K29: AFT | N29: 77 | O29: 05-21
A30: ZL-193-01-1 | B30: ZL-193-01-1 (03) / UPPER WING FAIRING SLIDE STOWAGE AREA | C30: 117 | D30: ACFT GENERAL T/C | E30: Open | F30: Normal | G30: AP | I30: OFFWING SLIDE (AP) | J30: N/A | N30: 1.75 | O30: 05-21
A31: ZL-211-01-1 | B31: ZL-211-01-1 (03) / COCKPIT ZONAL INSPECTION | C31: 122 | D31: FLIGHT DECK | E31: Open | F31: Normal | G31: INSP | I31: INSP | J31: N/A | K31: FWD | N31: 0.43 | O31: 05-22
A32: ZL-833-02-1 | B32: ZL-833-02-1 (04) / FWD AND AFT EMERGENCY EXITS INSP | C32: 157 | D32: PAX DOORS | E32: Open | F32: Normal | G32: AP | I32: AP | J32: N/A | K32: JOINT | N32: 1.97 | O32: 05-28
A33: 31871161 | B33: A_N (A_N09)/A_N-CHECK | C33: 158 | D33: ACFT GENERAL T/C | E33: Open | F33: Normal | J33: N/A | K33: JOINT | N33: 0 | O33: 20-00
A34: 05-SVA-01 | B34: 05-SVA-01 (00) / EMERGENCY EQUIPMENTS EXPIRY CHECK | C34: 159 | D34: GENERAL CABIN | E34: Open | F34: Normal | G34: CAB | I34: CAB ONLY | J34: N/A | K34: JOINT | N34: 2.17 | O34: 05
A35: 11-11-00-01-0-SVA | B35: 11-11-00-01-0-SVA (02) / INTERIOR PLACARDS CHECK | C35: 160 | D35: GENERAL CABIN | E35: Open | F35: Normal | G35: PAINT | I35: PAINT | J35: N/A | K35: JOINT | N35: 1 | O35: 11-11
A36: 212300-02-1 | B36: 212300-02-1 (4) / LAVATORY AIR EXTRACTION FLTR R/R | C36: 162 | D36: LAVATORY | E36: Open | F36: Normal | G36: CAB | H36: Requested | I36: P/S 4509043 | J36: N/A | K36: JOINT | L36: 46222 | N36: 0.43 | O36: 21-23
A37: 25-10-00-00-SVA | B37: 25-10-00-00-SVA (00) / COCKPIT CHECK | C37: 168 | D37: FLIGHT DECK | E37: Open | F37: Normal | G37: CAB | I37: CAB ONLY | J37: N/A | K37: FWD | N37: 6.83 | O37: 25-10
A38: 25-20-00-00-SVA | B38: 25-20-00-00-SVA (01) / GENERAL CABIN DEEP INSP | C38: 169 | D38: GENERAL CABIN | E38: Open | F38: Normal | G38: JOINT | I38: CAB + INSP | J38: N/A | K38: JOINT | N38: 10.83 | O38: 25-10
A39: 25-21-00-00-SVA | B39: 25-21-00-00-SVA (01) / B/C SEAT DEEP INSP | C39: 170 | D39: PAX SEAT | E39: Open | F39: Normal | G39: SEAT | I39: SEAT SHOP | J39: N/A | K39: JOINT | N39: 6.42 | O39: 25-10
A40: 25-21-01-00-SVA | B40: 25-21-01-00-SVA (01) / G/C SEAT DEEP INSP | C40: 171 | D40: PAX SEAT | E40: Open | F40: Normal | G40: SEAT | I40: STEP 8 (CAB POOL SPLTY) | J40: N/A | K40: JOINT | N40: 6.92 | O40: 25-10
...

Sheet DASHBOARD
A1: 📊 HZ-ASD C2+6Y — WORK PACKAGE DASHBOARD | F1: ="DAY "&MAX(MIN(TODAY()-DASHBOARD!$M$1+1,DASHBOARD!$M$2-DASHBOARD!$M$1+1),0)&"/"&(DASHBOARD!$M$2-DASHBOARD!$M$1+1) -> DAY 2/38 | L1: START → | M1: 46221
A2: =IF(AND(DASHBOARD!$M$1="",DASHBOARD!$M$2=""),"⚙️ Set CHECK START (M1) and CHECK END (M2) dates → schedule alert activates automatically",IF(OR(NOT(ISNUMBER(DASHBOARD!$M$1)),NOT(ISNUMBER(DASHBOARD!$M$2))),"⚠️ Date not recognized — clear M1/M2 and re-type as 2026-07-01 (year-month-day)",IF(DASHBOARD!$M$2<=DASHBOARD!$M$1,"⚠️ CHECK END must be after CHECK START — please review M1/M2",IF(AND(TODAY()>DASHBOARD!$M$2,(COUNTIFS('HZ-ASD Tracker'!$A$4:$A$1004,"<>",'HZ-ASD Tracker'!$E$4:$E$1004,"Closed")/COUNTIF('HZ-ASD Tracker'!$A$4:$A$1004,"<>"))<1),"❌ CHECK PERIOD ENDED — Completion "&TEXT((COUNTIFS('HZ-ASD Tracker'!$A$4:$A$1004,"<>",'HZ-ASD Tracker'!$E$4:$E$1004,"Closed")/COUNTIF('HZ-ASD Tracker'!$A$4:$A$1004,"<>")),"0%")&" · Overdue by "&(TODAY()-DASHBOARD!$M$2)&" days",IF((COUNTIFS('HZ-ASD Tracker'!$A$4:$A$1004,"<>",'HZ-ASD Tracker'!$E$4:$E$1004,"Closed")/COUNTIF('HZ-ASD Tracker'!$A$4:$A$1004,"<>"))>=((TODAY()-DASHBOARD!$M$1)/(DASHBOARD!$M$2-DASHBOARD!$M$1))-0.05,"✅ ON TRACK — "&"Completed "&TEXT((COUNTIFS('HZ-ASD Tracker'!$A$4:$A$1004,"<>",'HZ-ASD Tracker'!$E$4:$E$1004,"Closed")/COUNTIF('HZ-ASD Tracker'!$A$4:$A$1004,"<>")),"0%")&" vs Time "&TEXT(MAX(MIN(((TODAY()-DASHBOARD!$M$1)/(DASHBOARD!$M$2-DASHBOARD!$M$1)),1),0),"0%")&" · Days Left: "&MAX(DASHBOARD!$M$2-TODAY(),0)&" · Pace needed: "&TEXT((COUNTIF('HZ-ASD Tracker'!$A$4:$A$1004,"<>")-COUNTIFS('HZ-ASD Tracker'!$A$4:$A$1004,"<>",'HZ-ASD Tracker'!$E$4:$E$1004,"Closed"))/MAX(DASHBOARD!$M$2-TODAY(),1),"0.0")&"/day vs avg "&TEXT(COUNTIFS('HZ-ASD Tracker'!$A$4:$A$1004,"<>",'HZ-ASD Tracker'!$E$4:$E$1004,"Closed")/MAX(TODAY()-DASHBOARD!$M$1,1),"0.0")&"/day",IF((COUNTIFS('HZ-ASD Tracker'!$A$4:$A$1004,"<>",'HZ-ASD Tracker'!$E$4:$E$1004,"Closed")/COUNTIF('HZ-ASD Tracker'!$A$4:$A$1004,"<>"))>=((TODAY()-DASHBOARD!$M$1)/(DASHBOARD!$M$2-DASHBOARD!$M$1))-0.15,"⚠️ WARNING — "&"Completed "&TEXT((COUNTIFS('HZ-ASD Tracker'!$A$4:$A$1004,"<>",'HZ-ASD Tracker'!$E$4:$E$1004,"Closed")/COUNTIF('HZ-ASD Tracker'!$A$4:$A$1004,"<>")),"0%")&" vs Time "&TEXT(MAX(MIN(((TODAY()-DASHBOARD!$M$1)/(DASHBOARD!$M$2-DASHBOARD!$M$1)),1),0),"0%")&" · Days Left: "&MAX(DASHBOARD!$M$2-TODAY(),0)&" · Pace needed: "&TEXT((COUNTIF('HZ-ASD Tracker'!$A$4:$A$1004,"<>")-COUNTIFS('HZ-ASD Tracker'!$A$4:$A$1004,"<>",'HZ-ASD Tracker'!$E$4:$E$1004,"Closed"))/MAX(DASHBOARD!$M$2-TODAY(),1),"0.0")&"/day vs avg "&TEXT(COUNTIFS('HZ-ASD Tracker'!$A$4:$A$1004,"<>",'HZ-ASD Tracker'!$E$4:$E$1004,"Closed")/MAX(TODAY()-DASHBOARD!$M$1,1),"0.0")&"/day","🔴 CRITICAL — "&"Completed "&TEXT((COUNTIFS('HZ-ASD Tracker'!$A$4:$A$1004,"<>",'HZ-ASD Tracker'!$E$4:$E$1004,"Closed")/COUNTIF('HZ-ASD Tracker'!$A$4:$A$1004,"<>")),"0%")&" vs Time "&TEXT(MAX(MIN(((TODAY()-DASHBOARD!$M$1)/(DASHBOARD!$M$2-DASHBOARD!$M$1)),1),0),"0%")&" · Days Left: "&MAX(DASHBOARD!$M$2-TODAY(),0)&" · Pace needed: "&TEXT((COUNTIF('HZ-ASD Tracker'!$A$4:$A$1004,"<>")-COUNTIFS('HZ-ASD Tracker'!$A$4:$A$1004,"<>",'HZ-ASD Tracker'!$E$4:$E$1004,"Closed"))/MAX(DASHBOARD!$M$2-TODAY(),1),"0.0")&"/day vs avg "&TEXT(COUNTIFS('HZ-ASD Tracker'!$A$4:$A$1004,"<>",'HZ-ASD Tracker'!$E$4:$E$1004,"Closed")/MAX(TODAY()-DASHBOARD!$M$1,1),"0.0")&"/day")))))) -> ✅ ON TRACK — Completed 0% vs Time 3% · Days Left: 36 · Pace needed: 5.3/day vs avg 0.0/day | L2: END → | M2: 46258
A4: TOTAL WOs | B4: CLOSED | C4: OPEN | D4: HPC ⏳ | E4: 🚨 AOG/CRIT | F4: MH DONE ⏱ | G4: DONE
A5: =COUNTIF('HZ-ASD Tracker'!$A$4:$A$1004,"<>") -> 192 | B5: =COUNTIFS('HZ-ASD Tracker'!$A$4:$A$1004,"<>",'HZ-ASD Tracker'!$E$4:$E$1004,"Closed") -> 0 | C5: =COUNTIFS('HZ-ASD Tracker'!$A$4:$A$1004,"<>",'HZ-ASD Tracker'!$E$4:$E$1004,"Open") -> 192 | D5: =COUNTIFS('HZ-ASD Tracker'!$A$4:$A$1004,"<>",'HZ-ASD Tracker'!$E$4:$E$1004,"HPC") -> 0 | E5: =COUNTIFS('HZ-ASD Tracker'!$A$4:$A$1004,"<>",'HZ-ASD Tracker'!$F$4:$F$1004,"AOG",'HZ-ASD Tracker'!$E$4:$E$1004,"<>Closed")+COUNTIFS('HZ-ASD Tracker'!$A$4:$A$1004,"<>",'HZ-ASD Tracker'!$F$4:$F$1004,"Critical",'HZ-ASD Tracker'!$E$4:$E$1004,"<>Closed") -> 1 | F5: =IFERROR(SUMIFS('HZ-ASD Tracker'!$N$4:$N$1004,'HZ-ASD Tracker'!$E$4:$E$1004,"Closed")/SUM('HZ-ASD Tracker'!$N$4:$N$1004),0) -> 0 | G5: =IFERROR(COUNTIFS('HZ-ASD Tracker'!$A$4:$A$1004,"<>",'HZ-ASD Tracker'!$E$4:$E$1004,"Closed")/COUNTIF('HZ-ASD Tracker'!$A$4:$A$1004,"<>"),0) -> 0
A7: TIMELINE — linked to LAYOVER sheet
A8: ="🛬 O.O.S "&TEXT(DASHBOARD!$M$1-1,"DD-MMM")&" 🛫 B.I.S "&TEXT(DASHBOARD!$M$2,"DD-MMM")&" GROUND TIME "&(DASHBOARD!$M$2-DASHBOARD!$M$1+1)&" days"&" · DAY "&MAX(MIN(TODAY()-DASHBOARD!$M$1+1,DASHBOARD!$M$2-DASHBOARD!$M$1+1),0)&"/"&(DASHBOARD!$M$2-DASHBOARD!$M$1+1) -> 🛬 O.O.S 17-Jul 🛫 B.I.S 24-Aug GROUND TIME 38 days · DAY 2/38
A9: =IF(NOT(ISNUMBER(LAYOVER!$B$7)),"📍 Phase: awaiting official schedule","📍 Now: "&IF(AND(ISNUMBER(LAYOVER!$B$37),TODAY()>=LAYOVER!$B$37),"PHASE 5 — Release",IF(AND(ISNUMBER(LAYOVER!$B$27),TODAY()>=LAYOVER!$B$27),"PHASE 4 — Close Up & Final",IF(AND(ISNUMBER(LAYOVER!$B$21),TODAY()>=LAYOVER!$B$21),"PHASE 3 — Mod & Rectification",IF(AND(ISNUMBER(LAYOVER!$B$14),TODAY()>=LAYOVER!$B$14),"PHASE 2 — Inspection","PHASE 1 — Pre Hangar"))))) -> 📍 Now: PHASE 1 — Pre Hangar
A10: =IF(NOT(ISNUMBER(LAYOVER!$B$19)),"⏳ set findings cutoff (LAYOVER)",IF(TODAY()>LAYOVER!$B$19,"🔒 FINDINGS WINDOW CLOSED","⏳ Findings window closes in: "&(LAYOVER!$B$19-TODAY())&" day(s)")) -> ⏳ set findings cutoff (LAYOVER)
A11: =IFERROR("📅 Next: "&INDEX(LAYOVER!$A$41:$A$48,MATCH(_xludf.MINIFS(LAYOVER!$B$41:$B$48,LAYOVER!$B$41:$B$48,">="&TODAY()),LAYOVER!$B$41:$B$48,0))&IF(_xludf.MINIFS(LAYOVER!$B$41:$B$48,LAYOVER!$B$41:$B$48,">="&TODAY())=TODAY()," — TODAY"," in "&(_xludf.MINIFS(LAYOVER!$B$41:$B$48,LAYOVER!$B$41:$B$48,">="&TODAY())-TODAY())&" day(s)"),"📅 no upcoming milestone set") -> 📅 no upcoming milestone set
A12: =IF(NOT(ISNUMBER(LAYOVER!$C$28)),"🔒 Cabin close-up: date TBD",IF(TODAY()>LAYOVER!$C$28,"🔒 Close-up date passed — "&COUNTIFS('OPEN UP-ACCESS'!$B$4:$B$504,"<>",'OPEN UP-ACCESS'!$F$4:$F$504,"Open")&" still open","🔒 Close-up in "&(LAYOVER!$C$28-TODAY())&" day(s) · "&COUNTIFS('OPEN UP-ACCESS'!$B$4:$B$504,"<>",'OPEN UP-ACCESS'!$F$4:$F$504,"Open")&" still open")) -> 🔒 Cabin close-up: date TBD
A13: BY SOURCE
B14: Closed | C14: Total | D14: % | E14: Window ⏱ | F14: Left
A15: ROUTINE TASKS (WP) | B15: =(COUNTIFS('HZ-ASD Tracker'!$A$4:$A$1004,"<>",'HZ-ASD Tracker'!$E$4:$E$1004,"Closed")-SUMPRODUCT(('HZ-ASD Tracker'!$A$4:$A$1004<>"")*(LEN('HZ-ASD Tracker'!$A$4:$A$1004)=8)*ISNUMBER(--'HZ-ASD Tracker'!$A$4:$A$1004)*('HZ-ASD Tracker'!$E$4:$E$1004="Closed"))+SUMPRODUCT(('HZ-ASD Tracker'!$A$4:$A$1004<>"")*(LEN('HZ-ASD Tracker'!$A$4:$A$1004)=8)*ISNUMBER(--'HZ-ASD Tracker'!$A$4:$A$1004)*(((LEFT('HZ-ASD Tracker'!$B$4:$B$1004,3)="6Y_")+(LEFT('HZ-ASD Tracker'!$B$4:$B$1004,4)="A_N ")+(LEFT('HZ-ASD Tracker'!$B$4:$B$1004,4)="C_N ")+(LEFT('HZ-ASD Tracker'!$B$4:$B$1004,4)="DCC-")+(LEFT('HZ-ASD Tracker'!$B$4:$B$1004,4)="CCC-")+(LEFT('HZ-ASD Tracker'!$B$4:$B$1004,4)="ISC-")+(LEFT('HZ-ASD Tracker'!$B$4:$B$1004,7)="WEEKLY-"))>0)*('HZ-ASD Tracker'!$E$4:$E$1004="Closed"))) -> 0 | C15: =(COUNTIF('HZ-ASD Tracker'!$A$4:$A$1004,"<>")-SUMPRODUCT(('HZ-ASD Tracker'!$A$4:$A$1004<>"")*(LEN('HZ-ASD Tracker'!$A$4:$A$1004)=8)*ISNUMBER(--'HZ-ASD Tracker'!$A$4:$A$1004))+SUMPRODUCT(('HZ-ASD Tracker'!$A$4:$A$1004<>"")*(LEN('HZ-ASD Tracker'!$A$4:$A$1004)=8)*ISNUMBER(--'HZ-ASD Tracker'!$A$4:$A$1004)*(((LEFT('HZ-ASD Tracker'!$B$4:$B$1004,3)="6Y_")+(LEFT('HZ-ASD Tracker'!$B$4:$B$1004,4)="A_N ")+(LEFT('HZ-ASD Tracker'!$B$4:$B$1004,4)="C_N ")+(LEFT('HZ-ASD Tracker'!$B$4:$B$1004,4)="DCC-")+(LEFT('HZ-ASD Tracker'!$B$4:$B$1004,4)="CCC-")+(LEFT('HZ-ASD Tracker'!$B$4:$B$1004,4)="ISC-")+(LEFT('HZ-ASD Tracker'!$B$4:$B$1004,7)="WEEKLY-"))>0))) -> 164 | D15: =IFERROR(B15/C15,0) -> 0 | E15: =MIN(MAX((TODAY()-DASHBOARD!$M$1)/(DASHBOARD!$M$2-DASHBOARD!$M$1),0),1) -> 0.027027027 | F15: =C15-B15 -> 164 | G15: =IF(D15=0,"",D15)
A16: ENG ORDERS (EOD/AD/EO) | B16: =SUMPRODUCT(('HZ-ASD Tracker'!$A$4:$A$1004<>"")*(LEN('HZ-ASD Tracker'!$A$4:$A$1004)=8)*ISNUMBER(--'HZ-ASD Tracker'!$A$4:$A$1004)*(((LEFT('HZ-ASD Tracker'!$B$4:$B$1004,4)="EOD-")+(LEFT('HZ-ASD Tracker'!$B$4:$B$1004,3)="EO-")+(LEFT('HZ-ASD Tracker'!$B$4:$B$1004,3)="ER-")+(LEFT('HZ-ASD Tracker'!$B$4:$B$1004,5)="FRSEO")+(LEFT('HZ-ASD Tracker'!$B$4:$B$1004,1)="S")*ISNUMBER(--MID('HZ-ASD Tracker'!$B$4:$B$1004,2,2))*(MID('HZ-ASD Tracker'!$B$4:$B$1004,4,2)="-R")+(LEFT('HZ-ASD Tracker'!$B$4:$B$1004,8)="REPLACE ")+ISNUMBER(SEARCH("/AD-",'HZ-ASD Tracker'!$B$4:$B$1004)))>0)*('HZ-ASD Tracker'!$E$4:$E$1004="Closed")) -> 0 | C16: =SUMPRODUCT(('HZ-ASD Tracker'!$A$4:$A$1004<>"")*(LEN('HZ-ASD Tracker'!$A$4:$A$1004)=8)*ISNUMBER(--'HZ-ASD Tracker'!$A$4:$A$1004)*(((LEFT('HZ-ASD Tracker'!$B$4:$B$1004,4)="EOD-")+(LEFT('HZ-ASD Tracker'!$B$4:$B$1004,3)="EO-")+(LEFT('HZ-ASD Tracker'!$B$4:$B$1004,3)="ER-")+(LEFT('HZ-ASD Tracker'!$B$4:$B$1004,5)="FRSEO")+(LEFT('HZ-ASD Tracker'!$B$4:$B$1004,1)="S")*ISNUMBER(--MID('HZ-ASD Tracker'!$B$4:$B$1004,2,2))*(MID('HZ-ASD Tracker'!$B$4:$B$1004,4,2)="-R")+(LEFT('HZ-ASD Tracker'!$B$4:$B$1004,8)="REPLACE ")+ISNUMBER(SEARCH("/AD-",'HZ-ASD Tracker'!$B$4:$B$1004)))>0)) -> 26 | D16: =IFERROR(B16/C16,0) -> 0 | E16: =IF(AND(ISNUMBER(LAYOVER!$B$22),ISNUMBER(LAYOVER!$C$22)),MIN(MAX((TODAY()-LAYOVER!$B$22)/(LAYOVER!$C$22-LAYOVER!$B$22),0),1),"") | F16: =C16-B16 -> 26 | G16: =IF(D16=0,"",D16)
A17: FINDINGS (AMOS) | B17: =(SUMPRODUCT(('HZ-ASD Tracker'!$A$4:$A$1004<>"")*(LEN('HZ-ASD Tracker'!$A$4:$A$1004)=8)*ISNUMBER(--'HZ-ASD Tracker'!$A$4:$A$1004)*('HZ-ASD Tracker'!$E$4:$E$1004="Closed"))-SUMPRODUCT(('HZ-ASD Tracker'!$A$4:$A$1004<>"")*(LEN('HZ-ASD Tracker'!$A$4:$A$1004)=8)*ISNUMBER(--'HZ-ASD Tracker'!$A$4:$A$1004)*(((LEFT('HZ-ASD Tracker'!$B$4:$B$1004,4)="EOD-")+(LEFT('HZ-ASD Tracker'!$B$4:$B$1004,3)="EO-")+(LEFT('HZ-ASD Tracker'!$B$4:$B$1004,3)="ER-")+(LEFT('HZ-ASD Tracker'!$B$4:$B$1004,5)="FRSEO")+(LEFT('HZ-ASD Tracker'!$B$4:$B$1004,1)="S")*ISNUMBER(--MID('HZ-ASD Tracker'!$B$4:$B$1004,2,2))*(MID('HZ-ASD Tracker'!$B$4:$B$1004,4,2)="-R")+(LEFT('HZ-ASD Tracker'!$B$4:$B$1004,8)="REPLACE ")+ISNUMBER(SEARCH("/AD-",'HZ-ASD Tracker'!$B$4:$B$1004)))>0)*('HZ-ASD Tracker'!$E$4:$E$1004="Closed"))-SUMPRODUCT(('HZ-ASD Tracker'!$A$4:$A$1004<>"")*(LEN('HZ-ASD Tracker'!$A$4:$A$1004)=8)*ISNUMBER(--'HZ-ASD Tracker'!$A$4:$A$1004)*(((LEFT('HZ-ASD Tracker'!$B$4:$B$1004,3)="6Y_")+(LEFT('HZ-ASD Tracker'!$B$4:$B$1004,4)="A_N ")+(LEFT('HZ-ASD Tracker'!$B$4:$B$1004,4)="C_N ")+(LEFT('HZ-ASD Tracker'!$B$4:$B$1004,4)="DCC-")+(LEFT('HZ-ASD Tracker'!$B$4:$B$1004,4)="CCC-")+(LEFT('HZ-ASD Tracker'!$B$4:$B$1004,4)="ISC-")+(LEFT('HZ-ASD Tracker'!$B$4:$B$1004,7)="WEEKLY-"))>0)*('HZ-ASD Tracker'!$E$4:$E$1004="Closed"))) -> 0 | C17: =(SUMPRODUCT(('HZ-ASD Tracker'!$A$4:$A$1004<>"")*(LEN('HZ-ASD Tracker'!$A$4:$A$1004)=8)*ISNUMBER(--'HZ-ASD Tracker'!$A$4:$A$1004))-SUMPRODUCT(('HZ-ASD Tracker'!$A$4:$A$1004<>"")*(LEN('HZ-ASD Tracker'!$A$4:$A$1004)=8)*ISNUMBER(--'HZ-ASD Tracker'!$A$4:$A$1004)*(((LEFT('HZ-ASD Tracker'!$B$4:$B$1004,4)="EOD-")+(LEFT('HZ-ASD Tracker'!$B$4:$B$1004,3)="EO-")+(LEFT('HZ-ASD Tracker'!$B$4:$B$1004,3)="ER-")+(LEFT('HZ-ASD Tracker'!$B$4:$B$1004,5)="FRSEO")+(LEFT('HZ-ASD Tracker'!$B$4:$B$1004,1)="S")*ISNUMBER(--MID('HZ-ASD Tracker'!$B$4:$B$1004,2,2))*(MID('HZ-ASD Tracker'!$B$4:$B$1004,4,2)="-R")+(LEFT('HZ-ASD Tracker'!$B$4:$B$1004,8)="REPLACE ")+ISNUMBER(SEARCH("/AD-",'HZ-ASD Tracker'!$B$4:$B$1004)))>0))-SUMPRODUCT(('HZ-ASD Tracker'!$A$4:$A$1004<>"")*(LEN('HZ-ASD Tracker'!$A$4:$A$1004)=8)*ISNUMBER(--'HZ-ASD Tracker'!$A$4:$A$1004)*(((LEFT('HZ-ASD Tracker'!$B$4:$B$1004,3)="6Y_")+(LEFT('HZ-ASD Tracker'!$B$4:$B$1004,4)="A_N ")+(LEFT('HZ-ASD Tracker'!$B$4:$B$1004,4)="C_N ")+(LEFT('HZ-ASD Tracker'!$B$4:$B$1004,4)="DCC-")+(LEFT('HZ-ASD Tracker'!$B$4:$B$1004,4)="CCC-")+(LEFT('HZ-ASD Tracker'!$B$4:$B$1004,4)="ISC-")+(LEFT('HZ-ASD Tracker'!$B$4:$B$1004,7)="WEEKLY-"))>0))) -> 2 | D17: =IFERROR(B17/C17,0) -> 0 | E17: =IF(AND(ISNUMBER(LAYOVER!$B$21),ISNUMBER(LAYOVER!$C$21)),MIN(MAX((TODAY()-LAYOVER!$B$21)/(LAYOVER!$C$21-LAYOVER!$B$21),0),1),"") | F17: =C17-B17 -> 2 | G17: =IF(D17=0,"",D17)
A19: BY CATEGORY
B20: Closed | C20: Total | D20: % | E20: Share | F20: Left
A21: GENERAL CABIN | B21: =COUNTIFS('HZ-ASD Tracker'!$A$4:$A$1004,"<>",'HZ-ASD Tracker'!$D$4:$D$1004,"GENERAL CABIN",'HZ-ASD Tracker'!$E$4:$E$1004,"Closed") -> 0 | C21: =COUNTIFS('HZ-ASD Tracker'!$A$4:$A$1004,"<>",'HZ-ASD Tracker'!$D$4:$D$1004,"GENERAL CABIN") -> 25 | D21: =IFERROR(B21/C21,0) -> 0 | E21: =IFERROR(C21/COUNTIF('HZ-ASD Tracker'!$A$4:$A$1004,"<>"),0) -> 0.13020833 | F21: =C21-B21 -> 25 | G21: =IF(D21=0,"",D21)
A22: GALLEY | B22: =COUNTIFS('HZ-ASD Tracker'!$A$4:$A$1004,"<>",'HZ-ASD Tracker'!$D$4:$D$1004,"GALLEY",'HZ-ASD Tracker'!$E$4:$E$1004,"Closed") -> 0 | C22: =COUNTIFS('HZ-ASD Tracker'!$A$4:$A$1004,"<>",'HZ-ASD Tracker'!$D$4:$D$1004,"GALLEY") -> 8 | D22: =IFERROR(B22/C22,0) -> 0 | E22: =IFERROR(C22/COUNTIF('HZ-ASD Tracker'!$A$4:$A$1004,"<>"),0) -> 0.041666667 | F22: =C22-B22 -> 8 | G22: =IF(D22=0,"",D22)
A23: LAVATORY | B23: =COUNTIFS('HZ-ASD Tracker'!$A$4:$A$1004,"<>",'HZ-ASD Tracker'!$D$4:$D$1004,"LAVATORY",'HZ-ASD Tracker'!$E$4:$E$1004,"Closed") -> 0 | C23: =COUNTIFS('HZ-ASD Tracker'!$A$4:$A$1004,"<>",'HZ-ASD Tracker'!$D$4:$D$1004,"LAVATORY") -> 11 | D23: =IFERROR(B23/C23,0) -> 0 | E23: =IFERROR(C23/COUNTIF('HZ-ASD Tracker'!$A$4:$A$1004,"<>"),0) -> 0.057291667 | F23: =C23-B23 -> 11 | G23: =IF(D23=0,"",D23)
A24: PAX DOORS | B24: =COUNTIFS('HZ-ASD Tracker'!$A$4:$A$1004,"<>",'HZ-ASD Tracker'!$D$4:$D$1004,"PAX DOORS",'HZ-ASD Tracker'!$E$4:$E$1004,"Closed") -> 0 | C24: =COUNTIFS('HZ-ASD Tracker'!$A$4:$A$1004,"<>",'HZ-ASD Tracker'!$D$4:$D$1004,"PAX DOORS") -> 41 | D24: =IFERROR(B24/C24,0) -> 0 | E24: =IFERROR(C24/COUNTIF('HZ-ASD Tracker'!$A$4:$A$1004,"<>"),0) -> 0.21354167 | F24: =C24-B24 -> 41 | G24: =IF(D24=0,"",D24)
A25: F/A SEAT | B25: =COUNTIFS('HZ-ASD Tracker'!$A$4:$A$1004,"<>",'HZ-ASD Tracker'!$D$4:$D$1004,"F/A SEAT",'HZ-ASD Tracker'!$E$4:$E$1004,"Closed") -> 0 | C25: =COUNTIFS('HZ-ASD Tracker'!$A$4:$A$1004,"<>",'HZ-ASD Tracker'!$D$4:$D$1004,"F/A SEAT") -> 6 | D25: =IFERROR(B25/C25,0) -> 0 | E25: =IFERROR(C25/COUNTIF('HZ-ASD Tracker'!$A$4:$A$1004,"<>"),0) -> 0.03125 | F25: =C25-B25 -> 6 | G25: =IF(D25=0,"",D25)
A26: PAX SEAT | B26: =COUNTIFS('HZ-ASD Tracker'!$A$4:$A$1004,"<>",'HZ-ASD Tracker'!$D$4:$D$1004,"PAX SEAT",'HZ-ASD Tracker'!$E$4:$E$1004,"Closed") -> 0 | C26: =COUNTIFS('HZ-ASD Tracker'!$A$4:$A$1004,"<>",'HZ-ASD Tracker'!$D$4:$D$1004,"PAX SEAT") -> 13 | D26: =IFERROR(B26/C26,0) -> 0 | E26: =IFERROR(C26/COUNTIF('HZ-ASD Tracker'!$A$4:$A$1004,"<>"),0) -> 0.067708333 | F26: =C26-B26 -> 13 | G26: =IF(D26=0,"",D26)
A27: FLIGHT DECK | B27: =COUNTIFS('HZ-ASD Tracker'!$A$4:$A$1004,"<>",'HZ-ASD Tracker'!$D$4:$D$1004,"FLIGHT DECK",'HZ-ASD Tracker'!$E$4:$E$1004,"Closed") -> 0 | C27: =COUNTIFS('HZ-ASD Tracker'!$A$4:$A$1004,"<>",'HZ-ASD Tracker'!$D$4:$D$1004,"FLIGHT DECK") -> 30 | D27: =IFERROR(B27/C27,0) -> 0 | E27: =IFERROR(C27/COUNTIF('HZ-ASD Tracker'!$A$4:$A$1004,"<>"),0) -> 0.15625 | F27: =C27-B27 -> 30 | G27: =IF(D27=0,"",D27)
A28: TEDLAR/SIDEWALL | B28: =COUNTIFS('HZ-ASD Tracker'!$A$4:$A$1004,"<>",'HZ-ASD Tracker'!$D$4:$D$1004,"TEDLAR/SIDEWALL",'HZ-ASD Tracker'!$E$4:$E$1004,"Closed") -> 0 | C28: =COUNTIFS('HZ-ASD Tracker'!$A$4:$A$1004,"<>",'HZ-ASD Tracker'!$D$4:$D$1004,"TEDLAR/SIDEWALL") -> 1 | D28: =IFERROR(B28/C28,0) -> 0 | E28: =IFERROR(C28/COUNTIF('HZ-ASD Tracker'!$A$4:$A$1004,"<>"),0) -> 0.0052083333 | F28: =C28-B28 -> 1 | G28: =IF(D28=0,"",D28)
A29: ACCESS | B29: =COUNTIFS('HZ-ASD Tracker'!$A$4:$A$1004,"<>",'HZ-ASD Tracker'!$D$4:$D$1004,"ACCESS",'HZ-ASD Tracker'!$E$4:$E$1004,"Closed") -> 0 | C29: =COUNTIFS('HZ-ASD Tracker'!$A$4:$A$1004,"<>",'HZ-ASD Tracker'!$D$4:$D$1004,"ACCESS") -> 0 | D29: =IFERROR(B29/C29,0) -> 0 | E29: =IFERROR(C29/COUNTIF('HZ-ASD Tracker'!$A$4:$A$1004,"<>"),0) -> 0 | F29: =C29-B29 -> 0 | G29: =IF(D29=0,"",D29)
A30: ACFT GENERAL T/C | B30: =COUNTIFS('HZ-ASD Tracker'!$A$4:$A$1004,"<>",'HZ-ASD Tracker'!$D$4:$D$1004,"ACFT GENERAL T/C",'HZ-ASD Tracker'!$E$4:$E$1004,"Closed") -> 0 | C30: =COUNTIFS('HZ-ASD Tracker'!$A$4:$A$1004,"<>",'HZ-ASD Tracker'!$D$4:$D$1004,"ACFT GENERAL T/C") -> 57 | D30: =IFERROR(B30/C30,0) -> 0 | E30: =IFERROR(C30/COUNTIF('HZ-ASD Tracker'!$A$4:$A$1004,"<>"),0) -> 0.296875 | F30: =C30-B30 -> 57 | G30: =IF(D30=0,"",D30)
A32: SPECIALTY
B33: Closed | C33: Total | D33: % | E33: Share | F33: Left
A34: CAB | B34: =COUNTIFS('HZ-ASD Tracker'!$A$4:$A$1004,"<>",'HZ-ASD Tracker'!$G$4:$G$1004,"CAB",'HZ-ASD Tracker'!$E$4:$E$1004,"Closed") -> 0 | C34: =COUNTIFS('HZ-ASD Tracker'!$A$4:$A$1004,"<>",'HZ-ASD Tracker'!$G$4:$G$1004,"CAB") -> 66 | D34: =IFERROR(B34/C34,0) -> 0 | E34: =IFERROR(C34/COUNTIF('HZ-ASD Tracker'!$A$4:$A$1004,"<>"),0) -> 0.34375 | F34: =C34-B34 -> 66 | G34: =IF(D34=0,"",D34)
A35: SEAT | B35: =COUNTIFS('HZ-ASD Tracker'!$A$4:$A$1004,"<>",'HZ-ASD Tracker'!$G$4:$G$1004,"SEAT",'HZ-ASD Tracker'!$E$4:$E$1004,"Closed") -> 0 | C35: =COUNTIFS('HZ-ASD Tracker'!$A$4:$A$1004,"<>",'HZ-ASD Tracker'!$G$4:$G$1004,"SEAT") -> 10 | D35: =IFERROR(B35/C35,0) -> 0 | E35: =IFERROR(C35/COUNTIF('HZ-ASD Tracker'!$A$4:$A$1004,"<>"),0) -> 0.052083333 | F35: =C35-B35 -> 10 | G35: =IF(D35=0,"",D35)
A36: AV | B36: =COUNTIFS('HZ-ASD Tracker'!$A$4:$A$1004,"<>",'HZ-ASD Tracker'!$G$4:$G$1004,"AV",'HZ-ASD Tracker'!$E$4:$E$1004,"Closed") -> 0 | C36: =COUNTIFS('HZ-ASD Tracker'!$A$4:$A$1004,"<>",'HZ-ASD Tracker'!$G$4:$G$1004,"AV") -> 26 | D36: =IFERROR(B36/C36,0) -> 0 | E36: =IFERROR(C36/COUNTIF('HZ-ASD Tracker'!$A$4:$A$1004,"<>"),0) -> 0.13541667 | F36: =C36-B36 -> 26 | G36: =IF(D36=0,"",D36)
A37: WALL | B37: =COUNTIFS('HZ-ASD Tracker'!$A$4:$A$1004,"<>",'HZ-ASD Tracker'!$G$4:$G$1004,"WALL",'HZ-ASD Tracker'!$E$4:$E$1004,"Closed") -> 0 | C37: =COUNTIFS('HZ-ASD Tracker'!$A$4:$A$1004,"<>",'HZ-ASD Tracker'!$G$4:$G$1004,"WALL") -> 0 | D37: =IFERROR(B37/C37,0) -> 0 | E37: =IFERROR(C37/COUNTIF('HZ-ASD Tracker'!$A$4:$A$1004,"<>"),0) -> 0 | F37: =C37-B37 -> 0 | G37: =IF(D37=0,"",D37)
A38: S/M | B38: =COUNTIFS('HZ-ASD Tracker'!$A$4:$A$1004,"<>",'HZ-ASD Tracker'!$G$4:$G$1004,"S/M",'HZ-ASD Tracker'!$E$4:$E$1004,"Closed") -> 0 | C38: =COUNTIFS('HZ-ASD Tracker'!$A$4:$A$1004,"<>",'HZ-ASD Tracker'!$G$4:$G$1004,"S/M") -> 0 | D38: =IFERROR(B38/C38,0) -> 0 | E38: =IFERROR(C38/COUNTIF('HZ-ASD Tracker'!$A$4:$A$1004,"<>"),0) -> 0 | F38: =C38-B38 -> 0 | G38: =IF(D38=0,"",D38)
A39: PAINT | B39: =COUNTIFS('HZ-ASD Tracker'!$A$4:$A$1004,"<>",'HZ-ASD Tracker'!$G$4:$G$1004,"PAINT",'HZ-ASD Tracker'!$E$4:$E$1004,"Closed") -> 0 | C39: =COUNTIFS('HZ-ASD Tracker'!$A$4:$A$1004,"<>",'HZ-ASD Tracker'!$G$4:$G$1004,"PAINT") -> 1 | D39: =IFERROR(B39/C39,0) -> 0 | E39: =IFERROR(C39/COUNTIF('HZ-ASD Tracker'!$A$4:$A$1004,"<>"),0) -> 0.0052083333 | F39: =C39-B39 -> 1 | G39: =IF(D39=0,"",D39)
A40: JOINT | B40: =COUNTIFS('HZ-ASD Tracker'!$A$4:$A$1004,"<>",'HZ-ASD Tracker'!$G$4:$G$1004,"JOINT",'HZ-ASD Tracker'!$E$4:$E$1004,"Closed") -> 0 | C40: =COUNTIFS('HZ-ASD Tracker'!$A$4:$A$1004,"<>",'HZ-ASD Tracker'!$G$4:$G$1004,"JOINT") -> 31 | D40: =IFERROR(B40/C40,0) -> 0 | E40: =IFERROR(C40/COUNTIF('HZ-ASD Tracker'!$A$4:$A$1004,"<>"),0) -> 0.16145833 | F40: =C40-B40 -> 31 | G40: =IF(D40=0,"",D40)
A41: INSP | B41: =COUNTIFS('HZ-ASD Tracker'!$A$4:$A$1004,"<>",'HZ-ASD Tracker'!$G$4:$G$1004,"INSP",'HZ-ASD Tracker'!$E$4:$E$1004,"Closed") -> 0 | C41: =COUNTIFS('HZ-ASD Tracker'!$A$4:$A$1004,"<>",'HZ-ASD Tracker'!$G$4:$G$1004,"INSP") -> 14 | D41: =IFERROR(B41/C41,0) -> 0 | E41: =IFERROR(C41/COUNTIF('HZ-ASD Tracker'!$A$4:$A$1004,"<>"),0) -> 0.072916667 | F41: =C41-B41 -> 14 | G41: =IF(D41=0,"",D41)
A42: AP | B42: =COUNTIFS('HZ-ASD Tracker'!$A$4:$A$1004,"<>",'HZ-ASD Tracker'!$G$4:$G$1004,"AP",'HZ-ASD Tracker'!$E$4:$E$1004,"Closed") -> 0 | C42: =COUNTIFS('HZ-ASD Tracker'!$A$4:$A$1004,"<>",'HZ-ASD Tracker'!$G$4:$G$1004,"AP") -> 14 | D42: =IFERROR(B42/C42,0) -> 0 | E42: =IFERROR(C42/COUNTIF('HZ-ASD Tracker'!$A$4:$A$1004,"<>"),0) -> 0.072916667 | F42: =C42-B42 -> 14 | G42: =IF(D42=0,"",D42)
A44: DAILY CLOSURES — last 10 days | C44: Σ Closed | D44: Left | E44: Cum %
A45: =TODAY()-9 -> 46213 | B45: =COUNTIFS('HZ-ASD Tracker'!$M$4:$M$1004,TODAY()-9,'HZ-ASD Tracker'!$E$4:$E$1004,"Closed") -> 0 | C45: =COUNTIFS('HZ-ASD Tracker'!$M$4:$M$1004,"<="&TODAY()-9,'HZ-ASD Tracker'!$E$4:$E$1004,"Closed") -> 0 | D45: =COUNTIF('HZ-ASD Tracker'!$A$4:$A$1004,"<>")-C45 -> 192 | E45: =IFERROR(C45/COUNTIF('HZ-ASD Tracker'!$A$4:$A$1004,"<>"),0) -> 0 | F45: =IF(E45=0,"",E45) | G45: =IF(B45=0,"",B45)
...

Sheet LAYOVER
D1: HZ-ASD C2+6Y-CHK + WIFI — LAYOVER SCHEDULE | AQ1: ="O.O.S "&TEXT(DASHBOARD!$M$1-1,"DD-MMM")&" B.I.S "&TEXT(DASHBOARD!$M$2,"DD-MMM")&" GROUND TIME "&(DASHBOARD!$M$2-DASHBOARD!$M$1+1)&" DAYS" -> O.O.S 17-Jul B.I.S 24-Aug GROUND TIME 38 DAYS
A3: TASK | B3: Start | C3: Finish | D3: =IF(DASHBOARD!$M$2-DASHBOARD!$M$1>=0,"Day "&1,"") -> Day 1 | F3: =IF(DASHBOARD!$M$2-DASHBOARD!$M$1>=1,"Day "&2,"") -> Day 2 | H3: =IF(DASHBOARD!$M$2-DASHBOARD!$M$1>=2,"Day "&3,"") -> Day 3 | J3: =IF(DASHBOARD!$M$2-DASHBOARD!$M$1>=3,"Day "&4,"") -> Day 4 | L3: =IF(DASHBOARD!$M$2-DASHBOARD!$M$1>=4,"Day "&5,"") -> Day 5 | N3: =IF(DASHBOARD!$M$2-DASHBOARD!$M$1>=5,"Day "&6,"") -> Day 6 | P3: =IF(DASHBOARD!$M$2-DASHBOARD!$M$1>=6,"Day "&7,"") -> Day 7 | R3: =IF(DASHBOARD!$M$2-DASHBOARD!$M$1>=7,"Day "&8,"") -> Day 8 | T3: =IF(DASHBOARD!$M$2-DASHBOARD!$M$1>=8,"Day "&9,"") -> Day 9 | V3: =IF(DASHBOARD!$M$2-DASHBOARD!$M$1>=9,"Day "&10,"") -> Day 10 | X3: =IF(DASHBOARD!$M$2-DASHBOARD!$M$1>=10,"Day "&11,"") -> Day 11 | Z3: =IF(DASHBOARD!$M$2-DASHBOARD!$M$1>=11,"Day "&12,"") -> Day 12 | AB3: =IF(DASHBOARD!$M$2-DASHBOARD!$M$1>=12,"Day "&13,"") -> Day 13 | AD3: =IF(DASHBOARD!$M$2-DASHBOARD!$M$1>=13,"Day "&14,"") -> Day 14 | AF3: =IF(DASHBOARD!$M$2-DASHBOARD!$M$1>=14,"Day "&15,"") -> Day 15 | AH3: =IF(DASHBOARD!$M$2-DASHBOARD!$M$1>=15,"Day "&16,"") -> Day 16 | AJ3: =IF(DASHBOARD!$M$2-DASHBOARD!$M$1>=16,"Day "&17,"") -> Day 17 | AL3: =IF(DASHBOARD!$M$2-DASHBOARD!$M$1>=17,"Day "&18,"") -> Day 18 | AN3: =IF(DASHBOARD!$M$2-DASHBOARD!$M$1>=18,"Day "&19,"") -> Day 19 | AP3: =IF(DASHBOARD!$M$2-DASHBOARD!$M$1>=19,"Day "&20,"") -> Day 20 | AR3: =IF(DASHBOARD!$M$2-DASHBOARD!$M$1>=20,"Day "&21,"") -> Day 21 | AT3: =IF(DASHBOARD!$M$2-DASHBOARD!$M$1>=21,"Day "&22,"") -> Day 22 | AV3: =IF(DASHBOARD!$M$2-DASHBOARD!$M$1>=22,"Day "&23,"") -> Day 23 | AX3: =IF(DASHBOARD!$M$2-DASHBOARD!$M$1>=23,"Day "&24,"") -> Day 24 | AZ3: =IF(DASHBOARD!$M$2-DASHBOARD!$M$1>=24,"Day "&25,"") -> Day 25 | BB3: =IF(DASHBOARD!$M$2-DASHBOARD!$M$1>=25,"Day "&26,"") -> Day 26 | BD3: =IF(DASHBOARD!$M$2-DASHBOARD!$M$1>=26,"Day "&27,"") -> Day 27 | BF3: =IF(DASHBOARD!$M$2-DASHBOARD!$M$1>=27,"Day "&28,"") -> Day 28 | BH3: =IF(DASHBOARD!$M$2-DASHBOARD!$M$1>=28,"Day "&29,"") -> Day 29 | BJ3: =IF(DASHBOARD!$M$2-DASHBOARD!$M$1>=29,"Day "&30,"") -> Day 30 | BL3: =IF(DASHBOARD!$M$2-DASHBOARD!$M$1>=30,"Day "&31,"") -> Day 31 | BN3: =IF(DASHBOARD!$M$2-DASHBOARD!$M$1>=31,"Day "&32,"") -> Day 32 | BP3: =IF(DASHBOARD!$M$2-DASHBOARD!$M$1>=32,"Day "&33,"") -> Day 33 | BR3: =IF(DASHBOARD!$M$2-DASHBOARD!$M$1>=33,"Day "&34,"") -> Day 34 | BT3: =IF(DASHBOARD!$M$2-DASHBOARD!$M$1>=34,"Day "&35,"") -> Day 35 | BV3: =IF(DASHBOARD!$M$2-DASHBOARD!$M$1>=35,"Day "&36,"") -> Day 36 | BX3: =IF(DASHBOARD!$M$2-DASHBOARD!$M$1>=36,"Day "&37,"") -> Day 37 | BZ3: =IF(DASHBOARD!$M$2-DASHBOARD!$M$1>=37,"Day "&38,"") -> Day 38 | CB3: =IF(DASHBOARD!$M$2-DASHBOARD!$M$1>=38,"Day "&39,"") | CD3: =IF(DASHBOARD!$M$2-DASHBOARD!$M$1>=39,"Day "&40,"") | CF3: =IF(DASHBOARD!$M$2-DASHBOARD!$M$1>=40,"Day "&41,"") | CH3: =IF(DASHBOARD!$M$2-DASHBOARD!$M$1>=41,"Day "&42,"") | CJ3: =IF(DASHBOARD!$M$2-DASHBOARD!$M$1>=42,"Day "&43,"") | CL3: =IF(DASHBOARD!$M$2-DASHBOARD!$M$1>=43,"Day "&44,"") | CN3: =IF(DASHBOARD!$M$2-DASHBOARD!$M$1>=44,"Day "&45,"") | CP3: =IF(DASHBOARD!$M$2-DASHBOARD!$M$1>=45,"Day "&46,"") | CR3: =IF(DASHBOARD!$M$2-DASHBOARD!$M$1>=46,"Day "&47,"") | CT3: =IF(DASHBOARD!$M$2-DASHBOARD!$M$1>=47,"Day "&48,"") | CV3: =IF(DASHBOARD!$M$2-DASHBOARD!$M$1>=48,"Day "&49,"") | CX3: =IF(DASHBOARD!$M$2-DASHBOARD!$M$1>=49,"Day "&50,"")
D4: =IF(DASHBOARD!$M$2-DASHBOARD!$M$1>=0,DASHBOARD!$M$1+0,"") -> 46221 | F4: =IF(DASHBOARD!$M$2-DASHBOARD!$M$1>=1,DASHBOARD!$M$1+1,"") -> 46222 | H4: =IF(DASHBOARD!$M$2-DASHBOARD!$M$1>=2,DASHBOARD!$M$1+2,"") -> 46223 | J4: =IF(DASHBOARD!$M$2-DASHBOARD!$M$1>=3,DASHBOARD!$M$1+3,"") -> 46224 | L4: =IF(DASHBOARD!$M$2-DASHBOARD!$M$1>=4,DASHBOARD!$M$1+4,"") -> 46225 | N4: =IF(DASHBOARD!$M$2-DASHBOARD!$M$1>=5,DASHBOARD!$M$1+5,"") -> 46226 | P4: =IF(DASHBOARD!$M$2-DASHBOARD!$M$1>=6,DASHBOARD!$M$1+6,"") -> 46227 | R4: =IF(DASHBOARD!$M$2-DASHBOARD!$M$1>=7,DASHBOARD!$M$1+7,"") -> 46228 | T4: =IF(DASHBOARD!$M$2-DASHBOARD!$M$1>=8,DASHBOARD!$M$1+8,"") -> 46229 | V4: =IF(DASHBOARD!$M$2-DASHBOARD!$M$1>=9,DASHBOARD!$M$1+9,"") -> 46230 | X4: =IF(DASHBOARD!$M$2-DASHBOARD!$M$1>=10,DASHBOARD!$M$1+10,"") -> 46231 | Z4: =IF(DASHBOARD!$M$2-DASHBOARD!$M$1>=11,DASHBOARD!$M$1+11,"") -> 46232 | AB4: =IF(DASHBOARD!$M$2-DASHBOARD!$M$1>=12,DASHBOARD!$M$1+12,"") -> 46233 | AD4: =IF(DASHBOARD!$M$2-DASHBOARD!$M$1>=13,DASHBOARD!$M$1+13,"") -> 46234 | AF4: =IF(DASHBOARD!$M$2-DASHBOARD!$M$1>=14,DASHBOARD!$M$1+14,"") -> 46235 | AH4: =IF(DASHBOARD!$M$2-DASHBOARD!$M$1>=15,DASHBOARD!$M$1+15,"") -> 46236 | AJ4: =IF(DASHBOARD!$M$2-DASHBOARD!$M$1>=16,DASHBOARD!$M$1+16,"") -> 46237 | AL4: =IF(DASHBOARD!$M$2-DASHBOARD!$M$1>=17,DASHBOARD!$M$1+17,"") -> 46238 | AN4: =IF(DASHBOARD!$M$2-DASHBOARD!$M$1>=18,DASHBOARD!$M$1+18,"") -> 46239 | AP4: =IF(DASHBOARD!$M$2-DASHBOARD!$M$1>=19,DASHBOARD!$M$1+19,"") -> 46240 | AR4: =IF(DASHBOARD!$M$2-DASHBOARD!$M$1>=20,DASHBOARD!$M$1+20,"") -> 46241 | AT4: =IF(DASHBOARD!$M$2-DASHBOARD!$M$1>=21,DASHBOARD!$M$1+21,"") -> 46242 | AV4: =IF(DASHBOARD!$M$2-DASHBOARD!$M$1>=22,DASHBOARD!$M$1+22,"") -> 46243 | AX4: =IF(DASHBOARD!$M$2-DASHBOARD!$M$1>=23,DASHBOARD!$M$1+23,"") -> 46244 | AZ4: =IF(DASHBOARD!$M$2-DASHBOARD!$M$1>=24,DASHBOARD!$M$1+24,"") -> 46245 | BB4: =IF(DASHBOARD!$M$2-DASHBOARD!$M$1>=25,DASHBOARD!$M$1+25,"") -> 46246 | BD4: =IF(DASHBOARD!$M$2-DASHBOARD!$M$1>=26,DASHBOARD!$M$1+26,"") -> 46247 | BF4: =IF(DASHBOARD!$M$2-DASHBOARD!$M$1>=27,DASHBOARD!$M$1+27,"") -> 46248 | BH4: =IF(DASHBOARD!$M$2-DASHBOARD!$M$1>=28,DASHBOARD!$M$1+28,"") -> 46249 | BJ4: =IF(DASHBOARD!$M$2-DASHBOARD!$M$1>=29,DASHBOARD!$M$1+29,"") -> 46250 | BL4: =IF(DASHBOARD!$M$2-DASHBOARD!$M$1>=30,DASHBOARD!$M$1+30,"") -> 46251 | BN4: =IF(DASHBOARD!$M$2-DASHBOARD!$M$1>=31,DASHBOARD!$M$1+31,"") -> 46252 | BP4: =IF(DASHBOARD!$M$2-DASHBOARD!$M$1>=32,DASHBOARD!$M$1+32,"") -> 46253 | BR4: =IF(DASHBOARD!$M$2-DASHBOARD!$M$1>=33,DASHBOARD!$M$1+33,"") -> 46254 | BT4: =IF(DASHBOARD!$M$2-DASHBOARD!$M$1>=34,DASHBOARD!$M$1+34,"") -> 46255 | BV4: =IF(DASHBOARD!$M$2-DASHBOARD!$M$1>=35,DASHBOARD!$M$1+35,"") -> 46256 | BX4: =IF(DASHBOARD!$M$2-DASHBOARD!$M$1>=36,DASHBOARD!$M$1+36,"") -> 46257 | BZ4: =IF(DASHBOARD!$M$2-DASHBOARD!$M$1>=37,DASHBOARD!$M$1+37,"") -> 46258 | CB4: =IF(DASHBOARD!$M$2-DASHBOARD!$M$1>=38,DASHBOARD!$M$1+38,"") | CD4: =IF(DASHBOARD!$M$2-DASHBOARD!$M$1>=39,DASHBOARD!$M$1+39,"") | CF4: =IF(DASHBOARD!$M$2-DASHBOARD!$M$1>=40,DASHBOARD!$M$1+40,"") | CH4: =IF(DASHBOARD!$M$2-DASHBOARD!$M$1>=41,DASHBOARD!$M$1+41,"") | CJ4: =IF(DASHBOARD!$M$2-DASHBOARD!$M$1>=42,DASHBOARD!$M$1+42,"") | CL4: =IF(DASHBOARD!$M$2-DASHBOARD!$M$1>=43,DASHBOARD!$M$1+43,"") | CN4: =IF(DASHBOARD!$M$2-DASHBOARD!$M$1>=44,DASHBOARD!$M$1+44,"") | CP4: =IF(DASHBOARD!$M$2-DASHBOARD!$M$1>=45,DASHBOARD!$M$1+45,"") | CR4: =IF(DASHBOARD!$M$2-DASHBOARD!$M$1>=46,DASHBOARD!$M$1+46,"") | CT4: =IF(DASHBOARD!$M$2-DASHBOARD!$M$1>=47,DASHBOARD!$M$1+47,"") | CV4: =IF(DASHBOARD!$M$2-DASHBOARD!$M$1>=48,DASHBOARD!$M$1+48,"") | CX4: =IF(DASHBOARD!$M$2-DASHBOARD!$M$1>=49,DASHBOARD!$M$1+49,"")
D5: =IF(DASHBOARD!$M$2-DASHBOARD!$M$1>=0,"D","") -> D | E5: =IF(DASHBOARD!$M$2-DASHBOARD!$M$1>=0,"T","") -> T | F5: =IF(DASHBOARD!$M$2-DASHBOARD!$M$1>=1,"D","") -> D | G5: =IF(DASHBOARD!$M$2-DASHBOARD!$M$1>=1,"T","") -> T | H5: =IF(DASHBOARD!$M$2-DASHBOARD!$M$1>=2,"D","") -> D | I5: =IF(DASHBOARD!$M$2-DASHBOARD!$M$1>=2,"T","") -> T | J5: =IF(DASHBOARD!$M$2-DASHBOARD!$M$1>=3,"D","") -> D | K5: =IF(DASHBOARD!$M$2-DASHBOARD!$M$1>=3,"T","") -> T | L5: =IF(DASHBOARD!$M$2-DASHBOARD!$M$1>=4,"D","") -> D | M5: =IF(DASHBOARD!$M$2-DASHBOARD!$M$1>=4,"T","") -> T | N5: =IF(DASHBOARD!$M$2-DASHBOARD!$M$1>=5,"D","") -> D | O5: =IF(DASHBOARD!$M$2-DASHBOARD!$M$1>=5,"T","") -> T | P5: =IF(DASHBOARD!$M$2-DASHBOARD!$M$1>=6,"D","") -> D | Q5: =IF(DASHBOARD!$M$2-DASHBOARD!$M$1>=6,"T","") -> T | R5: =IF(DASHBOARD!$M$2-DASHBOARD!$M$1>=7,"D","") -> D | S5: =IF(DASHBOARD!$M$2-DASHBOARD!$M$1>=7,"T","") -> T | T5: =IF(DASHBOARD!$M$2-DASHBOARD!$M$1>=8,"D","") -> D | U5: =IF(DASHBOARD!$M$2-DASHBOARD!$M$1>=8,"T","") -> T | V5: =IF(DASHBOARD!$M$2-DASHBOARD!$M$1>=9,"D","") -> D | W5: =IF(DASHBOARD!$M$2-DASHBOARD!$M$1>=9,"T","") -> T | X5: =IF(DASHBOARD!$M$2-DASHBOARD!$M$1>=10,"D","") -> D | Y5: =IF(DASHBOARD!$M$2-DASHBOARD!$M$1>=10,"T","") -> T | Z5: =IF(DASHBOARD!$M$2-DASHBOARD!$M$1>=11,"D","") -> D | AA5: =IF(DASHBOARD!$M$2-DASHBOARD!$M$1>=11,"T","") -> T | AB5: =IF(DASHBOARD!$M$2-DASHBOARD!$M$1>=12,"D","") -> D | AC5: =IF(DASHBOARD!$M$2-DASHBOARD!$M$1>=12,"T","") -> T | AD5: =IF(DASHBOARD!$M$2-DASHBOARD!$M$1>=13,"D","") -> D | AE5: =IF(DASHBOARD!$M$2-DASHBOARD!$M$1>=13,"T","") -> T | AF5: =IF(DASHBOARD!$M$2-DASHBOARD!$M$1>=14,"D","") -> D | AG5: =IF(DASHBOARD!$M$2-DASHBOARD!$M$1>=14,"T","") -> T | AH5: =IF(DASHBOARD!$M$2-DASHBOARD!$M$1>=15,"D","") -> D | AI5: =IF(DASHBOARD!$M$2-DASHBOARD!$M$1>=15,"T","") -> T | AJ5: =IF(DASHBOARD!$M$2-DASHBOARD!$M$1>=16,"D","") -> D | AK5: =IF(DASHBOARD!$M$2-DASHBOARD!$M$1>=16,"T","") -> T | AL5: =IF(DASHBOARD!$M$2-DASHBOARD!$M$1>=17,"D","") -> D | AM5: =IF(DASHBOARD!$M$2-DASHBOARD!$M$1>=17,"T","") -> T | AN5: =IF(DASHBOARD!$M$2-DASHBOARD!$M$1>=18,"D","") -> D | AO5: =IF(DASHBOARD!$M$2-DASHBOARD!$M$1>=18,"T","") -> T | AP5: =IF(DASHBOARD!$M$2-DASHBOARD!$M$1>=19,"D","") -> D | AQ5: =IF(DASHBOARD!$M$2-DASHBOARD!$M$1>=19,"T","") -> T | AR5: =IF(DASHBOARD!$M$2-DASHBOARD!$M$1>=20,"D","") -> D | AS5: =IF(DASHBOARD!$M$2-DASHBOARD!$M$1>=20,"T","") -> T | AT5: =IF(DASHBOARD!$M$2-DASHBOARD!$M$1>=21,"D","") -> D | AU5: =IF(DASHBOARD!$M$2-DASHBOARD!$M$1>=21,"T","") -> T | AV5: =IF(DASHBOARD!$M$2-DASHBOARD!$M$1>=22,"D","") -> D | AW5: =IF(DASHBOARD!$M$2-DASHBOARD!$M$1>=22,"T","") -> T | AX5: =IF(DASHBOARD!$M$2-DASHBOARD!$M$1>=23,"D","") -> D | AY5: =IF(DASHBOARD!$M$2-DASHBOARD!$M$1>=23,"T","") -> T | AZ5: =IF(DASHBOARD!$M$2-DASHBOARD!$M$1>=24,"D","") -> D | BA5: =IF(DASHBOARD!$M$2-DASHBOARD!$M$1>=24,"T","") -> T | BB5: =IF(DASHBOARD!$M$2-DASHBOARD!$M$1>=25,"D","") -> D | BC5: =IF(DASHBOARD!$M$2-DASHBOARD!$M$1>=25,"T","") -> T | BD5: =IF(DASHBOARD!$M$2-DASHBOARD!$M$1>=26,"D","") -> D | BE5: =IF(DASHBOARD!$M$2-DASHBOARD!$M$1>=26,"T","") -> T | BF5: =IF(DASHBOARD!$M$2-DASHBOARD!$M$1>=27,"D","") -> D | BG5: =IF(DASHBOARD!$M$2-DASHBOARD!$M$1>=27,"T","") -> T | BH5: =IF(DASHBOARD!$M$2-DASHBOARD!$M$1>=28,"D","") -> D | BI5: =IF(DASHBOARD!$M$2-DASHBOARD!$M$1>=28,"T","") -> T | BJ5: =IF(DASHBOARD!$M$2-DASHBOARD!$M$1>=29,"D","") -> D | BK5: =IF(DASHBOARD!$M$2-DASHBOARD!$M$1>=29,"T","") -> T | BL5: =IF(DASHBOARD!$M$2-DASHBOARD!$M$1>=30,"D","") -> D | BM5: =IF(DASHBOARD!$M$2-DASHBOARD!$M$1>=30,"T","") -> T | BN5: =IF(DASHBOARD!$M$2-DASHBOARD!$M$1>=31,"D","") -> D | BO5: =IF(DASHBOARD!$M$2-DASHBOARD!$M$1>=31,"T","") -> T | BP5: =IF(DASHBOARD!$M$2-DASHBOARD!$M$1>=32,"D","") -> D | BQ5: =IF(DASHBOARD!$M$2-DASHBOARD!$M$1>=32,"T","") -> T | BR5: =IF(DASHBOARD!$M$2-DASHBOARD!$M$1>=33,"D","") -> D | BS5: =IF(DASHBOARD!$M$2-DASHBOARD!$M$1>=33,"T","") -> T | BT5: =IF(DASHBOARD!$M$2-DASHBOARD!$M$1>=34,"D","") -> D | BU5: =IF(DASHBOARD!$M$2-DASHBOARD!$M$1>=34,"T","") -> T | BV5: =IF(DASHBOARD!$M$2-DASHBOARD!$M$1>=35,"D","") -> D | BW5: =IF(DASHBOARD!$M$2-DASHBOARD!$M$1>=35,"T","") -> T | BX5: =IF(DASHBOARD!$M$2-DASHBOARD!$M$1>=36,"D","") -> D | BY5: =IF(DASHBOARD!$M$2-DASHBOARD!$M$1>=36,"T","") -> T | BZ5: =IF(DASHBOARD!$M$2-DASHBOARD!$M$1>=37,"D","") -> D | CA5: =IF(DASHBOARD!$M$2-DASHBOARD!$M$1>=37,"T","") -> T | CB5: =IF(DASHBOARD!$M$2-DASHBOARD!$M$1>=38,"D","") | CC5: =IF(DASHBOARD!$M$2-DASHBOARD!$M$1>=38,"T","") | CD5: =IF(DASHBOARD!$M$2-DASHBOARD!$M$1>=39,"D","") | CE5: =IF(DASHBOARD!$M$2-DASHBOARD!$M$1>=39,"T","") | CF5: =IF(DASHBOARD!$M$2-DASHBOARD!$M$1>=40,"D","") | CG5: =IF(DASHBOARD!$M$2-DASHBOARD!$M$1>=40,"T","") | CH5: =IF(DASHBOARD!$M$2-DASHBOARD!$M$1>=41,"D","") | CI5: =IF(DASHBOARD!$M$2-DASHBOARD!$M$1>=41,"T","") | CJ5: =IF(DASHBOARD!$M$2-DASHBOARD!$M$1>=42,"D","") | CK5: =IF(DASHBOARD!$M$2-DASHBOARD!$M$1>=42,"T","") | CL5: =IF(DASHBOARD!$M$2-DASHBOARD!$M$1>=43,"D","") | CM5: =IF(DASHBOARD!$M$2-DASHBOARD!$M$1>=43,"T","") | CN5: =IF(DASHBOARD!$M$2-DASHBOARD!$M$1>=44,"D","") | CO5: =IF(DASHBOARD!$M$2-DASHBOARD!$M$1>=44,"T","") | CP5: =IF(DASHBOARD!$M$2-DASHBOARD!$M$1>=45,"D","") | CQ5: =IF(DASHBOARD!$M$2-DASHBOARD!$M$1>=45,"T","") | CR5: =IF(DASHBOARD!$M$2-DASHBOARD!$M$1>=46,"D","") | CS5: =IF(DASHBOARD!$M$2-DASHBOARD!$M$1>=46,"T","") | CT5: =IF(DASHBOARD!$M$2-DASHBOARD!$M$1>=47,"D","") | CU5: =IF(DASHBOARD!$M$2-DASHBOARD!$M$1>=47,"T","") | CV5: =IF(DASHBOARD!$M$2-DASHBOARD!$M$1>=48,"D","") | CW5: =IF(DASHBOARD!$M$2-DASHBOARD!$M$1>=48,"T","") | CX5: =IF(DASHBOARD!$M$2-DASHBOARD!$M$1>=49,"D","") | CY5: =IF(DASHBOARD!$M$2-DASHBOARD!$M$1>=49,"T","")
A6: PHASE 1 (Pre Hangar)
A7: Aircraft Arrival | B7: 46221.25
A8: Heavy Wash | B8: 46221.75
A9: Both ENG Preservation
A10: Pre HGR
A11: Pre Insp
A12: Defuel
A13: PHASE 2 (Inspection)
A14: Nose Jacking – Prox Sensor Check
A15: Open-Up
A16: Cabin Structure
A17: Joint Cards Insp
A18: Power Off
A19: FINDING CUT-OFF | D19: =IF(DASHBOARD!$M$1+INT((COLUMN()-4)/2)=$B19,"◆ "&TEXT($B19,"D MMM"),"") | F19: =IF(DASHBOARD!$M$1+INT((COLUMN()-4)/2)=$B19,"◆ "&TEXT($B19,"D MMM"),"") | H19: =IF(DASHBOARD!$M$1+INT((COLUMN()-4)/2)=$B19,"◆ "&TEXT($B19,"D MMM"),"") | J19: =IF(DASHBOARD!$M$1+INT((COLUMN()-4)/2)=$B19,"◆ "&TEXT($B19,"D MMM"),"") | L19: =IF(DASHBOARD!$M$1+INT((COLUMN()-4)/2)=$B19,"◆ "&TEXT($B19,"D MMM"),"") | N19: =IF(DASHBOARD!$M$1+INT((COLUMN()-4)/2)=$B19,"◆ "&TEXT($B19,"D MMM"),"") | P19: =IF(DASHBOARD!$M$1+INT((COLUMN()-4)/2)=$B19,"◆ "&TEXT($B19,"D MMM"),"") | R19: =IF(DASHBOARD!$M$1+INT((COLUMN()-4)/2)=$B19,"◆ "&TEXT($B19,"D MMM"),"") | T19: =IF(DASHBOARD!$M$1+INT((COLUMN()-4)/2)=$B19,"◆ "&TEXT($B19,"D MMM"),"") | V19: =IF(DASHBOARD!$M$1+INT((COLUMN()-4)/2)=$B19,"◆ "&TEXT($B19,"D MMM"),"") | X19: =IF(DASHBOARD!$M$1+INT((COLUMN()-4)/2)=$B19,"◆ "&TEXT($B19,"D MMM"),"") | Z19: =IF(DASHBOARD!$M$1+INT((COLUMN()-4)/2)=$B19,"◆ "&TEXT($B19,"D MMM"),"") | AB19: =IF(DASHBOARD!$M$1+INT((COLUMN()-4)/2)=$B19,"◆ "&TEXT($B19,"D MMM"),"") | AD19: =IF(DASHBOARD!$M$1+INT((COLUMN()-4)/2)=$B19,"◆ "&TEXT($B19,"D MMM"),"") | AF19: =IF(DASHBOARD!$M$1+INT((COLUMN()-4)/2)=$B19,"◆ "&TEXT($B19,"D MMM"),"") | AH19: =IF(DASHBOARD!$M$1+INT((COLUMN()-4)/2)=$B19,"◆ "&TEXT($B19,"D MMM"),"") | AJ19: =IF(DASHBOARD!$M$1+INT((COLUMN()-4)/2)=$B19,"◆ "&TEXT($B19,"D MMM"),"") | AL19: =IF(DASHBOARD!$M$1+INT((COLUMN()-4)/2)=$B19,"◆ "&TEXT($B19,"D MMM"),"") | AN19: =IF(DASHBOARD!$M$1+INT((COLUMN()-4)/2)=$B19,"◆ "&TEXT($B19,"D MMM"),"") | AP19: =IF(DASHBOARD!$M$1+INT((COLUMN()-4)/2)=$B19,"◆ "&TEXT($B19,"D MMM"),"") | AR19: =IF(DASHBOARD!$M$1+INT((COLUMN()-4)/2)=$B19,"◆ "&TEXT($B19,"D MMM"),"") | AT19: =IF(DASHBOARD!$M$1+INT((COLUMN()-4)/2)=$B19,"◆ "&TEXT($B19,"D MMM"),"") | AV19: =IF(DASHBOARD!$M$1+INT((COLUMN()-4)/2)=$B19,"◆ "&TEXT($B19,"D MMM"),"") | AX19: =IF(DASHBOARD!$M$1+INT((COLUMN()-4)/2)=$B19,"◆ "&TEXT($B19,"D MMM"),"") | AZ19: =IF(DASHBOARD!$M$1+INT((COLUMN()-4)/2)=$B19,"◆ "&TEXT($B19,"D MMM"),"") | BB19: =IF(DASHBOARD!$M$1+INT((COLUMN()-4)/2)=$B19,"◆ "&TEXT($B19,"D MMM"),"") | BD19: =IF(DASHBOARD!$M$1+INT((COLUMN()-4)/2)=$B19,"◆ "&TEXT($B19,"D MMM"),"") | BF19: =IF(DASHBOARD!$M$1+INT((COLUMN()-4)/2)=$B19,"◆ "&TEXT($B19,"D MMM"),"") | BH19: =IF(DASHBOARD!$M$1+INT((COLUMN()-4)/2)=$B19,"◆ "&TEXT($B19,"D MMM"),"") | BJ19: =IF(DASHBOARD!$M$1+INT((COLUMN()-4)/2)=$B19,"◆ "&TEXT($B19,"D MMM"),"") | BL19: =IF(DASHBOARD!$M$1+INT((COLUMN()-4)/2)=$B19,"◆ "&TEXT($B19,"D MMM"),"") | BN19: =IF(DASHBOARD!$M$1+INT((COLUMN()-4)/2)=$B19,"◆ "&TEXT($B19,"D MMM"),"") | BP19: =IF(DASHBOARD!$M$1+INT((COLUMN()-4)/2)=$B19,"◆ "&TEXT($B19,"D MMM"),"") | BR19: =IF(DASHBOARD!$M$1+INT((COLUMN()-4)/2)=$B19,"◆ "&TEXT($B19,"D MMM"),"") | BT19: =IF(DASHBOARD!$M$1+INT((COLUMN()-4)/2)=$B19,"◆ "&TEXT($B19,"D MMM"),"") | BV19: =IF(DASHBOARD!$M$1+INT((COLUMN()-4)/2)=$B19,"◆ "&TEXT($B19,"D MMM"),"") | BX19: =IF(DASHBOARD!$M$1+INT((COLUMN()-4)/2)=$B19,"◆ "&TEXT($B19,"D MMM"),"") | BZ19: =IF(DASHBOARD!$M$1+INT((COLUMN()-4)/2)=$B19,"◆ "&TEXT($B19,"D MMM"),"")
A20: PHASE 3 (Modification & Rectification)
A21: Findings & Rectification
A22: Engineering Orders Doc (EOD's / ER's)
A23: FOMAX & Eclipse Connectivity Mods
A24: Jacking – Free Fall Func Chk & NLG
A25: MATERIALS ARRIVAL CUT-OFF | D25: =IF(DASHBOARD!$M$1+INT((COLUMN()-4)/2)=$B25,"◆ "&TEXT($B25,"D MMM"),"") | F25: =IF(DASHBOARD!$M$1+INT((COLUMN()-4)/2)=$B25,"◆ "&TEXT($B25,"D MMM"),"") | H25: =IF(DASHBOARD!$M$1+INT((COLUMN()-4)/2)=$B25,"◆ "&TEXT($B25,"D MMM"),"") | J25: =IF(DASHBOARD!$M$1+INT((COLUMN()-4)/2)=$B25,"◆ "&TEXT($B25,"D MMM"),"") | L25: =IF(DASHBOARD!$M$1+INT((COLUMN()-4)/2)=$B25,"◆ "&TEXT($B25,"D MMM"),"") | N25: =IF(DASHBOARD!$M$1+INT((COLUMN()-4)/2)=$B25,"◆ "&TEXT($B25,"D MMM"),"") | P25: =IF(DASHBOARD!$M$1+INT((COLUMN()-4)/2)=$B25,"◆ "&TEXT($B25,"D MMM"),"") | R25: =IF(DASHBOARD!$M$1+INT((COLUMN()-4)/2)=$B25,"◆ "&TEXT($B25,"D MMM"),"") | T25: =IF(DASHBOARD!$M$1+INT((COLUMN()-4)/2)=$B25,"◆ "&TEXT($B25,"D MMM"),"") | V25: =IF(DASHBOARD!$M$1+INT((COLUMN()-4)/2)=$B25,"◆ "&TEXT($B25,"D MMM"),"") | X25: =IF(DASHBOARD!$M$1+INT((COLUMN()-4)/2)=$B25,"◆ "&TEXT($B25,"D MMM"),"") | Z25: =IF(DASHBOARD!$M$1+INT((COLUMN()-4)/2)=$B25,"◆ "&TEXT($B25,"D MMM"),"") | AB25: =IF(DASHBOARD!$M$1+INT((COLUMN()-4)/2)=$B25,"◆ "&TEXT($B25,"D MMM"),"") | AD25: =IF(DASHBOARD!$M$1+INT((COLUMN()-4)/2)=$B25,"◆ "&TEXT($B25,"D MMM"),"") | AF25: =IF(DASHBOARD!$M$1+INT((COLUMN()-4)/2)=$B25,"◆ "&TEXT($B25,"D MMM"),"") | AH25: =IF(DASHBOARD!$M$1+INT((COLUMN()-4)/2)=$B25,"◆ "&TEXT($B25,"D MMM"),"") | AJ25: =IF(DASHBOARD!$M$1+INT((COLUMN()-4)/2)=$B25,"◆ "&TEXT($B25,"D MMM"),"") | AL25: =IF(DASHBOARD!$M$1+INT((COLUMN()-4)/2)=$B25,"◆ "&TEXT($B25,"D MMM"),"") | AN25: =IF(DASHBOARD!$M$1+INT((COLUMN()-4)/2)=$B25,"◆ "&TEXT($B25,"D MMM"),"") | AP25: =IF(DASHBOARD!$M$1+INT((COLUMN()-4)/2)=$B25,"◆ "&TEXT($B25,"D MMM"),"") | AR25: =IF(DASHBOARD!$M$1+INT((COLUMN()-4)/2)=$B25,"◆ "&TEXT($B25,"D MMM"),"") | AT25: =IF(DASHBOARD!$M$1+INT((COLUMN()-4)/2)=$B25,"◆ "&TEXT($B25,"D MMM"),"") | AV25: =IF(DASHBOARD!$M$1+INT((COLUMN()-4)/2)=$B25,"◆ "&TEXT($B25,"D MMM"),"") | AX25: =IF(DASHBOARD!$M$1+INT((COLUMN()-4)/2)=$B25,"◆ "&TEXT($B25,"D MMM"),"") | AZ25: =IF(DASHBOARD!$M$1+INT((COLUMN()-4)/2)=$B25,"◆ "&TEXT($B25,"D MMM"),"") | BB25: =IF(DASHBOARD!$M$1+INT((COLUMN()-4)/2)=$B25,"◆ "&TEXT($B25,"D MMM"),"") | BD25: =IF(DASHBOARD!$M$1+INT((COLUMN()-4)/2)=$B25,"◆ "&TEXT($B25,"D MMM"),"") | BF25: =IF(DASHBOARD!$M$1+INT((COLUMN()-4)/2)=$B25,"◆ "&TEXT($B25,"D MMM"),"") | BH25: =IF(DASHBOARD!$M$1+INT((COLUMN()-4)/2)=$B25,"◆ "&TEXT($B25,"D MMM"),"") | BJ25: =IF(DASHBOARD!$M$1+INT((COLUMN()-4)/2)=$B25,"◆ "&TEXT($B25,"D MMM"),"") | BL25: =IF(DASHBOARD!$M$1+INT((COLUMN()-4)/2)=$B25,"◆ "&TEXT($B25,"D MMM"),"") | BN25: =IF(DASHBOARD!$M$1+INT((COLUMN()-4)/2)=$B25,"◆ "&TEXT($B25,"D MMM"),"") | BP25: =IF(DASHBOARD!$M$1+INT((COLUMN()-4)/2)=$B25,"◆ "&TEXT($B25,"D MMM"),"") | BR25: =IF(DASHBOARD!$M$1+INT((COLUMN()-4)/2)=$B25,"◆ "&TEXT($B25,"D MMM"),"") | BT25: =IF(DASHBOARD!$M$1+INT((COLUMN()-4)/2)=$B25,"◆ "&TEXT($B25,"D MMM"),"") | BV25: =IF(DASHBOARD!$M$1+INT((COLUMN()-4)/2)=$B25,"◆ "&TEXT($B25,"D MMM"),"") | BX25: =IF(DASHBOARD!$M$1+INT((COLUMN()-4)/2)=$B25,"◆ "&TEXT($B25,"D MMM"),"") | BZ25: =IF(DASHBOARD!$M$1+INT((COLUMN()-4)/2)=$B25,"◆ "&TEXT($B25,"D MMM"),"")
A26: PHASE 4 (Close Up & Final Inspection)
A27: Cabin Restoration
A28: Areas Close Up
A29: Cabin, Cargos & Cockpit
A30: Fuselage, Empennage & Wings
A31: Engines
A32: OPS & Func Check (Power On)
A33: W&B
A34: Refuel & Leak Checks
A35: Engine Run
A36: PHASE 5 (Release)
A37: Final Product Quality Inspection (FPQI)
A38: Aircraft Release | B38: 46258
A40: MILESTONES — auto from the schedule above
A41: FINDINGS CUTOFF | B41: =IF($B$19="","",$B$19)
A42: FOMAX START | B42: =IF($B$23="","",$B$23)
...

Sheet OPEN UP-ACCESS
A1: OPEN UP / ACCESS LOG ✈ HZ-ASD ✈ C2+6Y CHECK | F1: ="🔧 "&COUNTIFS(B4:B504,"<>",F4:F504,"Re-Installed")&" / "&COUNTIF(B4:B504,"<>")&" Re-Installed ("&TEXT(IFERROR(COUNTIFS(B4:B504,"<>",F4:F504,"Re-Installed")/COUNTIF(B4:B504,"<>"),0),"0%")&")" -> 🔧 0 / 0 Re-Installed (0%)
A2: =IF(COUNTIF(B4:B504,"<>")=0,"Track every removed item — who removed it, under which WO, and reinstallation status","Open by area: F/DECK "&COUNTIFS(C4:C504,"FLIGHT DECK",F4:F504,"Open")&" · FWD "&COUNTIFS(C4:C504,"FWD",F4:F504,"Open")&" · MID "&COUNTIFS(C4:C504,"MID",F4:F504,"Open")&" · AFT "&COUNTIFS(C4:C504,"AFT",F4:F504,"Open")&" · JOINT "&COUNTIFS(C4:C504,"JOINT",F4:F504,"Open")) -> Track every removed item — who removed it, under which WO, and reinstallation status | F2: ="⚠️ Still Open: "&COUNTIFS(B4:B504,"<>",F4:F504,"Open") -> ⚠️ Still Open: 0
A3: Seq. No. | B3: Item Removed (panel / seat / component) | C3: AREA | D3: Relevant WO No. | E3: Removed By | F3: Status | G3: Date Removed | H3: Re-Installed By | I3: Date Re-Installed | J3: Remarks
A4: =IF(B4<>"",ROW()-3,"")
A5: =IF(B5<>"",ROW()-3,"")
A6: =IF(B6<>"",ROW()-3,"")
A8: =IF(B8<>"",ROW()-3,"")
A9: =IF(B9<>"",ROW()-3,"")
A10: =IF(B10<>"",ROW()-3,"")
A11: =IF(B11<>"",ROW()-3,"")
A12: =IF(B12<>"",ROW()-3,"")
A13: =IF(B13<>"",ROW()-3,"")
A14: =IF(B14<>"",ROW()-3,"")
A15: =IF(B15<>"",ROW()-3,"")
A16: =IF(B16<>"",ROW()-3,"")
... A504: =IF(B504<>"",ROW()-3,"")

Sheet Findings Draft
A1: 📋 FINDINGS DRAFT — Pre-AMOS
A2: Findings sourced from ACFT Finding Report App · Review & assign P/N before raising on AMOS
A3: # | B3: By | C3: Category | D3: Sub-Category | E3: Finding Description | F3: Remarks | G3: Photo URL | H3: AMOS Status | I3: WO No. | J3: P/N Required | K3: Qty
A4: =IF(COUNTA(B4:G4)>0,ROW()-3,"") | H4: Not Raised
A5: =IF(COUNTA(B5:G5)>0,ROW()-3,"") | H5: Not Raised
A6: =IF(COUNTA(B6:G6)>0,ROW()-3,"") | H6: Not Raised
A7: =IF(COUNTA(B7:G7)>0,ROW()-3,"") | H7: Not Raised
A8: =IF(COUNTA(B8:G8)>0,ROW()-3,"") | H8: Not Raised
A9: =IF(COUNTA(B9:G9)>0,ROW()-3,"") | H9: Not Raised
A10: =IF(COUNTA(B10:G10)>0,ROW()-3,"") | H10: Not Raised
A11: =IF(COUNTA(B11:G11)>0,ROW()-3,"") | H11: Not Raised
A12: =IF(COUNTA(B12:G12)>0,ROW()-3,"") | H12: Not Raised
A13: =IF(COUNTA(B13:G13)>0,ROW()-3,"") | H13: Not Raised
A14: =IF(COUNTA(B14:G14)>0,ROW()-3,"") | H14: Not Raised
A15: =IF(COUNTA(B15:G15)>0,ROW()-3,"") | H15: Not Raised
... A503: =IF(COUNTA(B503:G503)>0,ROW()-3,"") | H503: Not Raised

Sheet DASHBOARD OLD
A1: 📊 ASD C2+6Y-CHECK — WORK PACKAGE DASHBOARD | I1: =IF(OR(NOT(ISNUMBER($M$1)),NOT(ISNUMBER($M$2))),"PENDING","DAY "&MAX(MIN(TODAY()-$M$1+1,$M$2-$M$1+1),0)&"/"&($M$2-$M$1+1)) -> DAY 2/38 | L1: CHECK START → | M1: =DASHBOARD!$M$1 -> 46221
A2: =IF(AND($M$1="",$M$2=""),"⚙️ Set CHECK START (M1) and CHECK END (M2) dates → schedule alert activates automatically",IF(OR(NOT(ISNUMBER($M$1)),NOT(ISNUMBER($M$2))),"⚠️ Date not recognized — clear M1/M2 and re-type as 2026-07-01 (year-month-day)",IF($M$2<=$M$1,"⚠️ CHECK END must be after CHECK START — please review M1/M2",IF(AND(TODAY()>$M$2,(COUNTIFS('HZ-ASD Tracker'!$A$4:$A$1004,"<>",'HZ-ASD Tracker'!$E$4:$E$1004,"Closed")/COUNTIF('HZ-ASD Tracker'!$A$4:$A$1004,"<>"))<1),"❌ CHECK PERIOD ENDED — Completion "&TEXT((COUNTIFS('HZ-ASD Tracker'!$A$4:$A$1004,"<>",'HZ-ASD Tracker'!$E$4:$E$1004,"Closed")/COUNTIF('HZ-ASD Tracker'!$A$4:$A$1004,"<>")),"0%")&" · Overdue by "&(TODAY()-$M$2)&" days",IF((COUNTIFS('HZ-ASD Tracker'!$A$4:$A$1004,"<>",'HZ-ASD Tracker'!$E$4:$E$1004,"Closed")/COUNTIF('HZ-ASD Tracker'!$A$4:$A$1004,"<>"))>=((TODAY()-$M$1)/($M$2-$M$1))-0.05,"✅ ON TRACK — "&"Completed "&TEXT((COUNTIFS('HZ-ASD Tracker'!$A$4:$A$1004,"<>",'HZ-ASD Tracker'!$E$4:$E$1004,"Closed")/COUNTIF('HZ-ASD Tracker'!$A$4:$A$1004,"<>")),"0%")&" vs Time "&TEXT(MAX(MIN(((TODAY()-$M$1)/($M$2-$M$1)),1),0),"0%")&" · Days Left: "&MAX($M$2-TODAY(),0)&" · Pace needed: "&TEXT((COUNTIF('HZ-ASD Tracker'!$A$4:$A$1004,"<>")-COUNTIFS('HZ-ASD Tracker'!$A$4:$A$1004,"<>",'HZ-ASD Tracker'!$E$4:$E$1004,"Closed"))/MAX($M$2-TODAY(),1),"0.0")&"/day vs avg "&TEXT(COUNTIFS('HZ-ASD Tracker'!$A$4:$A$1004,"<>",'HZ-ASD Tracker'!$E$4:$E$1004,"Closed")/MAX(TODAY()-$M$1,1),"0.0")&"/day",IF((COUNTIFS('HZ-ASD Tracker'!$A$4:$A$1004,"<>",'HZ-ASD Tracker'!$E$4:$E$1004,"Closed")/COUNTIF('HZ-ASD Tracker'!$A$4:$A$1004,"<>"))>=((TODAY()-$M$1)/($M$2-$M$1))-0.15,"⚠️ WARNING — "&"Completed "&TEXT((COUNTIFS('HZ-ASD Tracker'!$A$4:$A$1004,"<>",'HZ-ASD Tracker'!$E$4:$E$1004,"Closed")/COUNTIF('HZ-ASD Tracker'!$A$4:$A$1004,"<>")),"0%")&" vs Time "&TEXT(MAX(MIN(((TODAY()-$M$1)/($M$2-$M$1)),1),0),"0%")&" · Days Left: "&MAX($M$2-TODAY(),0)&" · Pace needed: "&TEXT((COUNTIF('HZ-ASD Tracker'!$A$4:$A$1004,"<>")-COUNTIFS('HZ-ASD Tracker'!$A$4:$A$1004,"<>",'HZ-ASD Tracker'!$E$4:$E$1004,"Closed"))/MAX($M$2-TODAY(),1),"0.0")&"/day vs avg "&TEXT(COUNTIFS('HZ-ASD Tracker'!$A$4:$A$1004,"<>",'HZ-ASD Tracker'!$E$4:$E$1004,"Closed")/MAX(TODAY()-$M$1,1),"0.0")&"/day","🔴 CRITICAL — "&"Completed "&TEXT((COUNTIFS('HZ-ASD Tracker'!$A$4:$A$1004,"<>",'HZ-ASD Tracker'!$E$4:$E$1004,"Closed")/COUNTIF('HZ-ASD Tracker'!$A$4:$A$1004,"<>")),"0%")&" vs Time "&TEXT(MAX(MIN(((TODAY()-$M$1)/($M$2-$M$1)),1),0),"0%")&" · Days Left: "&MAX($M$2-TODAY(),0)&" · Pace needed: "&TEXT((COUNTIF('HZ-ASD Tracker'!$A$4:$A$1004,"<>")-COUNTIFS('HZ-ASD Tracker'!$A$4:$A$1004,"<>",'HZ-ASD Tracker'!$E$4:$E$1004,"Closed"))/MAX($M$2-TODAY(),1),"0.0")&"/day vs avg "&TEXT(COUNTIFS('HZ-ASD Tracker'!$A$4:$A$1004,"<>",'HZ-ASD Tracker'!$E$4:$E$1004,"Closed")/MAX(TODAY()-$M$1,1),"0.0")&"/day")))))) -> ✅ ON TRACK — Completed 0% vs Time 3% · Days Left: 36 · Pace needed: 5.3/day vs avg 0.0/day | L2: CHECK END → | M2: =DASHBOARD!$M$2 -> 46258
A3: STATUS OVERVIEW | H3: =IF(NOT(ISNUMBER(LAYOVER!$B$19)),"⏳ set findings cutoff (LAYOVER)",IF(TODAY()>LAYOVER!$B$19,"🔒 FINDINGS WINDOW CLOSED","⏳ Findings window closes in: "&(LAYOVER!$B$19-TODAY())&" day(s)")) -> ⏳ set findings cutoff (LAYOVER)
B5: Total Items/WOs | C5: =COUNTIF('HZ-ASD Tracker'!A4:A1004,"<>") -> 192 | E5: Closed | F5: =COUNTIFS('HZ-ASD Tracker'!A4:A1004,"<>",'HZ-ASD Tracker'!E4:E1004,"Closed") -> 0 | H5: Completion | I5: =TEXT(IFERROR(COUNTIFS('HZ-ASD Tracker'!A4:A1004,"<>",'HZ-ASD Tracker'!E4:E1004,"Closed")/COUNTIF('HZ-ASD Tracker'!A4:A1004,"<>"),0),"0%") -> 0%
B7: Open | C7: =COUNTIFS('HZ-ASD Tracker'!A4:A1004,"<>",'HZ-ASD Tracker'!E4:E1004,"Open") -> 192 | E7: In Work (I/W) | F7: =COUNTIFS('HZ-ASD Tracker'!A4:A1004,"<>",'HZ-ASD Tracker'!E4:E1004,"I/W") -> 0 | H7: Deferred / Hold | I7: =COUNTIFS('HZ-ASD Tracker'!A4:A1004,"<>",'HZ-ASD Tracker'!E4:E1004,"Deferred")+COUNTIFS('HZ-ASD Tracker'!A4:A1004,"<>",'HZ-ASD Tracker'!E4:E1004,"On Hold") -> 0
A9: PRIORITY ALERTS | H9: =IFERROR("📅 Next: "&INDEX(LAYOVER!$A$41:$A$48,MATCH(_xludf.MINIFS(LAYOVER!$B$41:$B$48,LAYOVER!$B$41:$B$48,">="&TODAY()),LAYOVER!$B$41:$B$48,0))&IF(_xludf.MINIFS(LAYOVER!$B$41:$B$48,LAYOVER!$B$41:$B$48,">="&TODAY())=TODAY()," — TODAY"," in "&(_xludf.MINIFS(LAYOVER!$B$41:$B$48,LAYOVER!$B$41:$B$48,">="&TODAY())-TODAY())&" day(s)"),"📅 no upcoming milestone set") -> 📅 no upcoming milestone set
B11: AOG | C11: =COUNTIFS('HZ-ASD Tracker'!A4:A1004,"<>",'HZ-ASD Tracker'!F4:F1004,"AOG") -> 1 | E11: Critical | F11: =COUNTIFS('HZ-ASD Tracker'!A4:A1004,"<>",'HZ-ASD Tracker'!F4:F1004,"Critical") -> 0 | H11: 🚨 AOG/CRIT — STILL OPEN | I11: =COUNTIFS('HZ-ASD Tracker'!$A$4:$A$1004,"<>",'HZ-ASD Tracker'!$F$4:$F$1004,"AOG",'HZ-ASD Tracker'!$E$4:$E$1004,"<>Closed")+COUNTIFS('HZ-ASD Tracker'!$A$4:$A$1004,"<>",'HZ-ASD Tracker'!$F$4:$F$1004,"Critical",'HZ-ASD Tracker'!$E$4:$E$1004,"<>Closed") -> 1
A13: BY SOURCE — ROUTINE · ENG ORDERS · FINDINGS | G13: =IF(NOT(ISNUMBER(LAYOVER!$B$7)),"📍 Phase: awaiting official schedule","📍 Now: "&IF(AND(ISNUMBER(LAYOVER!$B$37),TODAY()>=LAYOVER!$B$37),"PHASE 5 — Release",IF(AND(ISNUMBER(LAYOVER!$B$27),TODAY()>=LAYOVER!$B$27),"PHASE 4 — Close Up & Final",IF(AND(ISNUMBER(LAYOVER!$B$21),TODAY()>=LAYOVER!$B$21),"PHASE 3 — Mod & Rectification",IF(AND(ISNUMBER(LAYOVER!$B$14),TODAY()>=LAYOVER!$B$14),"PHASE 2 — Inspection","PHASE 1 — Pre Hangar"))))) -> 📍 Now: PHASE 1 — Pre Hangar
